File: data/output/vidExt_M-35Zr39Ti25Nb_Glb_11_0pt1/vidExt_M-35Zr39Ti25Nb_Glb_11_0pt1_correlated.txt
Total length (mm) = 50
Gage length (mm) = 5.1
Width (mm) = 2.21
Thickness (mm) = 0.95
----------
Time (s)	Displacement (mm)	Force (N)	Eng. strain	Eng. stress (MPa)
0.00000000	0.00000000	58.56777700	0.00000000	27.89605954
0.20000000	0.00078580	61.83140200	0.00015408	29.45053679
0.40000000	0.00157161	65.30208500	0.00030816	31.10363658
0.60000000	0.00235741	69.42352100	0.00046224	33.06669255
0.80000000	0.00314321	72.96322300	0.00061632	34.75266635
1.00000000	0.00392901	76.62124400	0.00077039	36.49499595
1.20000000	0.00471482	80.78211900	0.00092447	38.47683687
1.40000000	0.00550062	85.23879200	0.00107855	40.59956752
1.60000000	0.00628642	89.40952700	0.00123263	42.58610479
1.80000000	0.00707222	93.19572700	0.00138671	44.38948654
2.00000000	0.00785803	97.32702300	0.00154079	46.35723887
2.20000000	0.00864383	101.48789800	0.00169487	48.33907978
2.40000000	0.00942963	105.40227600	0.00184895	50.20351322
2.60000000	0.01021543	109.48427200	0.00200303	52.14778376
2.80000000	0.01100124	114.07898300	0.00215711	54.33626244
3.00000000	0.01178704	118.12154000	0.00231118	56.26174804
3.20000000	0.01257284	121.95703900	0.00246526	58.08861110
3.40000000	0.01335865	126.51231000	0.00261934	60.25830436
3.60000000	0.01414445	131.01828200	0.00277342	62.40451631
3.80000000	0.01493025	135.43551400	0.00292750	64.50846106
4.00000000	0.01571605	139.52737000	0.00308158	66.45742796
4.20000000	0.01650186	143.60936700	0.00323566	68.40169898
4.40000000	0.01728766	147.82940100	0.00338974	70.41171755
4.60000000	0.01807346	152.35509300	0.00354382	72.56732222
4.80000000	0.01885926	156.75260500	0.00369789	74.66187426
5.00000000	0.01964507	160.99236000	0.00385197	76.68128602
5.20000000	0.02043087	165.33071300	0.00400605	78.74766040
5.40000000	0.02121667	169.08733300	0.00416013	80.53695308
5.60000000	0.02200247	173.54400500	0.00431421	82.65968326
5.80000000	0.02278828	178.14857500	0.00446829	84.85285782
6.00000000	0.02357408	182.18127200	0.00462237	86.77364706
6.20000000	0.02435988	186.68724300	0.00477645	88.91985854
6.40000000	0.02514569	191.75522900	0.00493053	91.33375994
6.60000000	0.02593149	196.15274100	0.00508461	93.42831198
6.80000000	0.02671729	200.08683900	0.00523868	95.30213813
7.00000000	0.02750309	204.12939500	0.00539276	97.22762324
7.20000000	0.02828890	208.67480600	0.00554684	99.39262015
7.40000000	0.02907470	213.38783500	0.00570092	101.63745416
7.60000000	0.02986050	217.62758900	0.00585500	103.65686544
7.80000000	0.03064630	222.13356100	0.00600908	105.80307740
8.00000000	0.03143211	226.50149300	0.00616316	107.88354037
8.20000000	0.03221791	230.83984700	0.00631724	109.94991522
8.40000000	0.03300371	235.51343600	0.00647132	112.17596380
8.60000000	0.03378951	239.73347000	0.00662539	114.18598238
8.80000000	0.03457532	244.07182300	0.00677947	116.25235675
9.00000000	0.03536112	248.58765400	0.00693355	118.40326459
9.20000000	0.03614692	252.78796900	0.00708763	120.40389093
9.40000000	0.03693273	257.40239900	0.00724171	122.60176185
9.60000000	0.03771853	261.88865000	0.00739579	124.73858061
9.80000000	0.03850433	265.73400900	0.00754987	126.57014003
10.00000000	0.03929013	270.05264200	0.00770395	128.62712170
10.20000000	0.04007594	274.47973400	0.00785803	130.73576280
10.40000000	0.04086174	278.66032800	0.00801211	132.72699595
10.60000000	0.04164754	283.29447800	0.00816618	134.93425959
10.80000000	0.04243334	287.55395200	0.00832026	136.96306359
11.00000000	0.04321915	291.61622700	0.00847434	138.89794094
11.20000000	0.04400495	295.97430000	0.00862842	140.97370803
11.40000000	0.04479075	300.41125200	0.00878250	143.08704549
11.60000000	0.04557655	304.57212700	0.00893658	145.06888640
11.80000000	0.04636236	309.09781700	0.00909066	147.22449012
12.00000000	0.04714816	313.76154600	0.00924474	149.44584234
12.20000000	0.04793396	318.09989900	0.00939882	151.51221672
12.40000000	0.04871976	322.71432900	0.00955290	153.71008764
12.60000000	0.04950557	327.22030000	0.00970697	155.85629912
12.80000000	0.05029137	331.49949300	0.00986105	157.89449536
13.00000000	0.05107717	335.58148900	0.01001513	159.83876590
13.20000000	0.05186298	339.79166300	0.01016921	161.84408812
13.40000000	0.05264878	344.08071600	0.01032329	163.88698071
13.60000000	0.05343458	348.35004900	0.01047737	165.92048059
13.80000000	0.05422038	353.01377800	0.01063145	168.14183282
14.00000000	0.05500619	357.17465300	0.01078553	170.12367373
14.20000000	0.05579199	361.01015100	0.01093961	171.95053632
14.40000000	0.05657779	365.67388000	0.01109368	174.17188854
14.60000000	0.05736359	369.83475400	0.01124776	176.15372898
14.80000000	0.05814940	373.54207400	0.01140184	177.91953989
15.00000000	0.05893520	378.38328100	0.01155592	180.22542558
15.20000000	0.05972100	383.45126500	0.01171000	182.63932603
15.40000000	0.06050680	387.57270000	0.01186408	184.60238152
15.60000000	0.06129261	391.64483500	0.01201816	186.54195523
15.80000000	0.06207841	396.46632200	0.01217224	188.83844820
16.00000000	0.06286421	400.85397400	0.01232632	190.92830388
16.20000000	0.06365002	404.83737000	0.01248040	192.82561086
16.40000000	0.06443582	409.45180000	0.01263447	195.02348178
16.60000000	0.06522162	413.83945100	0.01278855	197.11333698
16.80000000	0.06600742	417.67494900	0.01294263	198.94019957
17.00000000	0.06679323	421.87526300	0.01309671	200.94082543
17.20000000	0.06757903	426.43053300	0.01325079	203.11051822
17.40000000	0.06836483	430.31533000	0.01340487	204.96086211
17.60000000	0.06915063	434.46634400	0.01355895	206.93800619
17.80000000	0.06993644	439.20895200	0.01371303	209.19692879
18.00000000	0.07072224	443.36982600	0.01386711	211.17876923
18.20000000	0.07150804	447.58986000	0.01402118	213.18878781
18.40000000	0.07229384	451.39577800	0.01417526	215.00156132
18.60000000	0.07307965	455.31015500	0.01432934	216.86599428
18.80000000	0.07386545	460.17108100	0.01448342	219.18127221
19.00000000	0.07465125	464.43055400	0.01463750	221.21007573
19.20000000	0.07543706	468.18717300	0.01479158	222.99936794
19.40000000	0.07622286	472.35790600	0.01494566	224.98590426
19.60000000	0.07700866	476.75541800	0.01509974	227.08045630
19.80000000	0.07779446	481.01489100	0.01525382	229.10925982
20.00000000	0.07858027	485.09688600	0.01540790	231.05352989
20.20000000	0.07936607	489.44509700	0.01556197	233.12459967
20.40000000	0.08015187	493.55667200	0.01571605	235.08295880
20.60000000	0.08093767	497.54006800	0.01587013	236.98026578
20.80000000	0.08172348	501.85870000	0.01602421	239.03724696
21.00000000	0.08250928	505.91111500	0.01617829	240.96742796
21.20000000	0.08329508	510.11142800	0.01633237	242.96805335
21.40000000	0.08408088	514.14412400	0.01648645	244.88884211
21.60000000	0.08486669	518.21625800	0.01664053	246.82841534
21.80000000	0.08565249	522.62363000	0.01679461	248.92766373
22.00000000	0.08643829	526.50842600	0.01694868	250.77800714
22.20000000	0.08722410	530.47210200	0.01710276	252.66592141
22.40000000	0.08800990	534.77101500	0.01725684	254.71351036
22.60000000	0.08879570	538.94174800	0.01741092	256.70004668
22.80000000	0.08958150	542.72794600	0.01756500	258.50342748
23.00000000	0.09036731	546.57330300	0.01771908	260.33498595
23.20000000	0.09115311	551.08913300	0.01787316	262.48589331
23.40000000	0.09193891	555.21056700	0.01802724	264.44894832
23.60000000	0.09272471	558.76012700	0.01818132	266.13961753
23.80000000	0.09351052	562.66464400	0.01833540	267.99935413
24.00000000	0.09429632	566.82551800	0.01848947	269.98119457
24.20000000	0.09508212	570.73989400	0.01864355	271.84562705
24.40000000	0.09586792	574.79230900	0.01879763	273.77580805
24.60000000	0.09665373	579.08136100	0.01895171	275.81870017
24.80000000	0.09743953	583.62677000	0.01910579	277.98369612
25.00000000	0.09822533	587.40310800	0.01925987	279.78238057
25.20000000	0.09901114	591.18930500	0.01941395	281.58576090
25.40000000	0.09979694	595.62625600	0.01956803	283.69909788
25.60000000	0.10058274	599.77726900	0.01972211	285.67624149
25.80000000	0.10136854	603.62262600	0.01987618	287.50779995
26.00000000	0.10215435	607.74406000	0.02003026	289.47085497
26.20000000	0.10294015	612.02325200	0.02018434	291.50905073
26.40000000	0.10372595	615.61225200	0.02033842	293.21850536
26.60000000	0.10451175	619.51676800	0.02049250	295.07824149
26.80000000	0.10529756	623.70722100	0.02064658	297.07417052
27.00000000	0.10608336	627.77935600	0.02080066	299.01374422
27.20000000	0.10686916	631.66415200	0.02095474	300.86408764
27.40000000	0.10765496	635.62782700	0.02110882	302.75200143
27.60000000	0.10844077	639.95631900	0.02126290	304.81367897
27.80000000	0.10922657	643.86083500	0.02141697	306.67341510
28.00000000	0.11001237	647.75549100	0.02157105	308.52845487
28.20000000	0.11079818	651.76846600	0.02172513	310.43985044
28.40000000	0.11158398	655.49550400	0.02187921	312.21505311
28.60000000	0.11236978	659.80427500	0.02203329	314.26733746
28.80000000	0.11315558	663.65949200	0.02218737	316.10359228
29.00000000	0.11394139	667.50484900	0.02234145	317.93515075
29.20000000	0.11472719	671.70516100	0.02249553	319.93577566
29.40000000	0.11551299	675.69841600	0.02264961	321.83777852
29.60000000	0.11629879	679.46489400	0.02280369	323.63176661
29.80000000	0.11708460	683.23137100	0.02295776	325.42575423
30.00000000	0.11787040	687.22462600	0.02311184	327.32775709
30.20000000	0.11865620	691.07984300	0.02326592	329.16401191
30.40000000	0.11944200	694.95477900	0.02342000	331.00965897
30.60000000	0.12022781	698.34658100	0.02357408	332.62518743
30.80000000	0.12101361	702.15249800	0.02372816	334.43796047
31.00000000	0.12179941	706.28379100	0.02388224	336.40571136
31.20000000	0.12258521	710.03054800	0.02403632	338.19030626
31.40000000	0.12337102	713.82660500	0.02419040	339.99838295
31.60000000	0.12415682	717.90859900	0.02434447	341.94265254
31.80000000	0.12494262	721.37928000	0.02449855	343.59575137
32.00000000	0.12572843	724.87954000	0.02465263	345.26293879
32.20000000	0.12651423	729.03055300	0.02480671	347.24008240
32.40000000	0.12730003	732.96464900	0.02496079	349.11390760
32.60000000	0.12808583	736.59308700	0.02511487	350.84214670
32.80000000	0.12887164	740.27082600	0.02526895	352.59386806
33.00000000	0.12965744	744.37253900	0.02542303	354.54752989
33.20000000	0.13044324	748.27705500	0.02557711	356.40726602
33.40000000	0.13122904	751.60969700	0.02573119	357.99461634
33.60000000	0.13201485	755.33673400	0.02588526	359.76981853
33.80000000	0.13280065	759.43844800	0.02603934	361.72348083
34.00000000	0.13358645	762.98800700	0.02619342	363.41414956
34.20000000	0.13437225	766.67560500	0.02634750	365.17056680
34.40000000	0.13515806	770.76745900	0.02650158	367.11953275
34.60000000	0.13594386	774.62267500	0.02665566	368.95578709
34.80000000	0.13672966	778.14265500	0.02680974	370.63236723
35.00000000	0.13751547	781.47529700	0.02696382	372.21971755
35.20000000	0.13830127	784.83751800	0.02711790	373.82115647
35.40000000	0.13908707	788.91951200	0.02727197	375.76542605
35.60000000	0.13987287	792.64654900	0.02742605	377.54062824
35.80000000	0.14065868	795.77213400	0.02758013	379.02935651
36.00000000	0.14144448	799.32169300	0.02773421	380.72002524
36.20000000	0.14223028	803.47270500	0.02788829	382.69716837
36.40000000	0.14301608	807.49553900	0.02804237	384.61325982
36.60000000	0.14380189	810.67042300	0.02819645	386.12546940
36.80000000	0.14458769	814.18054300	0.02835053	387.79735318
37.00000000	0.14537349	817.86814100	0.02850461	389.55377042
37.20000000	0.14615929	821.25008200	0.02865869	391.16460205
37.40000000	0.14694510	825.14473700	0.02881276	393.01964134
37.60000000	0.14773090	828.96051400	0.02896684	394.83711074
37.80000000	0.14851670	832.15511700	0.02912092	396.35871255
38.00000000	0.14930251	835.66523700	0.02927500	398.03059633
38.20000000	0.15008831	839.71765000	0.02942908	399.96077638
38.40000000	0.15087411	843.36580800	0.02958316	401.69840819
38.60000000	0.15165991	846.98438700	0.02973724	403.42195142
38.80000000	0.15244572	850.72128400	0.02989132	405.20184996
39.00000000	0.15323152	854.37930200	0.03004540	406.94417814
39.20000000	0.15401732	857.93872100	0.03019947	408.63954322
39.40000000	0.15480312	861.20234300	0.03035355	410.19401905
39.60000000	0.15558893	864.58428400	0.03050763	411.80485068
39.80000000	0.15637473	868.20286300	0.03066171	413.52839390
40.00000000	0.15716053	871.78200200	0.03081579	415.23315170
40.20000000	0.15794633	875.32170100	0.03096987	416.91912408
40.40000000	0.15873214	878.71350200	0.03112395	418.53465206
40.60000000	0.15951794	881.93768500	0.03127803	420.07034294
40.80000000	0.16030374	885.45766400	0.03143211	421.74692260
41.00000000	0.16108955	888.94806400	0.03158619	423.40941367
41.20000000	0.16187535	892.40888400	0.03174026	425.05781567
41.40000000	0.16266115	895.67250600	0.03189434	426.61229150
41.60000000	0.16344695	898.63047200	0.03204842	428.02118219
41.80000000	0.16423276	901.94339400	0.03220250	429.59913980
42.00000000	0.16501856	905.15771600	0.03235658	431.13013384
42.20000000	0.16580436	908.26358000	0.03251066	432.60946892
42.40000000	0.16659016	911.59622200	0.03266474	434.19681924
42.60000000	0.16737597	914.94858300	0.03281882	435.79356180
42.80000000	0.16816177	918.62632100	0.03297290	437.54528269
43.00000000	0.16894757	922.04770100	0.03312697	439.17489926
43.20000000	0.16973337	925.40006200	0.03328105	440.77164182
43.40000000	0.17051918	928.96934100	0.03343513	442.47170326
43.60000000	0.17130498	932.10478400	0.03358921	443.96512693
43.80000000	0.17209078	935.32896700	0.03374329	445.50081781
44.00000000	0.17287659	938.59258900	0.03389737	447.05529364
44.20000000	0.17366239	941.64915400	0.03405145	448.51114742
44.40000000	0.17444819	945.23815200	0.03420553	450.22060110
44.60000000	0.17523399	949.11308700	0.03435961	452.06624768
44.80000000	0.17601980	952.62320600	0.03451369	453.73813098
45.00000000	0.17680560	956.15304500	0.03466776	455.41940700
45.20000000	0.17759140	959.38708700	0.03482184	456.95979376
45.40000000	0.17837720	962.44365200	0.03497592	458.41564754
45.60000000	0.17916301	965.64811500	0.03513000	459.94194570
45.80000000	0.17994881	969.59206900	0.03528408	461.82046630
46.00000000	0.18073461	972.93457000	0.03543816	463.41251250
46.20000000	0.18152041	975.71505700	0.03559224	464.73686925
46.40000000	0.18230622	979.27447600	0.03574632	466.43223434
46.60000000	0.18309202	982.42963900	0.03590040	467.93505073
46.80000000	0.18387782	985.57494200	0.03605447	469.43317075
47.00000000	0.18466363	989.35127800	0.03620855	471.23185425
47.20000000	0.18544943	992.76279800	0.03636263	472.85677447
47.40000000	0.18623523	996.17431900	0.03651671	474.48169517
47.60000000	0.18702103	999.84219600	0.03667079	476.22871922
47.80000000	0.18780684	1002.91848000	0.03682487	477.69396523
48.00000000	0.18859264	1006.20182100	0.03697895	479.25783329
48.20000000	0.18937844	1009.42600400	0.03713303	480.79352417
48.40000000	0.19016424	1012.40368900	0.03728711	482.21180710
48.60000000	0.19095005	1015.73633000	0.03744119	483.79915694
48.80000000	0.19173585	1019.16757000	0.03759526	485.43346987
49.00000000	0.19252165	1022.25371300	0.03774934	486.90341176
49.20000000	0.19330745	1024.82714300	0.03790342	488.12914646
49.40000000	0.19409326	1027.57805100	0.03805750	489.43941462
49.60000000	0.19487906	1031.21634800	0.03821158	491.17234961
49.80000000	0.19566486	1034.73632700	0.03836566	492.84892927
50.00000000	0.19645067	1037.21115800	0.03851974	494.02770088
50.20000000	0.19723647	1040.13954400	0.03867382	495.42250250
50.40000000	0.19802227	1043.60036300	0.03882790	497.07090402
50.60000000	0.19880807	1046.85412500	0.03898198	498.62068350
50.80000000	0.19959388	1049.82195000	0.03913605	500.03427006
51.00000000	0.20037968	1052.74047500	0.03929013	501.42437485
51.20000000	0.20116548	1055.63928100	0.03944421	502.80508740
51.40000000	0.20195128	1058.60710600	0.03959829	504.21867397
51.60000000	0.20273709	1061.24955500	0.03975237	505.47728269
51.80000000	0.20352289	1063.46802900	0.03990645	506.53395046
52.00000000	0.20430869	1065.88370100	0.04006053	507.68454442
52.20000000	0.20509449	1068.49657000	0.04021461	508.92906406
52.40000000	0.20588030	1071.17845800	0.04036869	510.20645773
52.60000000	0.20666610	1073.82090700	0.04052276	511.46506644
52.80000000	0.20745190	1076.38447700	0.04067684	512.68610479
53.00000000	0.20823770	1078.62267100	0.04083092	513.75216528
53.20000000	0.20863061	1080.98904300	0.04090796	514.87927745
53.40000000	0.20981104	1083.39485400	0.04113942	516.02517457
53.60000000	0.21099147	1085.55416900	0.04137088	517.05366468
53.80000000	0.21217190	1087.43740700	0.04160233	517.95065825
54.00000000	0.21335233	1089.57700100	0.04183379	518.96975518
54.20000000	0.21453276	1091.63771700	0.04206525	519.95128221
54.40000000	0.21571319	1093.59983400	0.04229670	520.88584615
54.60000000	0.21689362	1095.24643400	0.04252816	521.67012813
54.80000000	0.21807405	1096.90289500	0.04275962	522.45910693
55.00000000	0.21925448	1098.68753400	0.04299107	523.30913741
55.20000000	0.22043491	1100.19609600	0.04322253	524.02767135
55.40000000	0.22161534	1101.57647900	0.04345399	524.68515313
55.60000000	0.22279577	1102.78924500	0.04368544	525.26279829
55.80000000	0.22397620	1103.97243100	0.04391690	525.82635437
56.00000000	0.22515663	1105.11617800	0.04414836	526.37112551
56.20000000	0.22633706	1106.37824300	0.04437982	526.97225196
56.40000000	0.22751749	1107.07829400	0.04461127	527.30568897
56.60000000	0.22869792	1107.88680500	0.04484273	527.69078590
56.80000000	0.22987835	1109.46438600	0.04507419	528.44219386
57.00000000	0.23105878	1110.61799200	0.04530564	528.99166087
57.20000000	0.23223921	1111.30818400	0.04553710	529.32040200
57.40000000	0.23341964	1112.05753500	0.04576856	529.67732079
57.60000000	0.23460007	1112.68856800	0.04600001	529.97788426
57.80000000	0.23578050	1113.11254300	0.04623147	530.17982520
58.00000000	0.23696093	1113.64497700	0.04646293	530.43342558
58.20000000	0.23814136	1113.93091300	0.04669438	530.56961800
58.40000000	0.23932179	1114.00979200	0.04692584	530.60718838
58.60000000	0.24050222	1115.00564000	0.04715730	531.08151465
58.80000000	0.24168265	1115.43947500	0.04738876	531.28815194
59.00000000	0.24286308	1115.40989600	0.04762021	531.27406335
59.20000000	0.24404351	1116.14938700	0.04785167	531.62628578
59.40000000	0.24522394	1116.62266100	0.04808313	531.85170803
59.60000000	0.24640437	1116.72126000	0.04831458	531.89867111
59.80000000	0.24758480	1116.72126000	0.04854604	531.89867111
60.00000000	0.24876523	1116.92831800	0.04877750	531.99729364
60.20000000	0.24994566	1117.09593600	0.04900895	532.07713075
60.40000000	0.25112609	1117.03677600	0.04924041	532.04895261
60.60000000	0.25230652	1117.74668800	0.04947187	532.38708645
60.80000000	0.25348695	1118.62421800	0.04970332	532.80505739
61.00000000	0.25466738	1118.76225600	0.04993478	532.87080543
61.20000000	0.25584781	1119.02847300	0.05016624	532.99760562
61.40000000	0.25702824	1119.40314800	0.05039769	533.17606478
61.60000000	0.25820867	1119.38342900	0.05062915	533.16667254
61.80000000	0.25938910	1119.50174700	0.05086061	533.22302786
62.00000000	0.26056953	1119.95530200	0.05109207	533.43905787
62.20000000	0.26174996	1119.79754400	0.05132352	533.36391712
62.40000000	0.26293039	1119.79754400	0.05155498	533.36391712
62.60000000	0.26411083	1119.97502200	0.05178644	533.44845058
62.80000000	0.26529126	1119.87642300	0.05201789	533.40148750
63.00000000	0.26647169	1120.23137900	0.05224935	533.57055442
63.20000000	0.26765212	1120.28067800	0.05248081	533.59403572
63.40000000	0.26883255	1120.45815600	0.05271226	533.67856918
63.60000000	0.27001298	1120.72437300	0.05294372	533.80536937
63.80000000	0.27119341	1120.91171000	0.05317518	533.89459871
64.00000000	0.27237384	1121.33568500	0.05340663	534.09653965
64.20000000	0.27355427	1121.49344400	0.05363809	534.17168088
64.40000000	0.27473470	1121.51316300	0.05386955	534.18107311
64.60000000	0.27591513	1121.43428400	0.05410101	534.14350274
64.80000000	0.27709556	1121.49344400	0.05433246	534.17168088
65.00000000	0.27827599	1121.87797900	0.05456392	534.35483639
65.20000000	0.27945642	1122.04559700	0.05479538	534.43467349
65.40000000	0.28063685	1121.86811900	0.05502683	534.35014003
65.60000000	0.28181728	1121.45400400	0.05525829	534.15289545
65.80000000	0.28299771	1121.54274300	0.05548975	534.19516218
66.00000000	0.28417814	1122.01601700	0.05572120	534.42058442
66.20000000	0.28535857	1121.79910000	0.05595266	534.31726602
66.40000000	0.28653900	1121.77938000	0.05618412	534.30787330
66.60000000	0.28771943	1122.32167400	0.05641557	534.56617004
66.80000000	0.28889986	1122.53859100	0.05664703	534.66948845
67.00000000	0.29008029	1122.38083300	0.05687849	534.59434770
67.20000000	0.29126072	1122.14419600	0.05710994	534.48163658
67.40000000	0.29244115	1122.35125300	0.05734140	534.58025863
67.60000000	0.29362158	1122.67663000	0.05757286	534.73523696
67.80000000	0.29480201	1122.61747000	0.05780432	534.70705882
68.00000000	0.29598244	1122.81466800	0.05803577	534.80098500
68.20000000	0.29716287	1122.92312700	0.05826723	534.85264444
68.40000000	0.29834330	1122.93298600	0.05849869	534.85734032
68.60000000	0.29952373	1122.92312700	0.05873014	534.85264444
68.80000000	0.30070416	1122.82452800	0.05896160	534.80568135
69.00000000	0.30188459	1122.50901200	0.05919306	534.65539986
69.20000000	0.30306502	1122.57803100	0.05942451	534.68827387
69.40000000	0.30424545	1122.70620900	0.05965597	534.74932555
69.60000000	0.30542588	1122.64705000	0.05988743	534.72114789
69.80000000	0.30660631	1122.52873100	0.06011888	534.66479209
70.00000000	0.30778674	1122.13433600	0.06035034	534.47694022
70.20000000	0.30896717	1122.25265500	0.06058180	534.53329602
70.40000000	0.31014760	1122.51887100	0.06081326	534.66009574
70.60000000	0.31132803	1122.28223400	0.06104471	534.54738462
70.80000000	0.31250846	1122.27237400	0.06127617	534.54268826
71.00000000	0.31368889	1122.41041300	0.06150763	534.60843677
71.20000000	0.31486932	1122.37097300	0.06173908	534.58965135
71.40000000	0.31604975	1122.62733000	0.06197054	534.71175518
71.60000000	0.31723018	1122.44985200	0.06220200	534.62722172
71.80000000	0.31841061	1122.32167400	0.06243345	534.56617004
72.00000000	0.31959104	1122.47943200	0.06266491	534.64131079
72.20000000	0.32077147	1122.30195400	0.06289637	534.55677733
72.40000000	0.32195190	1122.25265500	0.06312782	534.53329602
72.60000000	0.32313233	1121.93713800	0.06335928	534.38301405
72.80000000	0.32431276	1121.86811900	0.06359074	534.35014003
73.00000000	0.32549319	1122.04559700	0.06382220	534.43467349
73.20000000	0.32667363	1121.81882000	0.06405365	534.32665873
73.40000000	0.32785406	1121.86811900	0.06428511	534.35014003
73.60000000	0.32903449	1121.83853900	0.06451657	534.33605096
73.80000000	0.33021492	1121.96671800	0.06474802	534.39710312
74.00000000	0.33139535	1122.12447600	0.06497948	534.47224387
74.20000000	0.33257578	1121.72022100	0.06521094	534.27969564
74.40000000	0.33375621	1121.72022100	0.06544239	534.27969564
74.60000000	0.33493664	1122.12447600	0.06567385	534.47224387
74.80000000	0.33611707	1122.24279500	0.06590531	534.52859967
75.00000000	0.33729750	1122.42027300	0.06613676	534.61313313
75.20000000	0.33847793	1122.24279500	0.06636822	534.52859967
75.40000000	0.33965836	1122.16391600	0.06659968	534.49102929
75.60000000	0.34083879	1121.95685800	0.06683113	534.39240676
75.80000000	0.34201922	1121.58218300	0.06706259	534.21394761
76.00000000	0.34319965	1121.64134200	0.06729405	534.24212527
76.20000000	0.34438008	1121.30610600	0.06752551	534.08245106
76.40000000	0.34556051	1121.22722700	0.06775696	534.04488069
76.60000000	0.34674094	1121.44414400	0.06798842	534.14819910
76.80000000	0.34792137	1121.21736700	0.06821988	534.04018433
77.00000000	0.34910180	1120.72437300	0.06845133	533.80536937
77.20000000	0.35028223	1120.24123800	0.06868279	533.57525030
77.40000000	0.35146266	1120.32997700	0.06891425	533.61751703
77.60000000	0.35264309	1120.78353200	0.06914570	533.83354704
77.80000000	0.35382352	1120.83283100	0.06937716	533.85702834
78.00000000	0.35500395	1120.55675500	0.06960862	533.72553227
78.20000000	0.35618438	1120.36941700	0.06984007	533.63630245
78.40000000	0.35736481	1120.29053800	0.07007153	533.59873208
78.60000000	0.35854524	1120.43843600	0.07030299	533.66917647
78.80000000	0.35972567	1120.58633400	0.07053445	533.73962086
79.00000000	0.36090610	1120.04404100	0.07076590	533.48132460
79.20000000	0.36208653	1119.85670300	0.07099736	533.39209478
79.40000000	0.36326696	1119.78768400	0.07122882	533.35922077
79.60000000	0.36444739	1119.27497000	0.07146027	533.11501310
79.80000000	0.36562782	1119.37356900	0.07169173	533.16197618
80.00000000	0.36680825	1119.36370900	0.07192319	533.15727983
80.20000000	0.36798868	1119.36370900	0.07215464	533.15727983
80.40000000	0.36916911	1119.40314800	0.07238610	533.17606478
80.60000000	0.37034954	1119.00875300	0.07261756	532.98821291
80.80000000	0.37152997	1119.05805200	0.07284901	533.01169421
81.00000000	0.37271040	1118.80169500	0.07308047	532.88959038
81.20000000	0.37389083	1118.14108300	0.07331193	532.57493832
81.40000000	0.37507126	1117.69738900	0.07354338	532.36360514
81.60000000	0.37625169	1117.24383400	0.07377484	532.14757514
81.80000000	0.37743212	1117.17481500	0.07400630	532.11470112
82.00000000	0.37861255	1117.21425400	0.07423776	532.13348607
82.20000000	0.37979298	1117.11565500	0.07446921	532.08652298
82.40000000	0.38097341	1117.02691700	0.07470067	532.04425673
82.60000000	0.38215384	1117.02691700	0.07493213	532.04425673
82.80000000	0.38333427	1116.64238100	0.07516358	531.86110074
83.00000000	0.38451470	1116.21840600	0.07539504	531.65915980
83.20000000	0.38569513	1116.30714500	0.07562650	531.70142653
83.40000000	0.38687556	1115.78457100	0.07585795	531.45252251
83.60000000	0.38805599	1115.24227800	0.07608941	531.19422624
83.80000000	0.38923643	1115.13381900	0.07632087	531.14256680
84.00000000	0.39041686	1114.90704200	0.07655232	531.03455204
84.20000000	0.39159729	1114.88732200	0.07678378	531.02515932
84.40000000	0.39277772	1114.56194600	0.07701524	530.87018147
84.60000000	0.39395815	1113.98021300	0.07724670	530.59309979
84.80000000	0.39513858	1114.02951200	0.07747815	530.61658109
85.00000000	0.39631901	1114.22671000	0.07770961	530.71050726
85.20000000	0.39749944	1114.21685000	0.07794107	530.70581091
85.40000000	0.39867987	1114.25628900	0.07817252	530.72459586
85.60000000	0.39986030	1114.17741000	0.07840398	530.68702548
85.80000000	0.40104073	1114.05909200	0.07863544	530.63067016
86.00000000	0.40222116	1114.01965200	0.07886689	530.61188473
86.20000000	0.40340159	1113.69427600	0.07909835	530.45690688
86.40000000	0.40458202	1113.17170200	0.07932981	530.20800286
86.60000000	0.40576245	1113.06324300	0.07956126	530.15634342
86.80000000	0.40694288	1113.02380400	0.07979272	530.13755847
87.00000000	0.40812331	1113.01394400	0.08002418	530.13286211
87.20000000	0.40930374	1113.03366400	0.08025563	530.14225482
87.40000000	0.41048417	1112.52095000	0.08048709	529.89804715
87.60000000	0.41166460	1111.88991700	0.08071855	529.59748369
87.80000000	0.41284503	1111.29832400	0.08095001	529.31570564
88.00000000	0.41402546	1111.27860500	0.08118146	529.30631341
88.20000000	0.41520589	1112.03781600	0.08141292	529.66792855
88.40000000	0.41638632	1111.67300000	0.08164438	529.49416528
88.60000000	0.41756675	1111.10112700	0.08187583	529.22177995
88.80000000	0.41874718	1111.41664300	0.08210729	529.37206144
89.00000000	0.41992761	1111.27860500	0.08233875	529.30631341
89.20000000	0.42110804	1111.07154700	0.08257020	529.20769088
89.40000000	0.42228847	1111.17014600	0.08280166	529.25465397
89.60000000	0.42346890	1110.84477000	0.08303312	529.09967611
89.80000000	0.42464933	1110.66729200	0.08326457	529.01514265
90.00000000	0.42582976	1110.88420900	0.08349603	529.11846106
90.20000000	0.42701019	1110.43065500	0.08372749	528.90243153
90.40000000	0.42819062	1110.19401700	0.08395895	528.78971993
90.60000000	0.42937105	1110.12499800	0.08419040	528.75684592
90.80000000	0.43055148	1109.42494700	0.08442186	528.42340891
91.00000000	0.43173191	1108.93195200	0.08465332	528.18859347
91.20000000	0.43291234	1108.74461500	0.08488477	528.09936413
91.40000000	0.43409277	1108.81363400	0.08511623	528.13223815
91.60000000	0.43527320	1108.45867800	0.08534769	527.96317123
91.80000000	0.43645363	1108.16288200	0.08557914	527.82228245
92.00000000	0.43763406	1107.99526300	0.08581060	527.74244487
92.20000000	0.43881449	1107.76848600	0.08604206	527.63443010
92.40000000	0.43999492	1107.53184900	0.08627351	527.52171898
92.60000000	0.44117535	1107.09801400	0.08650497	527.31508169
92.80000000	0.44235578	1107.16703300	0.08673643	527.34795570
93.00000000	0.44353621	1106.87123700	0.08696789	527.20706692
93.20000000	0.44471664	1106.13174600	0.08719934	526.85484449
93.40000000	0.44589707	1106.02328700	0.08743080	526.80318504
93.60000000	0.44707750	1105.61903200	0.08766226	526.61063682
93.80000000	0.44825793	1105.42183400	0.08789371	526.51671065
94.00000000	0.44943836	1105.61903200	0.08812517	526.61063682
94.20000000	0.45061879	1105.19505700	0.08835663	526.40869588
94.40000000	0.45179923	1104.44570600	0.08858808	526.05177709
94.60000000	0.45297966	1104.20906800	0.08881954	525.93906549
94.80000000	0.45416009	1104.03159000	0.08905100	525.85453203
95.00000000	0.45534052	1103.38083800	0.08928245	525.54457633
95.20000000	0.45652095	1102.70050600	0.08951391	525.22053156
95.40000000	0.45770138	1101.88213600	0.08974537	524.83073875
95.60000000	0.45888181	1101.47788100	0.08997682	524.63819052
95.80000000	0.46006224	1100.98488600	0.09020828	524.40337509
96.00000000	0.46124267	1100.47217300	0.09043974	524.15916790
96.20000000	0.46242310	1099.72282100	0.09067120	523.80224863
96.40000000	0.46360353	1098.93403100	0.09090265	523.42654489
96.60000000	0.46478396	1098.23397900	0.09113411	523.09310741
96.80000000	0.46596439	1096.71555700	0.09136557	522.36987711
97.00000000	0.46714482	1095.14783500	0.09159702	521.62316504
97.20000000	0.46832525	1093.72801200	0.09182848	520.94689783
97.40000000	0.46950568	1091.79547500	0.09205994	520.02642296
97.60000000	0.47068611	1089.42910300	0.09229139	518.89931079
97.80000000	0.47186654	1086.03730300	0.09252285	517.28378328
98.00000000	0.47304697	1080.54534800	0.09275431	514.66794380
98.20000000	0.47422740	1073.28847400	0.09298576	511.21146654
98.40000000	0.47540783	1063.77368600	0.09321722	506.67953608
98.60000000	0.47658826	1046.69636600	0.09344868	498.54554227