File: data/output/vidExt_M-35Zr39Ti25Nb_Glb_11_0pt1/vidExt_M-35Zr39Ti25Nb_Glb_11_0pt1_normCorrelated.txt
Total length (mm) = 50
Gage length (mm) = 5.1
Width (mm) = 2.21
Thickness (mm) = 0.95
----------
Time (s)	Displacement (mm)	Force (N)	Eng. strain	Eng. stress (MPa)
0.00000000	0.00000000	137.61455100	0.00000000	65.54634484
0.20000000	0.00100920	141.66696700	0.00019788	67.47652632
0.40000000	0.00201841	145.74896400	0.00039577	69.42079733
0.60000000	0.00302761	150.16619600	0.00059365	71.52474208
0.80000000	0.00403681	154.63272800	0.00079153	73.65216861
1.00000000	0.00504602	158.68514500	0.00098941	75.58235056
1.20000000	0.00605522	163.08265700	0.00118730	77.67690260
1.40000000	0.00706442	167.05619500	0.00138518	79.56951417
1.60000000	0.00807363	171.34524800	0.00158306	81.61240676
1.80000000	0.00908283	176.02869800	0.00178095	83.84315218
2.00000000	0.01009203	180.24873300	0.00197883	85.85317123
2.20000000	0.01110124	184.56736600	0.00217671	87.91015289
2.40000000	0.01211044	189.18179600	0.00237460	90.10802382
2.60000000	0.01311964	193.77650700	0.00257248	92.29650250
2.80000000	0.01412885	197.99654100	0.00277036	94.30652108
3.00000000	0.01513805	202.03909800	0.00296824	96.23200667
3.20000000	0.01614725	206.48591000	0.00316613	98.35004049
3.40000000	0.01715645	211.13977900	0.00336401	100.56669636
3.60000000	0.01816566	215.53729200	0.00356189	102.66124887
3.80000000	0.01917486	219.66858700	0.00375978	104.62900071
4.00000000	0.02018406	224.27315800	0.00395766	106.82217576
4.20000000	0.02119327	228.97632700	0.00415554	109.06231341
4.40000000	0.02220247	233.21608100	0.00435343	111.08172470
4.60000000	0.02321167	237.58401400	0.00455131	113.16218814
4.80000000	0.02422088	241.74488900	0.00474919	115.14402905
5.00000000	0.02523008	246.09310100	0.00494707	117.21509931
5.20000000	0.02623928	250.93430900	0.00514496	119.52098547
5.40000000	0.02724849	255.31210200	0.00534284	121.60614527
5.60000000	0.02825769	259.55185600	0.00554072	123.62555656
5.80000000	0.02926689	263.70287100	0.00573861	125.60270112
6.00000000	0.03027610	267.86374500	0.00593649	127.58454156
6.20000000	0.03128530	272.47817500	0.00613437	129.78241248
6.40000000	0.03229450	276.61933000	0.00633226	131.75486068
6.60000000	0.03330371	280.76048500	0.00653014	133.72730888
6.80000000	0.03431291	285.36505500	0.00672802	135.92048345
7.00000000	0.03532211	289.61466900	0.00692590	137.94459109
7.20000000	0.03633132	293.91358200	0.00712379	139.99218004
7.40000000	0.03734052	298.25193500	0.00732167	142.05855442
7.60000000	0.03834972	302.33393100	0.00751955	144.00282496
7.80000000	0.03935893	306.89906100	0.00771744	146.17721410
8.00000000	0.04036813	311.40503200	0.00791532	148.32342558
8.20000000	0.04137733	315.78282400	0.00811320	150.40858490
8.40000000	0.04238654	320.56487200	0.00831109	152.68629293
8.60000000	0.04339574	324.89336500	0.00850897	154.74797095
8.80000000	0.04440494	329.28101700	0.00870685	156.83782663
9.00000000	0.04541415	333.66866900	0.00890473	158.92768231
9.20000000	0.04642335	337.66192600	0.00910262	160.82968612
9.40000000	0.04743255	342.02985800	0.00930050	162.91014908
9.60000000	0.04844175	346.08227400	0.00949838	164.84033055
9.80000000	0.04945096	350.72628300	0.00969627	167.05229007
10.00000000	0.05046016	355.17309500	0.00989415	169.17032389
10.20000000	0.05146936	359.03817200	0.01009203	171.01127507
10.40000000	0.05247857	363.26806600	0.01028992	173.02599000
10.60000000	0.05348777	367.61627800	0.01048780	175.09706025
10.80000000	0.05449697	371.90533100	0.01068568	177.13995285
11.00000000	0.05550618	376.00704700	0.01088356	179.09361610
11.20000000	0.05651538	380.77923400	0.01108145	181.36662729
11.40000000	0.05752458	385.57114200	0.01127933	183.64903167
11.60000000	0.05853379	389.72215600	0.01147721	185.62617576
11.80000000	0.05954299	393.89289000	0.01167510	187.61271255
12.00000000	0.06055219	398.55661900	0.01187298	189.83406478
12.20000000	0.06156140	402.87525200	0.01207086	191.89104644
12.40000000	0.06257060	407.18402500	0.01226875	193.94333175
12.60000000	0.06357980	411.89705300	0.01246663	196.18816528
12.80000000	0.06458901	415.97904800	0.01266451	198.13243534
13.00000000	0.06559821	419.68636700	0.01286239	199.89824577
13.20000000	0.06660741	424.06415900	0.01306028	201.98340510
13.40000000	0.06761662	428.32363200	0.01325816	204.01220862
13.60000000	0.06862582	432.21828900	0.01345604	205.86724887
13.80000000	0.06963502	436.87215800	0.01365393	208.08390474
14.00000000	0.07064423	441.31896900	0.01385181	210.20193808
14.20000000	0.07165343	445.46012300	0.01404969	212.17438581
14.40000000	0.07266263	449.55197800	0.01424757	214.12335223
14.60000000	0.07367184	453.46635500	0.01444546	215.98778519
14.80000000	0.07468104	457.77512700	0.01464334	218.04007002
15.00000000	0.07569024	462.17263900	0.01484122	220.13462205
15.20000000	0.07669944	466.17575500	0.01503911	222.04132174
15.40000000	0.07770865	470.23803000	0.01523699	223.97619910
15.60000000	0.07871785	474.76372000	0.01543487	226.13180281
15.80000000	0.07972705	478.93445400	0.01563276	228.11833960
16.00000000	0.08073626	482.93756900	0.01583064	230.02503882
16.20000000	0.08174546	487.51255900	0.01602852	232.20412432
16.40000000	0.08275466	491.35791600	0.01622640	234.03568278
16.60000000	0.08376387	495.41033100	0.01642429	235.96586378
16.80000000	0.08477307	499.77826300	0.01662217	238.04632674
17.00000000	0.08578227	503.78137900	0.01682005	239.95302643
17.20000000	0.08679148	508.10001100	0.01701794	242.01000762
17.40000000	0.08780068	512.22144500	0.01721582	243.97306263
17.60000000	0.08880988	516.17526100	0.01741370	245.85628054
17.80000000	0.08981909	520.35585500	0.01761159	247.84751369
18.00000000	0.09082829	524.70406600	0.01780947	249.91858347
18.20000000	0.09183749	528.34236600	0.01800735	251.65151989
18.40000000	0.09284670	532.53281900	0.01820523	253.64744892
18.60000000	0.09385590	536.96977000	0.01840312	255.76078590
18.80000000	0.09486510	540.63764900	0.01860100	257.50781091
19.00000000	0.09587431	544.69006400	0.01879888	259.43799190
19.20000000	0.09688351	549.00869600	0.01899677	261.49497309
19.40000000	0.09789271	553.11041000	0.01919465	263.44863539
19.60000000	0.09890192	556.88674800	0.01939253	265.24731984
19.80000000	0.09991112	560.60392700	0.01959042	267.01782663
20.00000000	0.10092032	564.72536100	0.01978830	268.98088164
20.20000000	0.10192953	568.77777600	0.01998618	270.91106263
20.40000000	0.10293873	572.83019100	0.02018406	272.84124363
20.60000000	0.10394793	577.06994300	0.02038195	274.86065397
20.80000000	0.10495714	581.38857500	0.02057983	276.91763515
21.00000000	0.10596634	585.51000900	0.02077771	278.88069016
21.20000000	0.10697554	589.32578600	0.02097560	280.69815956
21.40000000	0.10798474	593.42750000	0.02117348	282.65182186
21.60000000	0.10899395	597.56865400	0.02137136	284.62426959
21.80000000	0.11000315	601.69994800	0.02156925	286.59202096
22.00000000	0.11101235	605.97914000	0.02176713	288.63021672
22.20000000	0.11202156	609.94281600	0.02196501	290.51813098
22.40000000	0.11303076	613.60083500	0.02216289	292.26045963
22.60000000	0.11403996	617.55465000	0.02236078	294.14367707
22.80000000	0.11504917	621.65636400	0.02255866	296.09733937
23.00000000	0.11605837	625.80737800	0.02275654	298.07448345
23.20000000	0.11706757	629.84993200	0.02295443	299.99996761
23.40000000	0.11807678	633.64599000	0.02315231	301.80804477
23.60000000	0.11908598	637.69840400	0.02335019	303.73822529
23.80000000	0.12009518	641.81983800	0.02354808	305.70128030
24.00000000	0.12110439	645.77365300	0.02374596	307.58449774
24.20000000	0.12211359	649.52041100	0.02394384	309.36909312
24.40000000	0.12312279	653.73058400	0.02414172	311.37441486
24.60000000	0.12413200	657.95061600	0.02433961	313.38443248
24.80000000	0.12514120	661.62835500	0.02453749	315.13615385
25.00000000	0.12615040	665.39483300	0.02473537	316.93014194
25.20000000	0.12715961	669.57542500	0.02493326	318.92137414
25.40000000	0.12816881	673.77573800	0.02513114	320.92199952
25.60000000	0.12917801	677.59151500	0.02532902	322.73946892
25.80000000	0.13018722	681.33827300	0.02552691	324.52406430
26.00000000	0.13119642	685.25264900	0.02572479	326.38849678
26.20000000	0.13220562	689.18674400	0.02592267	328.26232151
26.40000000	0.13321483	693.02224100	0.02612055	330.08918362
26.60000000	0.13422403	696.53236100	0.02631844	331.76106740
26.80000000	0.13523323	700.31855800	0.02651632	333.56444773
27.00000000	0.13624244	704.24279400	0.02671420	335.43357657
27.20000000	0.13725164	708.09801000	0.02691209	337.26983091
27.40000000	0.13826084	711.89406700	0.02710997	339.07790760
27.60000000	0.13927004	715.82816300	0.02730785	340.95173279
27.80000000	0.14027925	719.66365900	0.02750573	342.77859443
28.00000000	0.14128845	723.20335900	0.02770362	344.46456728
28.20000000	0.14229765	727.11773500	0.02790150	346.32899976
28.40000000	0.14330686	730.96309100	0.02809938	348.16055775
28.60000000	0.14431606	734.63097000	0.02829727	349.90758276
28.80000000	0.14532526	738.27912800	0.02849515	351.64521457
29.00000000	0.14633447	742.45972100	0.02869303	353.63644725
29.20000000	0.14734367	746.39381600	0.02889092	355.51027197
29.40000000	0.14835287	749.93351600	0.02908880	357.19624482
29.60000000	0.14936208	753.53237500	0.02928668	358.91039533
29.80000000	0.15037128	757.40731100	0.02948456	360.75604239
30.00000000	0.15138048	761.33154600	0.02968245	362.62517075
30.20000000	0.15238969	764.74306700	0.02988033	364.25009145
30.40000000	0.15339889	768.64758300	0.03007821	366.10982758
30.60000000	0.15440809	772.59153800	0.03027610	367.98834865
30.80000000	0.15541730	776.35801500	0.03047398	369.78233627
31.00000000	0.15642650	779.82869500	0.03067186	371.43543463
31.20000000	0.15743570	783.09231800	0.03086975	372.98991093
31.40000000	0.15844491	786.87851500	0.03106763	374.79329126
31.60000000	0.15945411	790.70415100	0.03126551	376.61545654
31.80000000	0.16046331	794.33259000	0.03146339	378.34369612
32.00000000	0.16147252	797.61593200	0.03166128	379.90756466
32.20000000	0.16248172	801.36269000	0.03185916	381.69216004
32.40000000	0.16349092	805.66160000	0.03205704	383.73974756
32.60000000	0.16450013	809.12242100	0.03225493	385.38815004
32.80000000	0.16550933	812.32688400	0.03245281	386.91444820
33.00000000	0.16651853	816.05392200	0.03265069	388.68965087
33.20000000	0.16752773	819.71194000	0.03284858	390.43197904
33.40000000	0.16853694	823.14318000	0.03304646	392.06629197
33.60000000	0.16954614	826.94909700	0.03324434	393.87906502
33.80000000	0.17055534	830.63669400	0.03344222	395.63548178
34.00000000	0.17156455	833.74255900	0.03364011	397.11481734
34.20000000	0.17257375	837.55833500	0.03383799	398.93228626
34.40000000	0.17358295	841.66004800	0.03403587	400.88594808
34.60000000	0.17459216	845.15044800	0.03423376	402.54843915
34.80000000	0.17560136	848.87748500	0.03443164	404.32364134
35.00000000	0.17661056	852.66368200	0.03462952	406.12702167
35.20000000	0.17761977	856.12450200	0.03482741	407.77542367
35.40000000	0.17862897	859.51630300	0.03502529	409.39095166
35.60000000	0.17963817	862.84894400	0.03522317	410.97830150
35.80000000	0.18064738	866.51682200	0.03542105	412.72532603
36.00000000	0.18165658	870.05652100	0.03561894	414.41129840
36.20000000	0.18266578	873.51734200	0.03581682	416.05970088
36.40000000	0.18367499	877.03732100	0.03601470	417.73628054
36.60000000	0.18468419	880.24178400	0.03621259	419.26257871
36.80000000	0.18569339	883.56456600	0.03641047	420.84523267
37.00000000	0.18670260	887.10426500	0.03660835	422.53120505
37.20000000	0.18771180	890.83130200	0.03680624	424.30640724
37.40000000	0.18872100	894.08506400	0.03700412	425.85618671
37.60000000	0.18973021	897.13176900	0.03720200	427.30734413
37.80000000	0.19073941	900.31651200	0.03739988	428.82424958
38.00000000	0.19174861	903.58013500	0.03759777	430.37872589
38.20000000	0.19275782	906.74515800	0.03779565	431.88623863
38.40000000	0.19376702	909.89046200	0.03799353	433.38435913
38.60000000	0.19477622	913.23296300	0.03819142	434.97640533
38.80000000	0.19578543	916.84168100	0.03838930	436.69525173
39.00000000	0.19679463	920.60815800	0.03858718	438.48923934
39.20000000	0.19780383	923.66472200	0.03878507	439.94509264
39.40000000	0.19881303	926.89876500	0.03898295	441.48547988
39.60000000	0.19982224	930.61594200	0.03918083	443.25598571
39.80000000	0.20083144	933.83026400	0.03937871	444.78697976
40.00000000	0.20184064	936.86710900	0.03957660	446.23344082
40.20000000	0.20284985	939.96311300	0.03977448	447.70807954
40.40000000	0.20385905	943.53239200	0.03997236	449.40814099
40.60000000	0.20486825	947.36788700	0.04017025	451.23500214
40.80000000	0.20587746	950.80898700	0.04036813	452.87401143
41.00000000	0.20688666	954.30924700	0.04056601	454.54119886
41.20000000	0.20789586	957.75034600	0.04076389	456.18020767
41.40000000	0.20890507	960.83649100	0.04096178	457.65015051
41.60000000	0.20991427	964.07053300	0.04115966	459.19053727
41.80000000	0.21092347	967.70883100	0.04135754	460.92347273
42.00000000	0.21193268	971.21895000	0.04155543	462.59535604
42.20000000	0.21294188	974.38397300	0.04175331	464.10286878
42.40000000	0.21395108	977.51941600	0.04195119	465.59629245
42.60000000	0.21496029	980.87177700	0.04214908	467.19303501
42.80000000	0.21596949	983.86918200	0.04234696	468.62071065
43.00000000	0.21697869	987.25112300	0.04254484	470.23154227
43.20000000	0.21798790	991.13591700	0.04274272	472.08188473
43.40000000	0.21899710	994.64603600	0.04294061	473.75376804
43.60000000	0.22000630	997.98853700	0.04313849	475.34581424
43.80000000	0.22101551	1001.27187900	0.04333637	476.90968278
44.00000000	0.22202471	1004.52564100	0.04353426	478.45946225
44.20000000	0.22303391	1007.96674100	0.04373214	480.09847154
44.40000000	0.22404312	1010.92470600	0.04393002	481.50736175
44.60000000	0.22505232	1013.92211100	0.04412791	482.93503739
44.80000000	0.22606152	1017.49138900	0.04432579	484.63509836
45.00000000	0.22707073	1020.83389000	0.04452367	486.22714456
45.20000000	0.22807993	1023.65381700	0.04472155	487.57028673
45.40000000	0.22908913	1026.13850800	0.04491944	488.75375470
45.60000000	0.23009833	1029.20493200	0.04511732	490.21430436
45.80000000	0.23110754	1033.13902600	0.04531520	492.08812860
46.00000000	0.23211674	1036.35334800	0.04551309	493.61912265
46.20000000	0.23312594	1038.50280300	0.04571097	494.64291641
46.40000000	0.23413515	1041.58894700	0.04590885	496.11285878
46.60000000	0.23514435	1045.31598300	0.04610674	497.88806049
46.80000000	0.23615355	1048.24436800	0.04630462	499.28286163
47.00000000	0.23716276	1051.17275400	0.04650250	500.67766325
47.20000000	0.23817196	1054.24903800	0.04670038	502.14290926
47.40000000	0.23918116	1057.14784400	0.04689827	503.52362181
47.60000000	0.24019037	1059.99735000	0.04709615	504.88085258
47.80000000	0.24119957	1062.33414300	0.04729403	505.99387616
48.00000000	0.24220877	1064.89771200	0.04749192	507.21491403
48.20000000	0.24321798	1067.25422500	0.04768980	508.33733032
48.40000000	0.24422718	1069.56143700	0.04788768	509.43626435
48.60000000	0.24523638	1072.55884200	0.04808557	510.86393999
48.80000000	0.24624559	1075.12241200	0.04828345	512.08497833
49.00000000	0.24725479	1077.52822400	0.04848133	513.23087592
49.20000000	0.24826399	1080.00305400	0.04867921	514.40964706
49.40000000	0.24927320	1082.21166800	0.04887710	515.46161848
49.60000000	0.25028240	1084.35126300	0.04907498	516.48071588
49.80000000	0.25129160	1086.39225900	0.04927286	517.45285020
50.00000000	0.25230081	1088.43325500	0.04947075	518.42498452
50.20000000	0.25331001	1090.66158800	0.04966863	519.48634818
50.40000000	0.25431921	1092.67300500	0.04986651	520.44439390
50.60000000	0.25532842	1094.48722300	0.05006440	521.30851298
50.80000000	0.25633762	1096.16340300	0.05026228	522.10688402
51.00000000	0.25734682	1097.82972400	0.05046016	522.90055918
51.20000000	0.25835603	1099.47632400	0.05065804	523.68484115
51.40000000	0.25936523	1100.75810900	0.05085593	524.29536032
51.60000000	0.26037443	1102.14835300	0.05105381	524.95753894
51.80000000	0.26138363	1103.56817600	0.05125169	525.63380614
52.00000000	0.26239284	1104.57388400	0.05144958	526.11282877
52.20000000	0.26340204	1105.75707000	0.05164746	526.67638485
52.40000000	0.26441124	1106.61488000	0.05184534	527.08496309
52.60000000	0.26542045	1107.36423100	0.05204323	527.44188188
52.80000000	0.26642965	1108.77419400	0.05224111	528.11345273
53.00000000	0.26743885	1110.02639900	0.05243899	528.70988283
53.20000000	0.26844806	1110.87434900	0.05263687	529.11376471
53.40000000	0.26945726	1111.95893700	0.05283476	529.63035818
53.60000000	0.27046646	1112.45193100	0.05303264	529.86517314
53.80000000	0.27147567	1112.75758700	0.05323052	530.01075828
54.00000000	0.27248487	1113.38862000	0.05342841	530.31132174
54.20000000	0.27349407	1113.72385600	0.05362629	530.47099595
54.40000000	0.27450328	1114.01965200	0.05382417	530.61188473
54.60000000	0.27551248	1114.54222600	0.05402205	530.86078876
54.80000000	0.27652168	1115.30143700	0.05421994	531.22240391
55.00000000	0.27753089	1115.41975600	0.05441782	531.27875970
55.20000000	0.27854009	1115.65639300	0.05461570	531.39147083
55.40000000	0.27954929	1116.24798600	0.05481359	531.67324887
55.60000000	0.28055850	1116.80013900	0.05501147	531.93624149
55.80000000	0.28156770	1116.80999900	0.05520935	531.94093784
56.00000000	0.28257690	1116.75084000	0.05540724	531.91276018
56.20000000	0.28358611	1116.98747700	0.05560512	532.02547130
56.40000000	0.28459531	1117.02691700	0.05580300	532.04425673
56.60000000	0.28560451	1117.30299300	0.05600088	532.17575280
56.80000000	0.28661372	1118.22982200	0.05619877	532.61720505
57.00000000	0.28762292	1118.90029400	0.05639665	532.93655347
57.20000000	0.28863212	1118.75239600	0.05659453	532.86610907
57.40000000	0.28964132	1119.07777200	0.05679242	533.02108693
57.60000000	0.29065053	1119.58062600	0.05699030	533.26059824
57.80000000	0.29165973	1119.50174700	0.05718818	533.22302786
58.00000000	0.29266893	1119.62992600	0.05738607	533.28408002
58.20000000	0.29367814	1119.78768400	0.05758395	533.35922077
58.40000000	0.29468734	1119.91586200	0.05778183	533.42027245
58.60000000	0.29569654	1120.17221900	0.05797971	533.54237628
58.80000000	0.29670575	1119.88628300	0.05817760	533.40618385
59.00000000	0.29771495	1119.69894500	0.05837548	533.31695404
59.20000000	0.29872415	1120.25109800	0.05857336	533.57994665
59.40000000	0.29973336	1120.47787600	0.05877125	533.68796190
59.60000000	0.30074256	1120.57647400	0.05896913	533.73492451
59.80000000	0.30175176	1120.87227100	0.05916701	533.87581377
60.00000000	0.30276097	1121.18778700	0.05936490	534.02609526
60.20000000	0.30377017	1121.25680600	0.05956278	534.05896928
60.40000000	0.30477937	1121.37512500	0.05976066	534.11532508
60.60000000	0.30578858	1121.70050100	0.05995854	534.27030293
60.80000000	0.30679778	1121.56246300	0.06015643	534.20455489
61.00000000	0.30780698	1121.47372400	0.06035431	534.16228816
61.20000000	0.30881619	1121.99629800	0.06055219	534.41119219
61.40000000	0.30982539	1122.09489600	0.06075008	534.45815480
61.60000000	0.31083459	1121.69064100	0.06094796	534.26560657
61.80000000	0.31184380	1121.44414400	0.06114584	534.14819910
62.00000000	0.31285300	1121.47372400	0.06134373	534.16228816
62.20000000	0.31386220	1121.88783900	0.06154161	534.35953275
62.40000000	0.31487141	1121.91741900	0.06173949	534.37362181
62.60000000	0.31588061	1122.12447600	0.06193737	534.47224387
62.80000000	0.31688981	1122.41041300	0.06213526	534.60843677
63.00000000	0.31789902	1122.68648900	0.06233314	534.73993284
63.20000000	0.31890822	1122.38083300	0.06253102	534.59434770
63.40000000	0.31991742	1122.12447600	0.06272891	534.47224387
63.60000000	0.32092662	1122.45971200	0.06292679	534.63191808
63.80000000	0.32193583	1122.69634900	0.06312467	534.74462920
64.00000000	0.32294503	1122.72592900	0.06332256	534.75871827
64.20000000	0.32395423	1122.77522800	0.06352044	534.78219957
64.40000000	0.32496344	1122.79494800	0.06371832	534.79159228
64.60000000	0.32597264	1122.98228600	0.06391620	534.88082210
64.80000000	0.32698184	1122.79494800	0.06411409	534.79159228
65.00000000	0.32799105	1122.61747000	0.06431197	534.70705882
65.20000000	0.32900025	1122.73578900	0.06450985	534.76341462
65.40000000	0.33000945	1122.47943200	0.06470774	534.64131079
65.60000000	0.33101866	1122.73578900	0.06490562	534.76341462
65.80000000	0.33202786	1122.75550900	0.06510350	534.77280734
66.00000000	0.33303706	1122.19349500	0.06530139	534.50511789
66.20000000	0.33404627	1122.11461600	0.06549927	534.46754751
66.40000000	0.33505547	1122.58789100	0.06569715	534.69297023
66.60000000	0.33606467	1122.32167400	0.06589503	534.56617004
66.80000000	0.33707388	1122.17377500	0.06609292	534.49572517
67.00000000	0.33808308	1122.53859100	0.06629080	534.66948845
67.20000000	0.33909228	1122.54845100	0.06648868	534.67418481
67.40000000	0.34010149	1122.69634900	0.06668657	534.74462920
67.60000000	0.34111069	1122.40055300	0.06688445	534.60374041
67.80000000	0.34211989	1122.20335500	0.06708233	534.50981424
68.00000000	0.34312910	1122.49915200	0.06728021	534.65070350
68.20000000	0.34413830	1122.39069300	0.06747810	534.59904406
68.40000000	0.34514750	1122.37097300	0.06767598	534.58965135
68.60000000	0.34615671	1122.06531700	0.06787386	534.44406621
68.80000000	0.34716591	1121.69064100	0.06807175	534.26560657
69.00000000	0.34817511	1121.81882000	0.06826963	534.32665873
69.20000000	0.34918432	1121.93713800	0.06846751	534.38301405
69.40000000	0.35019352	1121.97657800	0.06866540	534.40179948
69.60000000	0.35120272	1121.89769900	0.06886328	534.36422910
69.80000000	0.35221192	1122.00615700	0.06906116	534.41588807
70.00000000	0.35322113	1122.07517700	0.06925904	534.44876256
70.20000000	0.35423033	1121.74980100	0.06945693	534.29378471
70.40000000	0.35523953	1121.82868000	0.06965481	534.33135508
70.60000000	0.35624874	1121.96671800	0.06985269	534.39710312
70.80000000	0.35725794	1122.03573700	0.07005058	534.42997714
71.00000000	0.35826714	1122.35125300	0.07024846	534.58025863
71.20000000	0.35927635	1122.14419600	0.07044634	534.48163658
71.40000000	0.36028555	1122.20335500	0.07064423	534.50981424
71.60000000	0.36129475	1122.19349500	0.07084211	534.50511789
71.80000000	0.36230396	1121.44414400	0.07103999	534.14819910
72.00000000	0.36331316	1121.68078100	0.07123787	534.26091022
72.20000000	0.36432236	1121.81882000	0.07143576	534.32665873
72.40000000	0.36533157	1121.18778700	0.07163364	534.02609526
72.60000000	0.36634077	1121.17792700	0.07183152	534.02139890
72.80000000	0.36734997	1121.50330300	0.07202941	534.17637676
73.00000000	0.36835918	1121.14834800	0.07222729	534.00731031
73.20000000	0.36936838	1120.51731500	0.07242517	533.70674684
73.40000000	0.37037758	1120.18207900	0.07262306	533.54707264
73.60000000	0.37138679	1120.41871600	0.07282094	533.65978376
73.80000000	0.37239599	1120.89199100	0.07301882	533.88520648
74.00000000	0.37340519	1120.64549400	0.07321670	533.76779900
74.20000000	0.37441440	1120.26095800	0.07341459	533.58464301
74.40000000	0.37542360	1120.47787600	0.07361247	533.68796190
74.60000000	0.37643280	1120.59619400	0.07381035	533.74431722
74.80000000	0.37744201	1120.34969700	0.07400824	533.62690974
75.00000000	0.37845121	1120.21165900	0.07420612	533.56116171
75.20000000	0.37946041	1119.94544200	0.07440400	533.43436151
75.40000000	0.38046961	1119.74824400	0.07460189	533.34043534
75.60000000	0.38147882	1119.58062600	0.07479977	533.26059824
75.80000000	0.38248802	1119.36370900	0.07499765	533.15727983
76.00000000	0.38349722	1119.30455000	0.07519553	533.12910217
76.20000000	0.38450643	1119.35384900	0.07539342	533.15258347
76.40000000	0.38551563	1119.42286800	0.07559130	533.18545749
76.60000000	0.38652483	1119.18623100	0.07578918	533.07274637
76.80000000	0.38753404	1119.03833300	0.07598707	533.00230198
77.00000000	0.38854324	1118.90029400	0.07618495	532.93655347
77.20000000	0.38955244	1118.56505800	0.07638283	532.77687926
77.40000000	0.39056165	1118.06220400	0.07658072	532.53736794
77.60000000	0.39157085	1117.47061100	0.07677860	532.25558990
77.80000000	0.39258005	1117.15509500	0.07697648	532.10530841
78.00000000	0.39358926	1117.23397400	0.07717436	532.14287878
78.20000000	0.39459846	1117.34243300	0.07737225	532.19453822
78.40000000	0.39560766	1117.02691700	0.07757013	532.04425673
78.60000000	0.39661687	1116.84943900	0.07776801	531.95972327
78.80000000	0.39762607	1116.79027900	0.07796590	531.93154513
79.00000000	0.39863527	1116.48462300	0.07816378	531.78595999
79.20000000	0.39964448	1116.33672500	0.07836166	531.71551560
79.40000000	0.40065368	1116.04092800	0.07855954	531.57462634
79.60000000	0.40166288	1115.63667300	0.07875743	531.38207811
79.80000000	0.40267209	1115.05494000	0.07895531	531.10499643
80.00000000	0.40368129	1114.88732200	0.07915319	531.02515932
80.20000000	0.40469049	1115.04508000	0.07935108	531.10030007
80.40000000	0.40569970	1114.63096500	0.07954896	530.90305549
80.60000000	0.40670890	1114.17741000	0.07974684	530.68702548
80.80000000	0.40771810	1114.01965200	0.07994473	530.61188473
81.00000000	0.40872731	1114.25628900	0.08014261	530.72459586
81.20000000	0.40973651	1114.16755000	0.08034049	530.68232913
81.40000000	0.41074571	1114.11825100	0.08053837	530.65884782
81.60000000	0.41175491	1114.21685000	0.08073626	530.70581091
81.80000000	0.41276412	1114.16755000	0.08093414	530.68232913
82.00000000	0.41377332	1114.03937200	0.08113202	530.62127745
82.20000000	0.41478252	1113.89147400	0.08132991	530.55083306
82.40000000	0.41579173	1113.54637800	0.08152779	530.38646249
82.60000000	0.41680093	1113.14212300	0.08172567	530.19391427
82.80000000	0.41781013	1113.06324300	0.08192356	530.15634342
83.00000000	0.41881934	1113.05338400	0.08212144	530.15164754
83.20000000	0.41982854	1113.05338400	0.08231932	530.15164754
83.40000000	0.42083774	1112.88576600	0.08251720	530.07181043
83.60000000	0.42184695	1112.08711500	0.08271509	529.69140986
83.80000000	0.42285615	1111.36734400	0.08291297	529.34858014
84.00000000	0.42386535	1111.42650300	0.08311085	529.37675780
84.20000000	0.42487456	1111.56454100	0.08330874	529.44250583
84.40000000	0.42588376	1111.73215900	0.08350662	529.52234294
84.60000000	0.42689296	1111.44622300	0.08370450	529.38615051
84.80000000	0.42790217	1111.13070600	0.08390239	529.23586854
85.00000000	0.42891137	1111.49552200	0.08410027	529.40963182
85.20000000	0.42992057	1111.39692300	0.08429815	529.36266873
85.40000000	0.43092978	1111.04196700	0.08449603	529.19360181
85.60000000	0.43193898	1110.85463000	0.08469392	529.10437247
85.80000000	0.43294818	1110.79547000	0.08489180	529.07619433
86.00000000	0.43395739	1110.81519000	0.08508968	529.08558704
86.20000000	0.43496659	1110.44051500	0.08528757	528.90712789
86.40000000	0.43597579	1110.38135500	0.08548545	528.87894975
86.60000000	0.43698500	1110.15457800	0.08568333	528.77093498
86.80000000	0.43799420	1109.87850100	0.08588122	528.63943844
87.00000000	0.43900340	1109.36578700	0.08607910	528.39523077
87.20000000	0.44001261	1108.57699700	0.08627698	528.01952703
87.40000000	0.44102181	1108.73475500	0.08647486	528.09466778
87.60000000	0.44203101	1108.89251300	0.08667275	528.16980853
87.80000000	0.44304021	1108.28120000	0.08687063	527.87863777
88.00000000	0.44404942	1107.89666500	0.08706851	527.69548226
88.20000000	0.44505862	1107.93610400	0.08726640	527.71426721
88.40000000	0.44606782	1107.52198900	0.08746428	527.51702262
88.60000000	0.44707703	1107.28535200	0.08766216	527.40431150
88.80000000	0.44808623	1107.26563200	0.08786005	527.39491879
89.00000000	0.44909543	1107.09801400	0.08805793	527.31508169
89.20000000	0.45010464	1106.47684100	0.08825581	527.01921457
89.40000000	0.45111384	1106.07258600	0.08845369	526.82666635
89.60000000	0.45212304	1105.86552900	0.08865158	526.72804430
89.80000000	0.45313225	1105.42183400	0.08884946	526.51671065
90.00000000	0.45414145	1105.48099300	0.08904734	526.54488831
90.20000000	0.45515065	1105.59931200	0.08924523	526.60124411
90.40000000	0.45615986	1104.78094200	0.08944311	526.21145130
90.60000000	0.45716906	1104.23864800	0.08964099	525.95315456
90.80000000	0.45817826	1104.11046900	0.08983888	525.89210241
91.00000000	0.45918747	1103.67663500	0.09003676	525.68546559
91.20000000	0.46019667	1103.16392100	0.09023464	525.44125792
91.40000000	0.46120587	1102.27653100	0.09043252	525.01859062
91.60000000	0.46221508	1101.65535900	0.09063041	524.72272398
91.80000000	0.46322428	1101.22152400	0.09082829	524.51608669
92.00000000	0.46423348	1100.85670800	0.09102617	524.34232341
92.20000000	0.46524269	1100.16651600	0.09122406	524.01358228
92.40000000	0.46625189	1099.06220900	0.09142194	523.48759657
92.60000000	0.46726109	1098.49033600	0.09161982	523.21521124
92.80000000	0.46827030	1097.78042400	0.09181770	522.87707740
93.00000000	0.46927950	1095.96620600	0.09201559	522.01295832
93.20000000	0.47028870	1094.40834400	0.09221347	521.27094261
93.40000000	0.47129791	1092.77160400	0.09241135	520.49135699
93.60000000	0.47230711	1090.75032700	0.09260924	519.52861491
93.80000000	0.47331631	1088.00928000	0.09280712	518.22304358
94.00000000	0.47432551	1083.42443400	0.09300500	516.03926363
94.20000000	0.47533472	1077.16340800	0.09320289	513.05711265
94.40000000	0.47634392	1069.02900400	0.09340077	509.18266444
94.60000000	0.47735312	1056.74358800	0.09359865	503.33107311
94.70000000	0.47785773	1046.69636600	0.09369759	498.54554227