File: data/output/vidExt_M-35Zr39Ti25Nb_Glb_11_0pt1/vidExt_M-35Zr39Ti25Nb_Glb_11_0pt1_normCorrelated.txt
Total length (mm) = 50
Gage length (mm) = 5.1
Width (mm) = 2.21
Thickness (mm) = 0.95
----------
Time (s)	Displacement (mm)	Force (N)	Eng. strain	Eng. stress (MPa)
0.00000000	0.00000000	58.56777700	0.00000000	27.89605954
0.20000000	0.00080847	61.83140200	0.00015852	29.45053679
0.40000000	0.00161695	65.30208500	0.00031705	31.10363658
0.60000000	0.00242542	69.42352100	0.00047557	33.06669255
0.80000000	0.00323390	72.96322300	0.00063410	34.75266635
1.00000000	0.00404237	76.62124400	0.00079262	36.49499595
1.20000000	0.00485085	80.78211900	0.00095115	38.47683687
1.40000000	0.00565932	85.23879200	0.00110967	40.59956752
1.60000000	0.00646780	89.40952700	0.00126820	42.58610479
1.80000000	0.00727627	93.19572700	0.00142672	44.38948654
2.00000000	0.00808475	97.32702300	0.00158524	46.35723887
2.20000000	0.00889322	101.48789800	0.00174377	48.33907978
2.40000000	0.00970170	105.40227600	0.00190229	50.20351322
2.60000000	0.01051017	109.48427200	0.00206082	52.14778376
2.80000000	0.01131865	114.07898300	0.00221934	54.33626244
3.00000000	0.01212712	118.12154000	0.00237787	56.26174804
3.20000000	0.01293560	121.95703900	0.00253639	58.08861110
3.40000000	0.01374407	126.51231000	0.00269492	60.25830436
3.60000000	0.01455255	131.01828200	0.00285344	62.40451631
3.80000000	0.01536102	135.43551400	0.00301197	64.50846106
4.00000000	0.01616950	139.52737000	0.00317049	66.45742796
4.20000000	0.01697797	143.60936700	0.00332901	68.40169898
4.40000000	0.01778645	147.82940100	0.00348754	70.41171755
4.60000000	0.01859492	152.35509300	0.00364606	72.56732222
4.80000000	0.01940340	156.75260500	0.00380459	74.66187426
5.00000000	0.02021187	160.99236000	0.00396311	76.68128602
5.20000000	0.02102035	165.33071300	0.00412164	78.74766040
5.40000000	0.02182882	169.08733300	0.00428016	80.53695308
5.60000000	0.02263730	173.54400500	0.00443869	82.65968326
5.80000000	0.02344577	178.14857500	0.00459721	84.85285782
6.00000000	0.02425425	182.18127200	0.00475573	86.77364706
6.20000000	0.02506272	186.68724300	0.00491426	88.91985854
6.40000000	0.02587120	191.75522900	0.00507278	91.33375994
6.60000000	0.02667967	196.15274100	0.00523131	93.42831198
6.80000000	0.02748815	200.08683900	0.00538983	95.30213813
7.00000000	0.02829662	204.12939500	0.00554836	97.22762324
7.20000000	0.02910510	208.67480600	0.00570688	99.39262015
7.40000000	0.02991357	213.38783500	0.00586541	101.63745416
7.60000000	0.03072204	217.62758900	0.00602393	103.65686544
7.80000000	0.03153052	222.13356100	0.00618245	105.80307740
8.00000000	0.03233899	226.50149300	0.00634098	107.88354037
8.20000000	0.03314747	230.83984700	0.00649950	109.94991522
8.40000000	0.03395594	235.51343600	0.00665803	112.17596380
8.60000000	0.03476442	239.73347000	0.00681655	114.18598238
8.80000000	0.03557289	244.07182300	0.00697508	116.25235675
9.00000000	0.03638137	248.58765400	0.00713360	118.40326459
9.20000000	0.03718984	252.78796900	0.00729213	120.40389093
9.40000000	0.03799832	257.40239900	0.00745065	122.60176185
9.60000000	0.03880679	261.88865000	0.00760918	124.73858061
9.80000000	0.03961527	265.73400900	0.00776770	126.57014003
10.00000000	0.04042374	270.05264200	0.00792622	128.62712170
10.20000000	0.04123222	274.47973400	0.00808475	130.73576280
10.40000000	0.04204069	278.66032800	0.00824327	132.72699595
10.60000000	0.04284917	283.29447800	0.00840180	134.93425959
10.80000000	0.04365764	287.55395200	0.00856032	136.96306359
11.00000000	0.04446612	291.61622700	0.00871885	138.89794094
11.20000000	0.04527459	295.97430000	0.00887737	140.97370803
11.40000000	0.04608307	300.41125200	0.00903590	143.08704549
11.60000000	0.04689154	304.57212700	0.00919442	145.06888640
11.80000000	0.04770002	309.09781700	0.00935294	147.22449012
12.00000000	0.04850849	313.76154600	0.00951147	149.44584234
12.20000000	0.04931697	318.09989900	0.00966999	151.51221672
12.40000000	0.05012544	322.71432900	0.00982852	153.71008764
12.60000000	0.05093392	327.22030000	0.00998704	155.85629912
12.80000000	0.05174239	331.49949300	0.01014557	157.89449536
13.00000000	0.05255087	335.58148900	0.01030409	159.83876590
13.20000000	0.05335934	339.79166300	0.01046262	161.84408812
13.40000000	0.05416782	344.08071600	0.01062114	163.88698071
13.60000000	0.05497629	348.35004900	0.01077966	165.92048059
13.80000000	0.05578477	353.01377800	0.01093819	168.14183282
14.00000000	0.05659324	357.17465300	0.01109671	170.12367373
14.20000000	0.05740172	361.01015100	0.01125524	171.95053632
14.40000000	0.05821019	365.67388000	0.01141376	174.17188854
14.60000000	0.05901867	369.83475400	0.01157229	176.15372898
14.80000000	0.05982714	373.54207400	0.01173081	177.91953989
15.00000000	0.06063561	378.38328100	0.01188934	180.22542558
15.20000000	0.06144409	383.45126500	0.01204786	182.63932603
15.40000000	0.06225256	387.57270000	0.01220639	184.60238152
15.60000000	0.06306104	391.64483500	0.01236491	186.54195523
15.80000000	0.06386951	396.46632200	0.01252343	188.83844820
16.00000000	0.06467799	400.85397400	0.01268196	190.92830388
16.20000000	0.06548646	404.83737000	0.01284048	192.82561086
16.40000000	0.06629494	409.45180000	0.01299901	195.02348178
16.60000000	0.06710341	413.83945100	0.01315753	197.11333698
16.80000000	0.06791189	417.67494900	0.01331606	198.94019957
17.00000000	0.06872036	421.87526300	0.01347458	200.94082543
17.20000000	0.06952884	426.43053300	0.01363311	203.11051822
17.40000000	0.07033731	430.31533000	0.01379163	204.96086211
17.60000000	0.07114579	434.46634400	0.01395015	206.93800619
17.80000000	0.07195426	439.20895200	0.01410868	209.19692879
18.00000000	0.07276274	443.36982600	0.01426720	211.17876923
18.20000000	0.07357121	447.58986000	0.01442573	213.18878781
18.40000000	0.07437969	451.39577800	0.01458425	215.00156132
18.60000000	0.07518816	455.31015500	0.01474278	216.86599428
18.80000000	0.07599664	460.17108100	0.01490130	219.18127221
19.00000000	0.07680511	464.43055400	0.01505983	221.21007573
19.20000000	0.07761359	468.18717300	0.01521835	222.99936794
19.40000000	0.07842206	472.35790600	0.01537687	224.98590426
19.60000000	0.07923054	476.75541800	0.01553540	227.08045630
19.80000000	0.08003901	481.01489100	0.01569392	229.10925982
20.00000000	0.08084749	485.09688600	0.01585245	231.05352989
20.20000000	0.08165596	489.44509700	0.01601097	233.12459967
20.40000000	0.08246444	493.55667200	0.01616950	235.08295880
20.60000000	0.08327291	497.54006800	0.01632802	236.98026578
20.80000000	0.08408139	501.85870000	0.01648655	239.03724696
21.00000000	0.08488986	505.91111500	0.01664507	240.96742796
21.20000000	0.08569834	510.11142800	0.01680360	242.96805335
21.40000000	0.08650681	514.14412400	0.01696212	244.88884211
21.60000000	0.08731529	518.21625800	0.01712064	246.82841534
21.80000000	0.08812376	522.62363000	0.01727917	248.92766373
22.00000000	0.08893224	526.50842600	0.01743769	250.77800714
22.20000000	0.08974071	530.47210200	0.01759622	252.66592141
22.40000000	0.09054918	534.77101500	0.01775474	254.71351036
22.60000000	0.09135766	538.94174800	0.01791327	256.70004668
22.80000000	0.09216613	542.72794600	0.01807179	258.50342748
23.00000000	0.09297461	546.57330300	0.01823032	260.33498595
23.20000000	0.09378308	551.08913300	0.01838884	262.48589331
23.40000000	0.09459156	555.21056700	0.01854736	264.44894832
23.60000000	0.09540003	558.76012700	0.01870589	266.13961753
23.80000000	0.09620851	562.66464400	0.01886441	267.99935413
24.00000000	0.09701698	566.82551800	0.01902294	269.98119457
24.20000000	0.09782546	570.73989400	0.01918146	271.84562705
24.40000000	0.09863393	574.79230900	0.01933999	273.77580805
24.60000000	0.09944241	579.08136100	0.01949851	275.81870017
24.80000000	0.10025088	583.62677000	0.01965704	277.98369612
25.00000000	0.10105936	587.40310800	0.01981556	279.78238057
25.20000000	0.10186783	591.18930500	0.01997408	281.58576090
25.40000000	0.10267631	595.62625600	0.02013261	283.69909788
25.60000000	0.10348478	599.77726900	0.02029113	285.67624149
25.80000000	0.10429326	603.62262600	0.02044966	287.50779995
26.00000000	0.10510173	607.74406000	0.02060818	289.47085497
26.20000000	0.10591021	612.02325200	0.02076671	291.50905073
26.40000000	0.10671868	615.61225200	0.02092523	293.21850536
26.60000000	0.10752716	619.51676800	0.02108376	295.07824149
26.80000000	0.10833563	623.70722100	0.02124228	297.07417052
27.00000000	0.10914411	627.77935600	0.02140081	299.01374422
27.20000000	0.10995258	631.66415200	0.02155933	300.86408764
27.40000000	0.11076106	635.62782700	0.02171785	302.75200143
27.60000000	0.11156953	639.95631900	0.02187638	304.81367897
27.80000000	0.11237801	643.86083500	0.02203490	306.67341510
28.00000000	0.11318648	647.75549100	0.02219343	308.52845487
28.20000000	0.11399496	651.76846600	0.02235195	310.43985044
28.40000000	0.11480343	655.49550400	0.02251048	312.21505311
28.60000000	0.11561191	659.80427500	0.02266900	314.26733746
28.80000000	0.11642038	663.65949200	0.02282753	316.10359228
29.00000000	0.11722886	667.50484900	0.02298605	317.93515075
29.20000000	0.11803733	671.70516100	0.02314457	319.93577566
29.40000000	0.11884581	675.69841600	0.02330310	321.83777852
29.60000000	0.11965428	679.46489400	0.02346162	323.63176661
29.80000000	0.12046276	683.23137100	0.02362015	325.42575423
30.00000000	0.12127123	687.22462600	0.02377867	327.32775709
30.20000000	0.12207970	691.07984300	0.02393720	329.16401191
30.40000000	0.12288818	694.95477900	0.02409572	331.00965897
30.60000000	0.12369665	698.34658100	0.02425425	332.62518743
30.80000000	0.12450513	702.15249800	0.02441277	334.43796047
31.00000000	0.12531360	706.28379100	0.02457129	336.40571136
31.20000000	0.12612208	710.03054800	0.02472982	338.19030626
31.40000000	0.12693055	713.82660500	0.02488834	339.99838295
31.60000000	0.12773903	717.90859900	0.02504687	341.94265254
31.80000000	0.12854750	721.37928000	0.02520539	343.59575137
32.00000000	0.12935598	724.87954000	0.02536392	345.26293879
32.20000000	0.13016445	729.03055300	0.02552244	347.24008240
32.40000000	0.13097293	732.96464900	0.02568097	349.11390760
32.60000000	0.13178140	736.59308700	0.02583949	350.84214670
32.80000000	0.13258988	740.27082600	0.02599802	352.59386806
33.00000000	0.13339835	744.37253900	0.02615654	354.54752989
33.20000000	0.13420683	748.27705500	0.02631506	356.40726602
33.40000000	0.13501530	751.60969700	0.02647359	357.99461634
33.60000000	0.13582378	755.33673400	0.02663211	359.76981853
33.80000000	0.13663225	759.43844800	0.02679064	361.72348083
34.00000000	0.13744073	762.98800700	0.02694916	363.41414956
34.20000000	0.13824920	766.67560500	0.02710769	365.17056680
34.40000000	0.13905768	770.76745900	0.02726621	367.11953275
34.60000000	0.13986615	774.62267500	0.02742474	368.95578709
34.80000000	0.14067463	778.14265500	0.02758326	370.63236723
35.00000000	0.14148310	781.47529700	0.02774178	372.21971755
35.20000000	0.14229158	784.83751800	0.02790031	373.82115647
35.40000000	0.14310005	788.91951200	0.02805883	375.76542605
35.60000000	0.14390853	792.64654900	0.02821736	377.54062824
35.80000000	0.14471700	795.77213400	0.02837588	379.02935651
36.00000000	0.14552548	799.32169300	0.02853441	380.72002524
36.20000000	0.14633395	803.47270500	0.02869293	382.69716837
36.40000000	0.14714243	807.49553900	0.02885146	384.61325982
36.60000000	0.14795090	810.67042300	0.02900998	386.12546940
36.80000000	0.14875938	814.18054300	0.02916850	387.79735318
37.00000000	0.14956785	817.86814100	0.02932703	389.55377042
37.20000000	0.15037633	821.25008200	0.02948555	391.16460205
37.40000000	0.15118480	825.14473700	0.02964408	393.01964134
37.60000000	0.15199327	828.96051400	0.02980260	394.83711074
37.80000000	0.15280175	832.15511700	0.02996113	396.35871255
38.00000000	0.15361022	835.66523700	0.03011965	398.03059633
38.20000000	0.15441870	839.71765000	0.03027818	399.96077638
38.40000000	0.15522717	843.36580800	0.03043670	401.69840819
38.60000000	0.15603565	846.98438700	0.03059523	403.42195142
38.80000000	0.15684412	850.72128400	0.03075375	405.20184996
39.00000000	0.15765260	854.37930200	0.03091227	406.94417814
39.20000000	0.15846107	857.93872100	0.03107080	408.63954322
39.40000000	0.15926955	861.20234300	0.03122932	410.19401905
39.60000000	0.16007802	864.58428400	0.03138785	411.80485068
39.80000000	0.16088650	868.20286300	0.03154637	413.52839390
40.00000000	0.16169497	871.78200200	0.03170490	415.23315170
40.20000000	0.16250345	875.32170100	0.03186342	416.91912408
40.40000000	0.16331192	878.71350200	0.03202195	418.53465206
40.60000000	0.16412040	881.93768500	0.03218047	420.07034294
40.80000000	0.16492887	885.45766400	0.03233899	421.74692260
41.00000000	0.16573735	888.94806400	0.03249752	423.40941367
41.20000000	0.16654582	892.40888400	0.03265604	425.05781567
41.40000000	0.16735430	895.67250600	0.03281457	426.61229150
41.60000000	0.16816277	898.63047200	0.03297309	428.02118219
41.80000000	0.16897125	901.94339400	0.03313162	429.59913980
42.00000000	0.16977972	905.15771600	0.03329014	431.13013384
42.20000000	0.17058820	908.26358000	0.03344867	432.60946892
42.40000000	0.17139667	911.59622200	0.03360719	434.19681924
42.60000000	0.17220515	914.94858300	0.03376571	435.79356180
42.80000000	0.17301362	918.62632100	0.03392424	437.54528269
43.00000000	0.17382210	922.04770100	0.03408276	439.17489926
43.20000000	0.17463057	925.40006200	0.03424129	440.77164182
43.40000000	0.17543905	928.96934100	0.03439981	442.47170326
43.60000000	0.17624752	932.10478400	0.03455834	443.96512693
43.80000000	0.17705600	935.32896700	0.03471686	445.50081781
44.00000000	0.17786447	938.59258900	0.03487539	447.05529364
44.20000000	0.17867295	941.64915400	0.03503391	448.51114742
44.40000000	0.17948142	945.23815200	0.03519244	450.22060110
44.60000000	0.18028990	949.11308700	0.03535096	452.06624768
44.80000000	0.18109837	952.62320600	0.03550948	453.73813098
45.00000000	0.18190684	956.15304500	0.03566801	455.41940700
45.20000000	0.18271532	959.38708700	0.03582653	456.95979376
45.40000000	0.18352379	962.44365200	0.03598506	458.41564754
45.60000000	0.18433227	965.64811500	0.03614358	459.94194570
45.80000000	0.18514074	969.59206900	0.03630211	461.82046630
46.00000000	0.18594922	972.93457000	0.03646063	463.41251250
46.20000000	0.18675769	975.71505700	0.03661916	464.73686925
46.40000000	0.18756617	979.27447600	0.03677768	466.43223434
46.60000000	0.18837464	982.42963900	0.03693620	467.93505073
46.80000000	0.18918312	985.57494200	0.03709473	469.43317075
47.00000000	0.18999159	989.35127800	0.03725325	471.23185425
47.20000000	0.19080007	992.76279800	0.03741178	472.85677447
47.40000000	0.19160854	996.17431900	0.03757030	474.48169517
47.60000000	0.19241702	999.84219600	0.03772883	476.22871922
47.80000000	0.19322549	1002.91848000	0.03788735	477.69396523
48.00000000	0.19403397	1006.20182100	0.03804588	479.25783329
48.20000000	0.19484244	1009.42600400	0.03820440	480.79352417
48.40000000	0.19565092	1012.40368900	0.03836293	482.21180710
48.60000000	0.19645939	1015.73633000	0.03852145	483.79915694
48.80000000	0.19726787	1019.16757000	0.03867997	485.43346987
49.00000000	0.19807634	1022.25371300	0.03883850	486.90341176
49.20000000	0.19888482	1024.82714300	0.03899702	488.12914646
49.40000000	0.19969329	1027.57805100	0.03915555	489.43941462
49.60000000	0.20050177	1031.21634800	0.03931407	491.17234961
49.80000000	0.20131024	1034.73632700	0.03947260	492.84892927
50.00000000	0.20211872	1037.21115800	0.03963112	494.02770088
50.20000000	0.20292719	1040.13954400	0.03978965	495.42250250
50.40000000	0.20373567	1043.60036300	0.03994817	497.07090402
50.60000000	0.20454414	1046.85412500	0.04010669	498.62068350
50.80000000	0.20535262	1049.82195000	0.04026522	500.03427006
51.00000000	0.20616109	1052.74047500	0.04042374	501.42437485
51.20000000	0.20696957	1055.63928100	0.04058227	502.80508740
51.40000000	0.20777804	1058.60710600	0.04074079	504.21867397
51.60000000	0.20858652	1061.24955500	0.04089932	505.47728269
51.80000000	0.20939499	1063.46802900	0.04105784	506.53395046
52.00000000	0.21020347	1065.88370100	0.04121637	507.68454442
52.20000000	0.21101194	1068.49657000	0.04137489	508.92906406
52.40000000	0.21182041	1071.17845800	0.04153341	510.20645773
52.60000000	0.21262889	1073.82090700	0.04169194	511.46506644
52.80000000	0.21343736	1076.38447700	0.04185046	512.68610479
53.00000000	0.21424584	1078.62267100	0.04200899	513.75216528
53.20000000	0.21465008	1080.98904300	0.04208825	514.87927745
53.40000000	0.21586457	1083.39485400	0.04232639	516.02517457
53.60000000	0.21707905	1085.55416900	0.04256452	517.05366468
53.80000000	0.21829354	1087.43740700	0.04280266	517.95065825
54.00000000	0.21950803	1089.57700100	0.04304079	518.96975518
54.20000000	0.22072252	1091.63771700	0.04327893	519.95128221
54.40000000	0.22193701	1093.59983400	0.04351706	520.88584615
54.60000000	0.22315150	1095.24643400	0.04375520	521.67012813
54.80000000	0.22436598	1096.90289500	0.04399333	522.45910693
55.00000000	0.22558047	1098.68753400	0.04423147	523.30913741
55.20000000	0.22679496	1100.19609600	0.04446960	524.02767135
55.40000000	0.22800945	1101.57647900	0.04470773	524.68515313
55.60000000	0.22922394	1102.78924500	0.04494587	525.26279829
55.80000000	0.23043842	1103.97243100	0.04518400	525.82635437
56.00000000	0.23165291	1105.11617800	0.04542214	526.37112551
56.20000000	0.23286740	1106.37824300	0.04566027	526.97225196
56.40000000	0.23408189	1107.07829400	0.04589841	527.30568897
56.60000000	0.23529638	1107.88680500	0.04613654	527.69078590
56.80000000	0.23651087	1109.46438600	0.04637468	528.44219386
57.00000000	0.23772535	1110.61799200	0.04661281	528.99166087
57.20000000	0.23893984	1111.30818400	0.04685095	529.32040200
57.40000000	0.24015433	1112.05753500	0.04708908	529.67732079
57.60000000	0.24136882	1112.68856800	0.04732722	529.97788426
57.80000000	0.24258331	1113.11254300	0.04756535	530.17982520
58.00000000	0.24379780	1113.64497700	0.04780349	530.43342558
58.20000000	0.24501228	1113.93091300	0.04804162	530.56961800
58.40000000	0.24622677	1114.00979200	0.04827976	530.60718838
58.60000000	0.24744126	1115.00564000	0.04851789	531.08151465
58.80000000	0.24865575	1115.43947500	0.04875603	531.28815194
59.00000000	0.24987024	1115.40989600	0.04899416	531.27406335
59.20000000	0.25108473	1116.14938700	0.04923230	531.62628578
59.40000000	0.25229921	1116.62266100	0.04947043	531.85170803
59.60000000	0.25351370	1116.72126000	0.04970857	531.89867111
59.80000000	0.25472819	1116.72126000	0.04994670	531.89867111
60.00000000	0.25594268	1116.92831800	0.05018484	531.99729364
60.20000000	0.25715717	1117.09593600	0.05042297	532.07713075
60.40000000	0.25837166	1117.03677600	0.05066111	532.04895261
60.60000000	0.25958614	1117.74668800	0.05089924	532.38708645
60.80000000	0.26080063	1118.62421800	0.05113738	532.80505739
61.00000000	0.26201512	1118.76225600	0.05137551	532.87080543
61.20000000	0.26322961	1119.02847300	0.05161365	532.99760562
61.40000000	0.26444410	1119.40314800	0.05185178	533.17606478
61.60000000	0.26565859	1119.38342900	0.05208992	533.16667254
61.80000000	0.26687307	1119.50174700	0.05232805	533.22302786
62.00000000	0.26808756	1119.95530200	0.05256619	533.43905787
62.20000000	0.26930205	1119.79754400	0.05280432	533.36391712
62.40000000	0.27051654	1119.79754400	0.05304246	533.36391712
62.60000000	0.27173103	1119.97502200	0.05328059	533.44845058
62.80000000	0.27294552	1119.87642300	0.05351873	533.40148750
63.00000000	0.27416000	1120.23137900	0.05375686	533.57055442
63.20000000	0.27537449	1120.28067800	0.05399500	533.59403572
63.40000000	0.27658898	1120.45815600	0.05423313	533.67856918
63.60000000	0.27780347	1120.72437300	0.05447127	533.80536937
63.80000000	0.27901796	1120.91171000	0.05470940	533.89459871
64.00000000	0.28023245	1121.33568500	0.05494754	534.09653965
64.20000000	0.28144693	1121.49344400	0.05518567	534.17168088
64.40000000	0.28266142	1121.51316300	0.05542381	534.18107311
64.60000000	0.28387591	1121.43428400	0.05566194	534.14350274
64.80000000	0.28509040	1121.49344400	0.05590008	534.17168088
65.00000000	0.28630489	1121.87797900	0.05613821	534.35483639
65.20000000	0.28751938	1122.04559700	0.05637635	534.43467349
65.40000000	0.28873386	1121.86811900	0.05661448	534.35014003
65.60000000	0.28994835	1121.45400400	0.05685262	534.15289545
65.80000000	0.29116284	1121.54274300	0.05709075	534.19516218
66.00000000	0.29237733	1122.01601700	0.05732889	534.42058442
66.20000000	0.29359182	1121.79910000	0.05756702	534.31726602
66.40000000	0.29480630	1121.77938000	0.05780516	534.30787330
66.60000000	0.29602079	1122.32167400	0.05804329	534.56617004
66.80000000	0.29723528	1122.53859100	0.05828143	534.66948845
67.00000000	0.29844977	1122.38083300	0.05851956	534.59434770
67.20000000	0.29966426	1122.14419600	0.05875770	534.48163658
67.40000000	0.30087875	1122.35125300	0.05899583	534.58025863
67.60000000	0.30209323	1122.67663000	0.05923397	534.73523696
67.80000000	0.30330772	1122.61747000	0.05947210	534.70705882
68.00000000	0.30452221	1122.81466800	0.05971024	534.80098500
68.20000000	0.30573670	1122.92312700	0.05994837	534.85264444
68.40000000	0.30695119	1122.93298600	0.06018651	534.85734032
68.60000000	0.30816568	1122.92312700	0.06042464	534.85264444
68.80000000	0.30938016	1122.82452800	0.06066278	534.80568135
69.00000000	0.31059465	1122.50901200	0.06090091	534.65539986
69.20000000	0.31180914	1122.57803100	0.06113905	534.68827387
69.40000000	0.31302363	1122.70620900	0.06137718	534.74932555
69.60000000	0.31423812	1122.64705000	0.06161532	534.72114789
69.80000000	0.31545261	1122.52873100	0.06185345	534.66479209
70.00000000	0.31666709	1122.13433600	0.06209159	534.47694022
70.20000000	0.31788158	1122.25265500	0.06232972	534.53329602
70.40000000	0.31909607	1122.51887100	0.06256786	534.66009574
70.60000000	0.32031056	1122.28223400	0.06280599	534.54738462
70.80000000	0.32152505	1122.27237400	0.06304413	534.54268826
71.00000000	0.32273954	1122.41041300	0.06328226	534.60843677
71.20000000	0.32395402	1122.37097300	0.06352040	534.58965135
71.40000000	0.32516851	1122.62733000	0.06375853	534.71175518
71.60000000	0.32638300	1122.44985200	0.06399667	534.62722172
71.80000000	0.32759749	1122.32167400	0.06423480	534.56617004
72.00000000	0.32881198	1122.47943200	0.06447294	534.64131079
72.20000000	0.33002647	1122.30195400	0.06471107	534.55677733
72.40000000	0.33124095	1122.25265500	0.06494921	534.53329602
72.60000000	0.33245544	1121.93713800	0.06518734	534.38301405
72.80000000	0.33366993	1121.86811900	0.06542548	534.35014003
73.00000000	0.33488442	1122.04559700	0.06566361	534.43467349
73.20000000	0.33609891	1121.81882000	0.06590175	534.32665873
73.40000000	0.33731340	1121.86811900	0.06613988	534.35014003
73.60000000	0.33852788	1121.83853900	0.06637802	534.33605096
73.80000000	0.33974237	1121.96671800	0.06661615	534.39710312
74.00000000	0.34095686	1122.12447600	0.06685429	534.47224387
74.20000000	0.34217135	1121.72022100	0.06709242	534.27969564
74.40000000	0.34338584	1121.72022100	0.06733056	534.27969564
74.60000000	0.34460033	1122.12447600	0.06756869	534.47224387
74.80000000	0.34581481	1122.24279500	0.06780683	534.52859967
75.00000000	0.34702930	1122.42027300	0.06804496	534.61313313
75.20000000	0.34824379	1122.24279500	0.06828310	534.52859967
75.40000000	0.34945828	1122.16391600	0.06852123	534.49102929
75.60000000	0.35067277	1121.95685800	0.06875937	534.39240676
75.80000000	0.35188726	1121.58218300	0.06899750	534.21394761
76.00000000	0.35310174	1121.64134200	0.06923564	534.24212527
76.20000000	0.35431623	1121.30610600	0.06947377	534.08245106
76.40000000	0.35553072	1121.22722700	0.06971191	534.04488069
76.60000000	0.35674521	1121.44414400	0.06995004	534.14819910
76.80000000	0.35795970	1121.21736700	0.07018818	534.04018433
77.00000000	0.35917418	1120.72437300	0.07042631	533.80536937
77.20000000	0.36038867	1120.24123800	0.07066445	533.57525030
77.40000000	0.36160316	1120.32997700	0.07090258	533.61751703
77.60000000	0.36281765	1120.78353200	0.07114072	533.83354704
77.80000000	0.36403214	1120.83283100	0.07137885	533.85702834
78.00000000	0.36524663	1120.55675500	0.07161699	533.72553227
78.20000000	0.36646111	1120.36941700	0.07185512	533.63630245
78.40000000	0.36767560	1120.29053800	0.07209326	533.59873208
78.60000000	0.36889009	1120.43843600	0.07233139	533.66917647
78.80000000	0.37010458	1120.58633400	0.07256953	533.73962086
79.00000000	0.37131907	1120.04404100	0.07280766	533.48132460
79.20000000	0.37253356	1119.85670300	0.07304580	533.39209478
79.40000000	0.37374804	1119.78768400	0.07328393	533.35922077
79.60000000	0.37496253	1119.27497000	0.07352207	533.11501310
79.80000000	0.37617702	1119.37356900	0.07376020	533.16197618
80.00000000	0.37739151	1119.36370900	0.07399834	533.15727983
80.20000000	0.37860600	1119.36370900	0.07423647	533.15727983
80.40000000	0.37982049	1119.40314800	0.07447461	533.17606478
80.60000000	0.38103497	1119.00875300	0.07471274	532.98821291
80.80000000	0.38224946	1119.05805200	0.07495088	533.01169421
81.00000000	0.38346395	1118.80169500	0.07518901	532.88959038
81.20000000	0.38467844	1118.14108300	0.07542714	532.57493832
81.40000000	0.38589293	1117.69738900	0.07566528	532.36360514
81.60000000	0.38710742	1117.24383400	0.07590341	532.14757514
81.80000000	0.38832190	1117.17481500	0.07614155	532.11470112
82.00000000	0.38953639	1117.21425400	0.07637968	532.13348607
82.20000000	0.39075088	1117.11565500	0.07661782	532.08652298
82.40000000	0.39196537	1117.02691700	0.07685595	532.04425673
82.60000000	0.39317986	1117.02691700	0.07709409	532.04425673
82.80000000	0.39439435	1116.64238100	0.07733222	531.86110074
83.00000000	0.39560883	1116.21840600	0.07757036	531.65915980
83.20000000	0.39682332	1116.30714500	0.07780849	531.70142653
83.40000000	0.39803781	1115.78457100	0.07804663	531.45252251
83.60000000	0.39925230	1115.24227800	0.07828476	531.19422624
83.80000000	0.40046679	1115.13381900	0.07852290	531.14256680
84.00000000	0.40168128	1114.90704200	0.07876103	531.03455204
84.20000000	0.40289576	1114.88732200	0.07899917	531.02515932
84.40000000	0.40411025	1114.56194600	0.07923730	530.87018147
84.60000000	0.40532474	1113.98021300	0.07947544	530.59309979
84.80000000	0.40653923	1114.02951200	0.07971357	530.61658109
85.00000000	0.40775372	1114.22671000	0.07995171	530.71050726
85.20000000	0.40896821	1114.21685000	0.08018984	530.70581091
85.40000000	0.41018269	1114.25628900	0.08042798	530.72459586
85.60000000	0.41139718	1114.17741000	0.08066611	530.68702548
85.80000000	0.41261167	1114.05909200	0.08090425	530.63067016
86.00000000	0.41382616	1114.01965200	0.08114238	530.61188473
86.20000000	0.41504065	1113.69427600	0.08138052	530.45690688
86.40000000	0.41625514	1113.17170200	0.08161865	530.20800286
86.60000000	0.41746962	1113.06324300	0.08185679	530.15634342
86.80000000	0.41868411	1113.02380400	0.08209492	530.13755847
87.00000000	0.41989860	1113.01394400	0.08233306	530.13286211
87.20000000	0.42111309	1113.03366400	0.08257119	530.14225482
87.40000000	0.42232758	1112.52095000	0.08280933	529.89804715
87.60000000	0.42354206	1111.88991700	0.08304746	529.59748369
87.80000000	0.42475655	1111.29832400	0.08328560	529.31570564
88.00000000	0.42597104	1111.27860500	0.08352373	529.30631341
88.20000000	0.42718553	1112.03781600	0.08376187	529.66792855
88.40000000	0.42840002	1111.67300000	0.08400000	529.49416528
88.60000000	0.42961451	1111.10112700	0.08423814	529.22177995
88.80000000	0.43082899	1111.41664300	0.08447627	529.37206144
89.00000000	0.43204348	1111.27860500	0.08471441	529.30631341
89.20000000	0.43325797	1111.07154700	0.08495254	529.20769088
89.40000000	0.43447246	1111.17014600	0.08519068	529.25465397
89.60000000	0.43568695	1110.84477000	0.08542881	529.09967611
89.80000000	0.43690144	1110.66729200	0.08566695	529.01514265
90.00000000	0.43811592	1110.88420900	0.08590508	529.11846106
90.20000000	0.43933041	1110.43065500	0.08614322	528.90243153
90.40000000	0.44054490	1110.19401700	0.08638135	528.78971993
90.60000000	0.44175939	1110.12499800	0.08661949	528.75684592
90.80000000	0.44297388	1109.42494700	0.08685762	528.42340891
91.00000000	0.44418837	1108.93195200	0.08709576	528.18859347
91.20000000	0.44540285	1108.74461500	0.08733389	528.09936413
91.40000000	0.44661734	1108.81363400	0.08757203	528.13223815
91.60000000	0.44783183	1108.45867800	0.08781016	527.96317123
91.80000000	0.44904632	1108.16288200	0.08804830	527.82228245
92.00000000	0.45026081	1107.99526300	0.08828643	527.74244487
92.20000000	0.45147530	1107.76848600	0.08852457	527.63443010
92.40000000	0.45268978	1107.53184900	0.08876270	527.52171898
92.60000000	0.45390427	1107.09801400	0.08900084	527.31508169
92.80000000	0.45511876	1107.16703300	0.08923897	527.34795570
93.00000000	0.45633325	1106.87123700	0.08947711	527.20706692
93.20000000	0.45754774	1106.13174600	0.08971524	526.85484449
93.40000000	0.45876223	1106.02328700	0.08995338	526.80318504
93.60000000	0.45997671	1105.61903200	0.09019151	526.61063682
93.80000000	0.46119120	1105.42183400	0.09042965	526.51671065
94.00000000	0.46240569	1105.61903200	0.09066778	526.61063682
94.20000000	0.46362018	1105.19505700	0.09090592	526.40869588
94.40000000	0.46483467	1104.44570600	0.09114405	526.05177709
94.60000000	0.46604916	1104.20906800	0.09138219	525.93906549
94.80000000	0.46726364	1104.03159000	0.09162032	525.85453203
95.00000000	0.46847813	1103.38083800	0.09185846	525.54457633
95.20000000	0.46969262	1102.70050600	0.09209659	525.22053156
95.40000000	0.47090711	1101.88213600	0.09233473	524.83073875
95.60000000	0.47212160	1101.47788100	0.09257286	524.63819052
95.80000000	0.47333609	1100.98488600	0.09281100	524.40337509
96.00000000	0.47455057	1100.47217300	0.09304913	524.15916790
96.20000000	0.47576506	1099.72282100	0.09328727	523.80224863
96.40000000	0.47697955	1098.93403100	0.09352540	523.42654489
96.60000000	0.47819404	1098.23397900	0.09376354	523.09310741
96.80000000	0.47940853	1096.71555700	0.09400167	522.36987711
97.00000000	0.48062302	1095.14783500	0.09423981	521.62316504
97.20000000	0.48183750	1093.72801200	0.09447794	520.94689783
97.40000000	0.48305199	1091.79547500	0.09471608	520.02642296
97.60000000	0.48426648	1089.42910300	0.09495421	518.89931079
97.80000000	0.48548097	1086.03730300	0.09519235	517.28378328
98.00000000	0.48669546	1080.54534800	0.09543048	514.66794380
98.20000000	0.48790994	1073.28847400	0.09566862	511.21146654
98.40000000	0.48912443	1063.77368600	0.09590675	506.67953608
98.60000000	0.49033892	1046.69636600	0.09614489	498.54554227