File: data/input/1000_900_600/1000_900_600_2025_02_26_11_00.txt
Project Title : 1000_900_600
Material : HSLA steel
Informations :
Date : 26/02/2025
Type test : Tension / Compression
Control Mod : Manual
Section : Rectangular
Width(mm) : 2.700000
Total Length(mm) : 18.150000
Gauge Length(mm) : 6.300000
Thickness(mm) : 0.730000
====================================================================================================
Time (s) 	Speed (µm/s) 	Traverse Speed (µm/s) 	Displacement (µm) 	Force (N) 	Real Speed (µm/s) 	Cal. Force (V) 	Stress (Mpa) 	Elongation (%) 	Speed Controller Input Voltage (V)
0.100000 	5.000000 	5.000000 	0.000000 	-18.313790 	0.004689 	2.422221 	-9.291623 	0.000000 	1.377600
0.600000 	5.000000 	5.000000 	0.000000 	-17.494579 	0.008862 	2.422903 	-8.875992 	0.000000 	1.377600
1.100000 	5.000000 	5.000000 	0.000000 	-18.076909 	0.007614 	2.422419 	-9.171441 	0.000000 	1.377600
1.600000 	5.000000 	5.000000 	0.000000 	-17.751199 	0.500258 	2.422690 	-9.006189 	0.000000 	1.377600
2.100000 	5.000000 	5.000000 	0.020000 	-17.504449 	4.944221 	2.422895 	-8.880999 	0.000317 	1.377600
2.600000 	5.000000 	5.000000 	0.060000 	-17.978209 	4.985897 	2.422501 	-9.121364 	0.000952 	1.377600
3.100000 	5.000000 	5.000000 	0.060000 	-17.553799 	4.979113 	2.422854 	-8.906037 	0.000952 	1.377600
3.600000 	5.000000 	5.000000 	0.060000 	-17.336659 	4.980380 	2.423035 	-8.795870 	0.000952 	1.377600
4.100000 	5.000000 	5.000000 	0.060000 	-17.543929 	4.979486 	2.422862 	-8.901030 	0.000952 	1.377600
4.600000 	5.000000 	5.000000 	0.060000 	-17.534059 	4.984182 	2.422871 	-8.896022 	0.000952 	1.377600
5.100000 	5.000000 	5.000000 	0.060000 	-17.741329 	4.987239 	2.422698 	-9.001182 	0.000952 	1.377600
5.600000 	5.000000 	5.000000 	0.060000 	-17.662369 	4.984704 	2.422764 	-8.961121 	0.000952 	1.377600
6.100000 	5.000000 	5.000000 	0.060000 	-18.185479 	4.991116 	2.422328 	-9.226524 	0.000952 	1.377600
6.600000 	5.000000 	5.000000 	0.060000 	-17.731459 	4.984108 	2.422706 	-8.996174 	0.000952 	1.377600
7.100000 	5.000000 	5.000000 	0.040000 	-17.603149 	4.986494 	2.422813 	-8.931075 	0.000635 	1.377600
7.600000 	5.000000 	5.000000 	0.040000 	-17.701849 	4.985748 	2.422731 	-8.981151 	0.000635 	1.377600
8.100000 	5.000000 	5.000000 	0.020000 	-17.820289 	4.976280 	2.422632 	-9.041243 	0.000317 	1.377600
8.600000 	5.000000 	5.000000 	0.020000 	-17.770939 	4.974863 	2.422673 	-9.016205 	0.000317 	1.377600
9.100000 	5.000000 	5.000000 	0.020000 	-18.106519 	4.984928 	2.422394 	-9.186463 	0.000317 	1.377600
9.600000 	5.000000 	5.000000 	0.020000 	-18.205219 	4.979635 	2.422312 	-9.236540 	0.000317 	1.377600
10.100000 	5.000000 	5.000000 	0.020000 	-17.672239 	4.978591 	2.422755 	-8.966129 	0.000317 	1.377600
10.600000 	5.000000 	5.000000 	0.020000 	-18.027559 	4.985152 	2.422460 	-9.146403 	0.000317 	1.377600
11.100000 	5.000000 	5.000000 	0.020000 	-17.593279 	4.975087 	2.422821 	-8.926068 	0.000317 	1.377600
11.600000 	5.000000 	5.000000 	0.000000 	-17.573539 	4.977622 	2.422838 	-8.916052 	0.000000 	1.377600
12.100000 	5.000000 	5.000000 	-0.020000 	-17.810419 	4.982095 	2.422640 	-9.036235 	-0.000317 	1.377600
12.600000 	5.000000 	5.000000 	-0.020000 	-17.938729 	4.983810 	2.422534 	-9.101334 	-0.000317 	1.377600
13.100000 	5.000000 	5.000000 	-0.020000 	-16.586539 	4.986941 	2.423659 	-8.415291 	-0.000317 	1.377600
13.600000 	5.000000 	5.000000 	-0.040000 	-16.635889 	4.976951 	2.423618 	-8.440329 	-0.000635 	1.377600
14.100000 	5.000000 	5.000000 	-0.020000 	-15.994339 	4.984779 	2.424152 	-8.114835 	-0.000317 	1.377600
14.600000 	5.000000 	5.000000 	-0.020000 	-15.254089 	4.985077 	2.424769 	-7.739264 	-0.000317 	1.377600
15.100000 	5.000000 	5.000000 	-0.040000 	-14.276958 	4.979411 	2.425582 	-7.243510 	-0.000635 	1.377600
15.600000 	5.000000 	5.000000 	-0.040000 	-14.355919 	4.984853 	2.425516 	-7.283571 	-0.000635 	1.377600
16.100000 	5.000000 	5.000000 	-0.040000 	-13.230738 	4.979486 	2.426453 	-6.712703 	-0.000635 	1.377600
16.600000 	5.000000 	5.000000 	-0.020000 	-12.579318 	4.983959 	2.426995 	-6.382201 	-0.000317 	1.377600
17.100000 	5.000000 	5.000000 	-0.020000 	-11.602188 	4.980902 	2.427809 	-5.886447 	-0.000317 	1.377600
17.600000 	5.000000 	5.000000 	0.000000 	-11.355438 	4.987910 	2.428014 	-5.761257 	0.000000 	1.377600
18.100000 	5.000000 	5.000000 	0.040000 	-10.190777 	4.989998 	2.428984 	-5.170359 	0.000635 	1.377600
18.600000 	5.000000 	5.000000 	0.140000 	-9.707147 	4.986195 	2.429386 	-4.924986 	0.002222 	1.377600
19.100000 	5.000000 	5.000000 	0.600000 	-9.795977 	4.979411 	2.429312 	-4.970054 	0.009524 	1.377600
19.600000 	5.000000 	5.000000 	1.160000 	-9.253127 	4.990147 	2.429764 	-4.694636 	0.018413 	1.377600
20.100000 	5.000000 	5.000000 	1.460000 	-8.917547 	4.981722 	2.430044 	-4.524377 	0.023175 	1.377600
20.600000 	5.000000 	5.000000 	1.540000 	-9.391307 	4.987090 	2.429649 	-4.764742 	0.024444 	1.377600
21.100000 	5.000000 	5.000000 	1.700000 	-8.897807 	4.978516 	2.430060 	-4.514362 	0.026984 	1.377600
21.600000 	5.000000 	5.000000 	1.880000 	-8.295737 	4.982691 	2.430561 	-4.208898 	0.029841 	1.377600
22.100000 	5.000000 	5.000000 	1.960000 	-7.762757 	4.983511 	2.431005 	-3.938486 	0.031111 	1.377600
22.600000 	5.000000 	5.000000 	2.040000 	-7.703537 	4.980380 	2.431054 	-3.908441 	0.032381 	1.377600
23.100000 	5.000000 	5.000000 	2.140000 	-7.555487 	4.981051 	2.431177 	-3.833327 	0.033968 	1.377600
23.600000 	5.000000 	5.000000 	2.200000 	-7.219907 	4.985972 	2.431457 	-3.663068 	0.034921 	1.377600
24.100000 	5.000000 	5.000000 	2.260000 	-7.032377 	4.974639 	2.431613 	-3.567923 	0.035873 	1.377600
24.600000 	5.000000 	5.000000 	2.340000 	-6.568487 	4.979411 	2.431999 	-3.332565 	0.037143 	1.377600
25.100000 	5.000000 	5.000000 	2.400000 	-5.887456 	4.977249 	2.432566 	-2.987040 	0.038095 	1.377600
25.600000 	5.000000 	5.000000 	2.340000 	-5.690056 	4.977100 	2.432730 	-2.886888 	0.037143 	1.377600
26.100000 	5.000000 	5.000000 	2.360000 	-5.275516 	4.982095 	2.433075 	-2.676568 	0.037460 	1.377600
26.600000 	5.000000 	5.000000 	2.260000 	-5.423566 	4.981946 	2.432952 	-2.751683 	0.035873 	1.377600
27.100000 	5.000000 	5.000000 	2.240000 	-4.515526 	4.975832 	2.433708 	-2.290982 	0.035556 	1.377600
27.600000 	5.000000 	5.000000 	2.180000 	-4.890586 	4.981349 	2.433396 	-2.481272 	0.034603 	1.377600
28.100000 	5.000000 	5.000000 	2.220000 	-4.752406 	4.980753 	2.433511 	-2.411165 	0.035238 	1.377600
28.600000 	5.000000 	5.000000 	2.340000 	-3.962806 	4.975981 	2.434168 	-2.010556 	0.037143 	1.377600
29.100000 	5.000000 	5.000000 	2.380000 	-4.239166 	4.981051 	2.433938 	-2.150769 	0.037778 	1.377600
29.600000 	5.000000 	5.000000 	2.400000 	-3.637096 	4.979411 	2.434439 	-1.845305 	0.038095 	1.377600
30.100000 	5.000000 	5.000000 	2.480000 	-3.607486 	4.984332 	2.434464 	-1.830282 	0.039365 	1.377600
30.600000 	5.000000 	5.000000 	2.580000 	-3.735796 	4.979858 	2.434357 	-1.895381 	0.040952 	1.377600
31.100000 	5.000000 	5.000000 	2.660000 	-3.252166 	4.973447 	2.434760 	-1.650008 	0.042222 	1.377600
31.600000 	5.000000 	5.000000 	2.780000 	-3.015286 	4.981051 	2.434957 	-1.529825 	0.044127 	1.377600
32.100000 	5.000000 	5.000000 	2.860000 	-2.916586 	4.981051 	2.435039 	-1.479749 	0.045397 	1.377600
32.600000 	5.000000 	5.000000 	2.680000 	-3.400216 	4.981722 	2.434637 	-1.725122 	0.042540 	1.377600
33.100000 	5.000000 	5.000000 	2.740000 	-3.745666 	4.982617 	2.434349 	-1.900389 	0.043492 	1.377600
33.600000 	5.000000 	5.000000 	2.700000 	-3.873976 	4.977994 	2.434242 	-1.965488 	0.042857 	1.377600
34.100000 	5.000000 	5.000000 	2.520000 	-4.100986 	4.976205 	2.434053 	-2.080663 	0.040000 	1.377600
34.600000 	5.000000 	5.000000 	2.560000 	-4.485916 	4.975534 	2.433733 	-2.275959 	0.040635 	1.377600
35.100000 	5.000000 	5.000000 	2.580000 	-4.683316 	4.976951 	2.433568 	-2.376112 	0.040952 	1.377600
35.600000 	5.000000 	5.000000 	2.380000 	-4.821496 	4.977920 	2.433453 	-2.446218 	0.037778 	1.377600
36.100000 	5.000000 	5.000000 	2.400000 	-4.604356 	4.974714 	2.433634 	-2.336051 	0.038095 	1.377600
36.600000 	5.000000 	5.000000 	2.300000 	-4.397086 	4.976652 	2.433807 	-2.230891 	0.036508 	1.377600
37.100000 	5.000000 	5.000000 	2.300000 	-3.913456 	4.979336 	2.434209 	-1.985518 	0.036508 	1.377600
37.600000 	5.000000 	5.000000 	2.360000 	-3.804886 	4.972999 	2.434300 	-1.930434 	0.037460 	1.377600
38.100000 	5.000000 	5.000000 	2.320000 	-3.765406 	4.971061 	2.434333 	-1.910404 	0.036825 	1.377600
38.600000 	5.000000 	5.000000 	2.320000 	-3.311386 	4.974639 	2.434711 	-1.680054 	0.036825 	1.377600
39.100000 	5.000000 	5.000000 	2.280000 	-3.054766 	4.981126 	2.434924 	-1.549856 	0.036190 	1.377600
39.600000 	5.000000 	5.000000 	2.320000 	-2.768536 	4.972999 	2.435163 	-1.404635 	0.036825 	1.377600
40.100000 	5.000000 	5.000000 	2.360000 	-1.978935 	4.981499 	2.435820 	-1.004026 	0.037460 	1.377600
40.600000 	5.000000 	5.000000 	2.420000 	-0.794535 	4.975981 	2.436806 	-0.403113 	0.038413 	1.377600
41.100000 	5.000000 	5.000000 	2.600000 	1.633485 	4.978069 	2.438827 	0.828760 	0.041270 	1.377600
41.600000 	5.000000 	5.000000 	2.920000 	8.621447 	4.978964 	2.444644 	4.374149 	0.046349 	1.377600
42.100000 	5.000000 	5.000000 	3.340000 	18.057169 	4.975609 	2.452499 	9.161425 	0.053016 	1.377600
42.600000 	5.000000 	5.000000 	3.800000 	29.091832 	4.983288 	2.461686 	14.759935 	0.060317 	1.377600
43.100000 	5.000000 	5.000000 	4.300000 	41.310894 	4.979635 	2.471858 	20.959358 	0.068254 	1.377600
43.600000 	5.000000 	5.000000 	4.720000 	54.753837 	4.982244 	2.483049 	27.779724 	0.074921 	1.377600
44.100000 	5.000000 	5.000000 	5.240000 	69.124560 	4.973745 	2.495012 	35.070807 	0.083175 	1.377600
44.600000 	5.000000 	5.000000 	5.800000 	86.130573 	4.974490 	2.509169 	43.698921 	0.092063 	1.377600
45.100000 	5.000000 	5.000000 	6.360000 	103.432686 	4.976727 	2.523573 	52.477263 	0.100952 	1.377600
45.600000 	5.000000 	5.000000 	6.980000 	120.882848 	4.976131 	2.538100 	61.330720 	0.110794 	1.377600
46.100000 	5.000000 	5.000000 	7.560000 	138.194830 	4.973819 	2.552512 	70.114069 	0.120000 	1.377600
46.600000 	5.000000 	5.000000 	8.100000 	155.832523 	4.979038 	2.567195 	79.062670 	0.128571 	1.377600
47.100000 	5.000000 	5.000000 	8.720000 	174.220335 	4.980828 	2.582502 	88.391849 	0.138413 	1.377600
47.600000 	5.000000 	5.000000 	9.300000 	192.154126 	4.982766 	2.597432 	97.490678 	0.147619 	1.377600
48.100000 	5.000000 	5.000000 	9.880000 	210.324797 	4.983959 	2.612558 	106.709689 	0.156825 	1.377600
48.600000 	5.000000 	5.000000 	10.540000 	229.028449 	4.980157 	2.628129 	116.199111 	0.167302 	1.377600
49.100000 	5.000000 	5.000000 	11.160000 	247.149769 	4.982766 	2.643214 	125.393084 	0.177143 	1.377600
49.600000 	5.000000 	5.000000 	11.760000 	265.369790 	4.977994 	2.658382 	134.637133 	0.186667 	1.377600
50.100000 	5.000000 	5.000000 	12.340000 	283.866170 	4.978591 	2.673780 	144.021395 	0.195873 	1.377600
50.600000 	5.000000 	5.000000 	12.980000 	302.362550 	4.977323 	2.689178 	153.405657 	0.206032 	1.377600
51.100000 	5.000000 	5.000000 	13.600000 	320.631919 	4.979336 	2.704387 	162.674743 	0.215873 	1.377600
51.600000 	5.000000 	5.000000 	14.220000 	338.170908 	4.979784 	2.718988 	171.573267 	0.225714 	1.377600
52.100000 	5.000000 	5.000000 	14.860000 	355.433537 	4.981200 	2.733359 	180.331577 	0.235873 	1.377600
52.600000 	5.000000 	5.000000 	15.480000 	373.061356 	4.972850 	2.748033 	189.275168 	0.245714 	1.377600
53.100000 	5.000000 	5.000000 	16.040000 	390.205544 	4.979038 	2.762306 	197.973386 	0.254603 	1.377600
53.600000 	5.000000 	5.000000 	16.640000 	408.080112 	4.979635 	2.777186 	207.042168 	0.264127 	1.377600
54.100000 	5.000000 	5.000000 	17.340000 	427.148950 	4.983884 	2.793060 	216.716870 	0.275238 	1.377600
54.600000 	5.000000 	5.000000 	17.960000 	446.138827 	4.976951 	2.808869 	226.351510 	0.285079 	1.377600
55.100000 	5.000000 	5.000000 	18.520000 	465.484024 	4.984406 	2.824973 	236.166425 	0.293968 	1.377600
55.600000 	5.000000 	5.000000 	19.220000 	485.865570 	4.985450 	2.841941 	246.507138 	0.305079 	1.377600
56.100000 	5.000000 	5.000000 	19.880000 	505.427906 	4.974118 	2.858226 	256.432220 	0.315556 	1.377600
56.600000 	5.000000 	5.000000 	20.540000 	525.513351 	4.973894 	2.874947 	266.622705 	0.326032 	1.377600
57.100000 	5.000000 	5.000000 	21.200000 	544.098556 	4.971806 	2.890418 	276.052033 	0.336508 	1.377600
57.600000 	5.000000 	5.000000 	21.860000 	564.055691 	4.982169 	2.907032 	286.177418 	0.346984 	1.377600
58.100000 	5.000000 	5.000000 	22.520000 	582.522456 	4.973223 	2.922406 	295.546654 	0.357460 	1.377600
58.600000 	5.000000 	5.000000 	23.160000 	600.959610 	4.982393 	2.937754 	304.900867 	0.367619 	1.377600
59.100000 	5.000000 	5.000000 	23.800000 	619.979093 	4.986195 	2.953587 	314.550529 	0.377778 	1.377600
59.600000 	5.000000 	5.000000 	24.420000 	638.445857 	4.976802 	2.968961 	323.919765 	0.387619 	1.377600
60.100000 	5.000000 	5.000000 	25.140000 	656.883010 	4.985674 	2.984309 	333.273978 	0.399048 	1.377600
60.600000 	5.000000 	5.000000 	25.840000 	674.708223 	4.981424 	2.999148 	342.317718 	0.410159 	1.377600
61.100000 	5.000000 	5.000000 	26.520000 	692.582785 	4.973148 	3.014029 	351.386497 	0.420952 	1.377600
61.600000 	5.000000 	5.000000 	27.240000 	710.378388 	4.984555 	3.028843 	360.415214 	0.432381 	1.377600
62.100000 	5.000000 	5.000000 	27.920000 	728.460219 	4.980529 	3.043896 	369.589152 	0.443175 	1.377600
62.600000 	5.000000 	5.000000 	28.640000 	745.762321 	4.979784 	3.058299 	378.367489 	0.454603 	1.377600
63.100000 	5.000000 	5.000000 	29.360000 	763.172992 	4.984555 	3.072794 	387.200909 	0.466032 	1.377600
63.600000 	5.000000 	5.000000 	30.060000 	780.218473 	4.983586 	3.086984 	395.849048 	0.477143 	1.377600
64.100000 	5.000000 	5.000000 	30.780000 	796.661884 	4.974416 	3.100672 	404.191722 	0.488571 	1.377600
64.600000 	5.000000 	5.000000 	31.500000 	813.687625 	4.979038 	3.114846 	412.829845 	0.500000 	1.377600
65.100000 	5.000000 	5.000000 	32.220000 	830.002725 	4.979560 	3.128428 	421.107420 	0.511429 	1.377600
65.600000 	5.000000 	5.000000 	32.980000 	846.811325 	4.986568 	3.142421 	429.635375 	0.523492 	1.377600
66.100000 	5.000000 	5.000000 	33.700000 	862.909285 	4.979933 	3.155822 	437.802783 	0.534921 	1.377600
66.600000 	5.000000 	5.000000 	34.460000 	879.303344 	4.982095 	3.169470 	446.120418 	0.546984 	1.377600
67.100000 	5.000000 	5.000000 	35.180000 	895.727014 	4.979709 	3.183142 	454.453076 	0.558413 	1.377600
67.600000 	5.000000 	5.000000 	35.900000 	912.002632 	4.978144 	3.196691 	462.710620 	0.569841 	1.377600
68.100000 	5.000000 	5.000000 	36.660000 	928.258511 	4.985152 	3.210224 	470.958149 	0.581905 	1.377600
68.600000 	5.000000 	5.000000 	37.440000 	943.379340 	4.984853 	3.222812 	478.629802 	0.594286 	1.377600
69.100000 	5.000000 	5.000000 	38.180000 	958.717308 	4.977398 	3.235580 	486.411623 	0.606032 	1.377600
69.600000 	5.000000 	5.000000 	38.980000 	974.765916 	4.981871 	3.248940 	494.553991 	0.618730 	1.377600
70.100000 	5.000000 	5.000000 	39.780000 	990.103884 	4.979336 	3.261709 	502.335811 	0.631429 	1.377600
70.600000 	5.000000 	5.000000 	40.560000 	1004.296932 	4.972552 	3.273524 	509.536749 	0.643810 	1.377600
71.100000 	5.000000 	5.000000 	41.340000 	1019.388150 	4.976876 	3.286088 	517.193379 	0.656190 	1.377600
71.600000 	5.000000 	5.000000 	42.140000 	1033.294968 	4.975161 	3.297665 	524.249096 	0.668889 	1.377600
72.100000 	5.000000 	5.000000 	42.940000 	1047.557106 	4.976205 	3.309538 	531.485087 	0.681587 	1.377600
72.600000 	5.000000 	5.000000 	43.760000 	1061.000034 	4.976280 	3.320729 	538.305446 	0.694603 	1.377600
73.100000 	5.000000 	5.000000 	44.560000 	1074.334392 	4.984257 	3.331829 	545.070721 	0.707302 	1.377600
73.600000 	5.000000 	5.000000 	45.380000 	1087.876019 	4.979784 	3.343102 	551.941156 	0.720317 	1.377600
74.100000 	5.000000 	5.000000 	46.180000 	1100.993237 	4.972776 	3.354022 	558.596264 	0.733016 	1.377600
74.600000 	5.000000 	5.000000 	46.980000 	1113.439295 	4.980231 	3.364383 	564.910855 	0.745714 	1.377600
75.100000 	5.000000 	5.000000 	47.760000 	1124.543034 	4.980306 	3.373627 	570.544411 	0.758095 	1.377600
75.600000 	5.000000 	5.000000 	48.560000 	1136.623902 	4.981573 	3.383684 	576.673720 	0.770794 	1.377600
76.100000 	5.000000 	5.000000 	49.340000 	1147.253881 	4.977100 	3.392533 	582.066911 	0.783175 	1.377600
76.600000 	5.000000 	5.000000 	50.140000 	1157.439711 	4.976354 	3.401013 	587.234759 	0.795873 	1.377600
77.100000 	5.000000 	5.000000 	51.000000 	1165.996992 	4.980231 	3.408136 	591.576353 	0.809524 	1.377600
77.600000 	5.000000 	5.000000 	51.900000 	1173.962074 	4.983884 	3.414767 	595.617490 	0.823810 	1.377600
78.100000 	5.000000 	5.000000 	52.860000 	1179.686667 	4.974267 	3.419533 	598.521901 	0.839048 	1.377600
78.600000 	5.000000 	5.000000 	53.820000 	1183.762973 	4.978367 	3.422926 	600.590042 	0.854286 	1.377600
79.100000 	5.000000 	5.000000 	54.820000 	1186.092291 	4.981126 	3.424865 	601.771837 	0.870159 	1.377600
79.600000 	5.000000 	5.000000 	55.840000 	1186.437740 	4.977845 	3.425153 	601.947103 	0.886349 	1.377600
80.100000 	5.000000 	5.000000 	56.840000 	1188.105768 	4.982319 	3.426542 	602.793388 	0.902222 	1.377600
80.600000 	5.000000 	5.000000 	57.860000 	1190.514046 	4.981797 	3.428546 	604.015244 	0.918413 	1.377600
81.100000 	5.000000 	5.000000 	58.880000 	1191.649095 	4.977696 	3.429491 	604.591119 	0.934603 	1.377600
81.600000 	5.000000 	5.000000 	59.880000 	1192.517654 	4.977174 	3.430214 	605.031788 	0.950476 	1.377600
82.100000 	5.000000 	5.000000 	60.880000 	1193.968542 	4.979038 	3.431422 	605.767906 	0.966349 	1.377600
82.600000 	5.000000 	5.000000 	61.920000 	1192.626224 	4.977845 	3.430305 	605.086871 	0.982857 	1.377600
83.100000 	5.000000 	5.000000 	63.040000 	1191.007545 	4.974565 	3.428957 	604.265624 	1.000635 	1.377600
83.600000 	5.000000 	5.000000 	64.100000 	1188.875628 	4.977994 	3.427182 	603.183982 	1.017460 	1.377600
84.100000 	5.000000 	5.000000 	65.160000 	1188.243948 	4.978889 	3.426657 	602.863495 	1.034286 	1.377600
84.600000 	5.000000 	5.000000 	66.220000 	1188.352518 	4.978442 	3.426747 	602.918578 	1.051111 	1.377600
85.100000 	5.000000 	5.000000 	67.360000 	1186.911500 	4.974267 	3.425547 	602.187468 	1.069206 	1.377600
85.600000 	5.000000 	5.000000 	68.460000 	1184.957242 	4.974490 	3.423920 	601.195962 	1.086667 	1.377600
86.100000 	5.000000 	5.000000 	69.540000 	1183.753103 	4.976652 	3.422918 	600.585035 	1.103810 	1.377600
86.600000 	5.000000 	5.000000 	70.580000 	1183.378044 	4.974714 	3.422606 	600.394746 	1.120317 	1.377600
87.100000 	5.000000 	5.000000 	71.600000 	1183.308954 	4.976503 	3.422548 	600.359692 	1.136508 	1.377600
87.600000 	5.000000 	5.000000 	72.620000 	1183.190514 	4.980678 	3.422450 	600.299601 	1.152698 	1.377600
88.100000 	5.000000 	5.000000 	73.680000 	1182.351565 	4.982990 	3.421751 	599.873955 	1.169524 	1.377600
88.600000 	5.000000 	5.000000 	74.740000 	1181.887675 	4.974863 	3.421365 	599.638597 	1.186349 	1.377600
89.100000 	5.000000 	5.000000 	75.740000 	1182.509484 	4.981200 	3.421883 	599.954076 	1.202222 	1.377600
89.600000 	5.000000 	5.000000 	76.680000 	1185.460611 	4.977547 	3.424340 	601.451350 	1.217143 	1.377600
90.100000 	5.000000 	5.000000 	77.540000 	1194.708791 	4.980529 	3.432038 	606.143476 	1.230794 	1.377600
90.600000 	5.000000 	5.000000 	78.340000 	1206.375119 	4.975460 	3.441750 	612.062465 	1.243492 	1.377600
91.100000 	5.000000 	5.000000 	79.180000 	1217.222236 	4.977547 	3.450780 	617.565823 	1.256825 	1.377600
91.600000 	5.000000 	5.000000 	79.980000 	1227.111965 	4.981424 	3.459013 	622.583443 	1.269524 	1.377600
92.100000 	5.000000 	5.000000 	80.780000 	1236.162745 	4.984779 	3.466548 	627.175416 	1.282222 	1.377600
92.600000 	5.000000 	5.000000 	81.580000 	1245.519494 	4.975683 	3.474337 	631.922625 	1.294921 	1.377600
93.100000 	5.000000 	5.000000 	82.400000 	1255.409223 	4.978442 	3.482570 	636.940245 	1.307937 	1.377600
93.600000 	5.000000 	5.000000 	83.220000 	1264.854802 	4.978889 	3.490434 	641.732522 	1.320952 	1.377600
94.100000 	5.000000 	5.000000 	84.020000 	1273.402211 	4.974043 	3.497549 	646.069108 	1.333651 	1.377600
94.600000 	5.000000 	5.000000 	84.800000 	1280.962622 	4.975385 	3.503843 	649.904933 	1.346032 	1.377600
95.100000 	5.000000 	5.000000 	85.600000 	1288.296023 	4.975534 	3.509948 	653.625583 	1.358730 	1.377600
95.600000 	5.000000 	5.000000 	86.400000 	1295.747864 	4.976429 	3.516151 	657.406324 	1.371429 	1.377600
96.100000 	5.000000 	5.000000 	87.240000 	1302.725945 	4.973372 	3.521961 	660.946700 	1.384762 	1.377600
96.600000 	5.000000 	5.000000 	88.040000 	1309.111827 	4.976354 	3.527277 	664.186620 	1.397460 	1.377600
97.100000 	5.000000 	5.000000 	88.820000 	1315.369400 	4.976280 	3.532486 	667.361441 	1.409841 	1.377600
97.600000 	5.000000 	5.000000 	89.600000 	1320.955812 	4.974341 	3.537137 	670.195745 	1.422222 	1.377600
98.100000 	5.000000 	5.000000 	90.380000 	1327.321954 	4.974863 	3.542436 	673.425649 	1.434603 	1.377600
98.600000 	5.000000 	5.000000 	91.200000 	1332.898497 	4.967184 	3.547079 	676.254945 	1.447619 	1.377600
99.100000 	5.000000 	5.000000 	92.000000 	1338.326990 	4.985524 	3.551598 	679.009127 	1.460317 	1.377600
99.600000 	5.000000 	5.000000 	92.860000 	1343.716003 	4.979933 	3.556084 	681.743279 	1.473968 	1.377600
100.100000 	5.000000 	5.000000 	93.720000 	1349.855135 	4.977323 	3.561195 	684.858009 	1.487619 	1.377600
100.600000 	5.000000 	5.000000 	94.600000 	1354.158449 	4.978964 	3.564777 	687.041324 	1.501587 	1.377600
101.100000 	5.000000 	5.000000 	95.480000 	1359.705382 	4.975385 	3.569395 	689.855597 	1.515556 	1.377600
101.600000 	5.000000 	5.000000 	96.340000 	1364.245576 	4.973521 	3.573174 	692.159095 	1.529206 	1.377600
102.100000 	5.000000 	5.000000 	97.200000 	1369.674069 	4.976280 	3.577694 	694.913277 	1.542857 	1.377600
102.600000 	5.000000 	5.000000 	98.080000 	1373.740503 	4.975907 	3.581079 	696.976409 	1.556825 	1.377600
103.100000 	5.000000 	5.000000 	99.040000 	1378.152387 	4.971732 	3.584752 	699.214808 	1.572063 	1.377600
103.600000 	5.000000 	5.000000 	99.940000 	1383.403220 	4.977547 	3.589123 	701.878853 	1.586349 	1.377600
104.100000 	5.000000 	5.000000 	100.840000 	1387.084725 	4.978144 	3.592188 	703.746689 	1.600635 	1.377600
104.600000 	5.000000 	5.000000 	101.760000 	1391.516349 	4.981797 	3.595877 	705.995103 	1.615238 	1.377600
105.100000 	5.000000 	5.000000 	102.620000 	1395.642003 	4.975087 	3.599311 	708.088282 	1.628889 	1.377600
105.600000 	5.000000 	5.000000 	103.500000 	1399.402468 	4.973819 	3.602442 	709.996178 	1.642857 	1.377600
106.100000 	5.000000 	5.000000 	104.380000 	1403.014883 	4.976802 	3.605449 	711.828961 	1.656825 	1.377600
106.600000 	5.000000 	5.000000 	105.300000 	1406.765477 	4.981797 	3.608571 	713.731851 	1.671429 	1.377600
107.100000 	5.000000 	5.000000 	106.160000 	1410.604902 	4.975087 	3.611768 	715.679808 	1.685079 	1.377600
107.600000 	5.000000 	5.000000 	107.080000 	1413.783038 	4.980380 	3.614413 	717.292256 	1.699683 	1.377600
108.100000 	5.000000 	5.000000 	107.980000 	1417.237533 	4.973596 	3.617289 	719.044918 	1.713968 	1.377600
108.600000 	5.000000 	5.000000 	108.920000 	1420.553848 	4.972925 	3.620050 	720.727472 	1.728889 	1.377600
109.100000 	5.000000 	5.000000 	109.840000 	1423.761593 	4.980082 	3.622720 	722.354943 	1.743492 	1.377600
109.600000 	5.000000 	5.000000 	110.780000 	1426.742329 	4.980380 	3.625202 	723.867239 	1.758413 	1.377600
110.100000 	5.000000 	5.000000 	111.700000 	1429.367745 	4.977771 	3.627387 	725.199262 	1.773016 	1.377600
110.600000 	5.000000 	5.000000 	112.600000 	1433.068990 	4.977547 	3.630469 	727.077113 	1.787302 	1.377600
111.100000 	5.000000 	5.000000 	113.500000 	1435.881936 	4.972999 	3.632810 	728.504280 	1.801587 	1.377600
111.600000 	5.000000 	5.000000 	114.400000 	1438.921891 	4.969942 	3.635341 	730.046622 	1.815873 	1.377600
112.100000 	5.000000 	5.000000 	115.340000 	1441.932237 	4.972403 	3.637847 	731.573941 	1.830794 	1.377600
112.600000 	5.000000 	5.000000 	116.240000 	1445.061022 	4.979038 	3.640452 	733.161351 	1.845079 	1.377600
113.100000 	5.000000 	5.000000 	117.200000 	1447.548259 	4.972850 	3.642522 	734.423267 	1.860317 	1.377600
113.600000 	5.000000 	5.000000 	118.140000 	1451.150803 	4.975161 	3.645521 	736.251042 	1.875238 	1.377600
114.100000 	5.000000 	5.000000 	119.140000 	1453.499860 	4.969942 	3.647477 	737.442851 	1.891111 	1.377600
114.600000 	5.000000 	5.000000 	120.040000 	1455.621907 	4.973745 	3.649243 	738.519486 	1.905397 	1.377600
115.100000 	5.000000 	5.000000 	120.920000 	1458.286803 	4.969197 	3.651462 	739.871539 	1.919365 	1.377600
115.600000 	5.000000 	5.000000 	121.820000 	1461.089879 	4.975385 	3.653795 	741.293698 	1.933651 	1.377600
116.100000 	5.000000 	5.000000 	122.760000 	1463.675815 	4.984108 	3.655948 	742.605690 	1.948571 	1.377600
116.600000 	5.000000 	5.000000 	123.640000 	1466.320971 	4.971881 	3.658150 	743.947727 	1.962540 	1.377600
117.100000 	5.000000 	5.000000 	124.560000 	1467.850819 	4.974267 	3.659424 	744.723906 	1.977143 	1.377600
117.600000 	5.000000 	5.000000 	125.500000 	1470.495975 	4.970912 	3.661626 	746.065943 	1.992063 	1.377600
118.100000 	5.000000 	5.000000 	126.440000 	1473.131261 	4.978665 	3.663820 	747.402973 	2.006984 	1.377600
118.600000 	5.000000 	5.000000 	127.400000 	1475.509927 	4.975683 	3.665800 	748.609806 	2.022222 	1.377600
119.100000 	5.000000 	5.000000 	128.340000 	1478.155083 	4.973968 	3.668002 	749.951843 	2.037143 	1.377600
119.600000 	5.000000 	5.000000 	129.300000 	1480.829849 	4.971732 	3.670228 	751.308904 	2.052381 	1.377600
120.100000 	5.000000 	5.000000 	130.240000 	1482.981506 	4.987239 	3.672020 	752.400561 	2.067302 	1.377600
120.600000 	5.000000 	5.000000 	131.200000 	1485.083812 	4.973447 	3.673770 	753.467180 	2.082540 	1.377600
121.100000 	5.000000 	5.000000 	132.140000 	1487.650008 	4.983735 	3.675906 	754.769157 	2.097460 	1.377600
121.600000 	5.000000 	5.000000 	133.100000 	1489.594395 	4.978516 	3.677525 	755.755655 	2.112698 	1.377600
122.100000 	5.000000 	5.000000 	134.020000 	1491.676962 	4.978144 	3.679258 	756.812259 	2.127302 	1.377600
122.600000 	5.000000 	5.000000 	134.980000 	1493.147590 	4.974938 	3.680483 	757.558392 	2.142540 	1.377600
123.100000 	5.000000 	5.000000 	135.960000 	1496.108585 	4.979411 	3.682948 	759.060672 	2.158095 	1.377600
123.600000 	5.000000 	5.000000 	136.940000 	1497.766743 	4.982319 	3.684328 	759.901950 	2.173651 	1.377600
124.100000 	5.000000 	5.000000 	137.920000 	1499.592690 	4.975385 	3.685848 	760.828356 	2.189206 	1.377600
124.600000 	5.000000 	5.000000 	138.880000 	1501.546947 	4.973670 	3.687475 	761.819861 	2.204444 	1.377600
125.100000 	5.000000 	5.000000 	139.840000 	1503.787433 	4.968228 	3.689340 	762.956587 	2.219683 	1.377600
125.600000 	5.000000 	5.000000 	140.800000 	1506.008180 	4.978740 	3.691189 	764.083298 	2.234921 	1.377600
126.100000 	5.000000 	5.000000 	141.780000 	1506.906349 	4.979933 	3.691937 	764.538990 	2.250476 	1.377600
126.600000 	5.000000 	5.000000 	142.760000 	1508.988915 	4.978740 	3.693670 	765.595594 	2.266032 	1.377600
127.100000 	5.000000 	5.000000 	143.740000 	1510.814862 	4.978889 	3.695190 	766.522000 	2.281587 	1.377600
127.600000 	5.000000 	5.000000 	144.680000 	1512.117700 	4.972477 	3.696275 	767.183004 	2.296508 	1.377600
128.100000 	5.000000 	5.000000 	145.620000 	1513.835078 	4.977547 	3.697705 	768.054327 	2.311429 	1.377600
128.600000 	5.000000 	5.000000 	146.600000 	1515.661025 	4.980977 	3.699225 	768.980733 	2.326984 	1.377600
129.100000 	5.000000 	5.000000 	147.580000 	1517.881771 	4.973894 	3.701073 	770.107444 	2.342540 	1.377600
129.600000 	5.000000 	5.000000 	148.520000 	1519.786678 	4.979933 	3.702659 	771.073911 	2.357460 	1.377600
130.100000 	5.000000 	5.000000 	149.460000 	1521.513925 	4.986195 	3.704097 	771.950241 	2.372381 	1.377600
130.600000 	5.000000 	5.000000 	150.440000 	1522.866113 	4.972477 	3.705223 	772.636283 	2.387937 	1.377600
131.100000 	5.000000 	5.000000 	151.400000 	1524.514401 	4.981722 	3.706595 	773.472552 	2.403175 	1.377600
131.600000 	5.000000 	5.000000 	152.320000 	1525.580359 	4.977398 	3.707482 	774.013373 	2.417778 	1.377600
132.100000 	5.000000 	5.000000 	153.280000 	1527.120077 	4.976727 	3.708764 	774.794559 	2.433016 	1.377600
132.600000 	5.000000 	5.000000 	154.160000 	1529.321083 	4.980828 	3.710596 	775.911255 	2.446984 	1.377600
133.100000 	5.000000 	5.000000 	155.060000 	1530.248862 	4.973819 	3.711369 	776.381969 	2.461270 	1.377600
133.600000 	5.000000 	5.000000 	156.020000 	1531.462870 	4.975832 	3.712379 	776.997904 	2.476508 	1.377600
134.100000 	5.000000 	5.000000 	156.980000 	1533.890886 	4.976652 	3.714401 	778.229775 	2.491746 	1.377600
134.600000 	5.000000 	5.000000 	157.920000 	1534.631134 	4.979038 	3.715017 	778.605345 	2.506667 	1.377600
135.100000 	5.000000 	5.000000 	158.880000 	1535.904362 	4.975907 	3.716077 	779.251325 	2.521905 	1.377600
135.600000 	5.000000 	5.000000 	159.880000 	1536.733441 	4.972850 	3.716767 	779.671964 	2.537778 	1.377600
136.100000 	5.000000 	5.000000 	160.860000 	1538.983797 	4.976131 	3.718640 	780.813697 	2.553333 	1.377600
136.600000 	5.000000 	5.000000 	161.800000 	1540.839354 	4.977622 	3.720185 	781.755127 	2.568254 	1.377600
137.100000 	5.000000 	5.000000 	162.760000 	1541.875703 	4.968377 	3.721048 	782.280925 	2.583492 	1.377600
137.600000 	5.000000 	5.000000 	163.740000 	1543.563470 	4.980455 	3.722453 	783.137225 	2.599048 	1.377600
138.100000 	5.000000 	5.000000 	164.700000 	1544.007619 	4.976205 	3.722823 	783.362567 	2.614286 	1.377600
138.600000 	5.000000 	5.000000 	165.680000 	1545.310457 	4.975236 	3.723907 	784.023570 	2.629841 	1.377600
139.100000 	5.000000 	5.000000 	166.680000 	1546.139536 	4.973148 	3.724597 	784.444209 	2.645714 	1.377600
139.600000 	5.000000 	5.000000 	167.680000 	1547.886523 	4.980828 	3.726052 	785.330555 	2.661587 	1.377600
140.100000 	5.000000 	5.000000 	168.640000 	1548.547812 	4.981424 	3.726602 	785.666064 	2.676825 	1.377600
140.600000 	5.000000 	5.000000 	169.600000 	1549.692730 	4.978218 	3.727555 	786.246946 	2.692063 	1.377600
141.100000 	5.000000 	5.000000 	170.560000 	1550.758688 	4.976802 	3.728443 	786.787767 	2.707302 	1.377600
141.600000 	5.000000 	5.000000 	171.540000 	1551.479197 	4.971955 	3.729043 	787.153322 	2.722857 	1.377600
142.100000 	5.000000 	5.000000 	172.440000 	1551.893736 	4.969868 	3.729388 	787.363641 	2.737143 	1.377600
142.600000 	5.000000 	5.000000 	173.440000 	1553.127484 	4.982915 	3.730415 	787.989591 	2.753016 	1.377600
143.100000 	5.000000 	5.000000 	174.440000 	1554.302012 	4.982095 	3.731393 	788.585496 	2.768889 	1.377600
143.600000 	5.000000 	5.000000 	175.440000 	1555.121221 	4.970986 	3.732075 	789.001127 	2.784762 	1.377600
144.100000 	5.000000 	5.000000 	176.400000 	1555.644330 	4.977994 	3.732510 	789.266530 	2.800000 	1.377600
144.600000 	5.000000 	5.000000 	177.380000 	1556.710288 	4.976131 	3.733397 	789.807351 	2.815556 	1.377600
145.100000 	5.000000 	5.000000 	178.320000 	1557.243268 	4.974714 	3.733841 	790.077761 	2.830476 	1.377600
145.600000 	5.000000 	5.000000 	179.320000 	1558.042736 	4.979262 	3.734507 	790.483377 	2.846349 	1.377600
146.100000 	5.000000 	5.000000 	180.280000 	1558.960645 	4.975907 	3.735271 	790.949084 	2.861587 	1.377600
146.600000 	5.000000 	5.000000 	181.260000 	1559.888423 	4.978144 	3.736043 	791.419799 	2.877143 	1.377600
147.100000 	5.000000 	5.000000 	182.260000 	1561.546580 	4.976280 	3.737424 	792.261076 	2.893016 	1.377600
147.600000 	5.000000 	5.000000 	183.240000 	1562.128909 	4.977771 	3.737908 	792.556524 	2.908571 	1.377600
148.100000 	5.000000 	5.000000 	184.160000 	1562.642149 	4.970763 	3.738336 	792.816920 	2.923175 	1.377600
148.600000 	5.000000 	5.000000 	185.140000 	1562.967858 	4.976429 	3.738607 	792.982171 	2.938730 	1.377600
149.100000 	5.000000 	5.000000 	186.080000 	1563.066558 	4.974938 	3.738689 	793.032247 	2.953651 	1.377600
149.600000 	5.000000 	5.000000 	187.020000 	1563.915376 	4.971359 	3.739396 	793.462900 	2.968571 	1.377600
150.100000 	5.000000 	5.000000 	187.940000 	1564.724715 	4.976131 	3.740069 	793.873524 	2.983175 	1.377600
150.600000 	5.000000 	5.000000 	188.840000 	1564.882635 	4.975981 	3.740201 	793.953645 	2.997460 	1.377600
151.100000 	5.000000 	5.000000 	189.760000 	1565.553794 	4.975087 	3.740759 	794.294162 	3.012063 	1.377600
151.600000 	5.000000 	5.000000 	190.680000 	1565.504444 	4.976951 	3.740718 	794.269124 	3.026667 	1.377600
152.100000 	5.000000 	5.000000 	191.660000 	1566.619752 	4.979560 	3.741647 	794.834983 	3.042222 	1.377600
152.600000 	5.000000 	5.000000 	192.640000 	1566.935591 	4.974789 	3.741910 	794.995227 	3.057778 	1.377600
153.100000 	5.000000 	5.000000 	193.640000 	1567.498181 	4.979411 	3.742378 	795.280660 	3.073651 	1.377600
153.600000 	5.000000 	5.000000 	194.620000 	1567.932460 	4.979635 	3.742740 	795.500994 	3.089206 	1.377600
154.100000 	5.000000 	5.000000 	195.640000 	1568.327259 	4.978964 	3.743068 	795.701298 	3.105397 	1.377600
154.600000 	5.000000 	5.000000 	196.620000 	1568.475309 	4.976951 	3.743192 	795.776412 	3.120952 	1.377600
155.100000 	5.000000 	5.000000 	197.620000 	1569.087248 	4.968600 	3.743701 	796.086884 	3.136825 	1.377600
155.600000 	5.000000 	5.000000 	198.620000 	1569.511657 	4.979635 	3.744054 	796.302211 	3.152698 	1.377600
156.100000 	5.000000 	5.000000 	199.580000 	1569.807757 	4.981722 	3.744301 	796.452439 	3.167937 	1.377600
156.600000 	5.000000 	5.000000 	200.560000 	1569.857107 	4.976056 	3.744342 	796.477477 	3.183492 	1.377600
157.100000 	5.000000 	5.000000 	201.560000 	1569.699187 	4.978367 	3.744210 	796.397355 	3.199365 	1.377600
157.600000 	5.000000 	5.000000 	202.580000 	1569.748537 	4.978815 	3.744252 	796.422393 	3.215556 	1.377600
158.100000 	5.000000 	5.000000 	203.620000 	1570.577615 	4.973447 	3.744942 	796.843032 	3.232063 	1.377600
158.600000 	5.000000 	5.000000 	204.600000 	1570.696055 	4.973819 	3.745040 	796.903123 	3.247619 	1.377600
159.100000 	5.000000 	5.000000 	205.620000 	1570.932935 	4.973372 	3.745238 	797.023305 	3.263810 	1.377600
159.600000 	5.000000 	5.000000 	206.680000 	1570.518395 	4.975310 	3.744892 	796.812986 	3.280635 	1.377600
160.100000 	5.000000 	5.000000 	207.680000 	1570.755275 	4.978069 	3.745090 	796.933168 	3.296508 	1.377600
160.600000 	5.000000 	5.000000 	208.660000 	1570.064376 	4.970837 	3.744514 	796.582636 	3.312063 	1.377600
161.100000 	5.000000 	5.000000 	209.680000 	1570.350606 	4.977845 	3.744753 	796.727857 	3.328254 	1.377600
161.600000 	5.000000 	5.000000 	210.680000 	1569.936066 	4.980604 	3.744408 	796.517538 	3.344127 	1.377600
162.100000 	5.000000 	5.000000 	211.680000 	1570.064376 	4.980231 	3.744514 	796.582636 	3.360000 	1.377600
162.600000 	5.000000 	5.000000 	212.660000 	1570.074246 	4.975832 	3.744523 	796.587644 	3.375556 	1.377600
163.100000 	5.000000 	5.000000 	213.700000 	1570.153206 	4.977249 	3.744588 	796.627705 	3.392063 	1.377600
163.600000 	5.000000 	5.000000 	214.740000 	1570.508526 	4.973148 	3.744884 	796.807978 	3.408571 	1.377600
164.100000 	5.000000 	5.000000 	215.740000 	1569.817627 	4.975758 	3.744309 	796.457446 	3.424444 	1.377600
164.600000 	5.000000 	5.000000 	216.740000 	1569.738667 	4.982915 	3.744243 	796.417385 	3.440317 	1.377600
165.100000 	5.000000 	5.000000 	217.760000 	1569.274778 	4.975534 	3.743857 	796.182028 	3.456508 	1.377600
165.600000 	5.000000 	5.000000 	218.760000 	1569.008288 	4.985897 	3.743635 	796.046823 	3.472381 	1.377600
166.100000 	5.000000 	5.000000 	219.740000 	1568.781278 	4.977100 	3.743446 	795.931648 	3.487937 	1.377600
166.600000 	5.000000 	5.000000 	220.740000 	1568.386479 	4.978591 	3.743118 	795.731344 	3.503810 	1.377600
167.100000 	5.000000 	5.000000 	221.700000 	1567.665970 	4.975310 	3.742518 	795.365789 	3.519048 	1.377600
167.600000 	5.000000 	5.000000 	222.620000 	1566.915852 	4.982766 	3.741893 	794.985211 	3.533651 	1.377600
168.100000 	5.000000 	5.000000 	223.580000 	1566.797412 	4.976354 	3.741795 	794.925120 	3.548889 	1.377600
168.600000 	5.000000 	5.000000 	224.560000 	1566.037423 	4.979038 	3.741162 	794.539535 	3.564444 	1.377600
169.100000 	5.000000 	5.000000 	225.580000 	1565.731453 	4.977622 	3.740907 	794.384299 	3.580635 	1.377600
169.600000 	5.000000 	5.000000 	226.600000 	1564.487836 	4.974192 	3.739872 	793.753341 	3.596825 	1.377600
170.100000 	5.000000 	5.000000 	227.620000 	1564.083166 	4.981126 	3.739535 	793.548030 	3.613016 	1.377600
170.600000 	5.000000 	5.000000 	228.580000 	1563.224478 	4.986046 	3.738820 	793.112368 	3.628254 	1.377600
171.100000 	5.000000 	5.000000 	229.540000 	1562.286829 	4.976205 	3.738040 	792.636646 	3.643492 	1.377600
171.600000 	5.000000 	5.000000 	230.520000 	1561.438011 	4.977398 	3.737333 	792.205992 	3.659048 	1.377600
172.100000 	5.000000 	5.000000 	231.580000 	1560.480622 	4.965544 	3.736536 	791.720255 	3.675873 	1.377600
172.600000 	5.000000 	5.000000 	232.600000 	1559.237004 	4.978293 	3.735501 	791.089297 	3.692063 	1.377600
173.100000 	5.000000 	5.000000 	233.560000 	1558.240136 	4.974639 	3.734671 	790.583529 	3.707302 	1.377600
173.600000 	5.000000 	5.000000 	234.520000 	1558.082216 	4.972179 	3.734540 	790.503407 	3.722540 	1.377600
174.100000 	5.000000 	5.000000 	235.540000 	1556.799118 	4.978665 	3.733471 	789.852419 	3.738730 	1.377600
174.600000 	5.000000 	5.000000 	236.540000 	1555.170571 	4.978591 	3.732116 	789.026165 	3.754603 	1.377600
175.100000 	5.000000 	5.000000 	237.600000 	1553.936823 	4.972776 	3.731089 	788.400215 	3.771429 	1.377600
175.600000 	5.000000 	5.000000 	238.660000 	1552.367496 	4.972030 	3.729782 	787.604006 	3.788254 	1.377600
176.100000 	5.000000 	5.000000 	239.740000 	1551.429847 	4.977398 	3.729002 	787.128284 	3.805397 	1.377600
176.600000 	5.000000 	5.000000 	240.800000 	1550.205969 	4.972477 	3.727983 	786.507341 	3.822222 	1.377600
177.100000 	5.000000 	5.000000 	241.840000 	1548.695862 	4.969868 	3.726726 	785.741178 	3.838730 	1.377600
177.600000 	5.000000 	5.000000 	242.880000 	1546.563945 	4.975534 	3.724951 	784.659536 	3.855238 	1.377600
178.100000 	5.000000 	5.000000 	243.880000 	1545.083448 	4.973745 	3.723718 	783.908395 	3.871111 	1.377600
178.600000 	5.000000 	5.000000 	244.880000 	1543.089711 	4.979560 	3.722059 	782.896860 	3.886984 	1.377600
179.100000 	5.000000 	5.000000 	245.920000 	1542.063232 	4.978665 	3.721204 	782.376069 	3.903492 	1.377600
179.600000 	5.000000 	5.000000 	246.980000 	1539.931316 	4.970464 	3.719429 	781.294427 	3.920317 	1.377600
180.100000 	5.000000 	5.000000 	247.980000 	1537.898099 	4.973148 	3.717737 	780.262861 	3.936190 	1.377600
180.600000 	5.000000 	5.000000 	248.980000 	1536.427472 	4.974938 	3.716512 	779.516728 	3.952063 	1.377600
181.100000 	5.000000 	5.000000 	250.020000 	1534.946974 	4.978815 	3.715280 	778.765588 	3.968571 	1.377600
181.600000 	5.000000 	5.000000 	251.080000 	1532.637398 	4.977622 	3.713357 	777.593809 	3.985397 	1.377600
182.100000 	5.000000 	5.000000 	252.020000 	1530.663401 	4.969793 	3.711714 	776.592289 	4.000317 	1.377600
182.600000 	5.000000 	5.000000 	253.040000 	1529.044723 	4.979486 	3.710366 	775.771042 	4.016508 	1.377600
183.100000 	5.000000 	5.000000 	254.020000 	1526.823977 	4.976056 	3.708518 	774.644331 	4.032063 	1.377600
183.600000 	5.000000 	5.000000 	255.040000 	1524.928940 	4.979187 	3.706940 	773.682872 	4.048254 	1.377600
184.100000 	5.000000 	5.000000 	256.000000 	1522.619364 	4.983661 	3.705017 	772.511093 	4.063492 	1.377600
184.600000 	5.000000 	5.000000 	256.980000 	1520.359137 	4.976578 	3.703136 	771.364352 	4.079048 	1.377600
185.100000 	5.000000 	5.000000 	257.940000 	1518.187741 	4.972179 	3.701328 	770.262679 	4.094286 	1.377600
185.600000 	5.000000 	5.000000 	258.920000 	1516.144654 	4.970464 	3.699627 	769.226106 	4.109841 	1.377600
186.100000 	5.000000 	5.000000 	259.940000 	1513.815338 	4.982840 	3.697688 	768.044311 	4.126032 	1.377600
186.600000 	5.000000 	5.000000 	261.000000 	1511.466281 	4.974267 	3.695733 	766.852502 	4.142857 	1.377600
187.100000 	5.000000 	5.000000 	262.020000 	1508.998785 	4.971881 	3.693679 	765.600601 	4.159048 	1.377600
187.600000 	5.000000 	5.000000 	263.000000 	1506.314149 	4.977547 	3.691444 	764.238533 	4.174603 	1.377600
188.100000 	5.000000 	5.000000 	263.980000 	1503.678864 	4.979486 	3.689250 	762.901504 	4.190159 	1.377600
188.600000 	5.000000 	5.000000 	264.980000 	1500.994228 	4.981424 	3.687015 	761.539436 	4.206032 	1.377600
189.100000 	5.000000 	5.000000 	265.960000 	1497.964143 	4.975981 	3.684492 	760.002102 	4.221587 	1.377600
189.600000 	5.000000 	5.000000 	266.980000 	1495.516386 	4.977771 	3.682455 	758.760216 	4.237778 	1.377600
190.100000 	5.000000 	5.000000 	268.000000 	1492.515911 	4.974043 	3.679957 	757.237905 	4.253968 	1.377600
190.600000 	5.000000 	5.000000 	269.040000 	1489.841145 	4.975758 	3.677730 	755.880845 	4.270476 	1.377600
191.100000 	5.000000 	5.000000 	270.060000 	1486.880150 	4.971359 	3.675265 	754.378564 	4.286667 	1.377600
191.600000 	5.000000 	5.000000 	271.120000 	1483.405915 	4.974490 	3.672373 	752.615888 	4.303492 	1.377600
192.100000 	5.000000 	5.000000 	272.140000 	1480.642319 	4.974863 	3.670072 	751.213759 	4.319683 	1.377600
192.600000 	5.000000 	5.000000 	273.200000 	1477.543144 	4.978815 	3.667492 	749.641372 	4.336508 	1.377600
193.100000 	5.000000 	5.000000 	274.220000 	1473.920859 	4.970613 	3.664477 	747.803582 	4.352698 	1.377600
193.600000 	5.000000 	5.000000 	275.300000 	1470.683504 	4.974118 	3.661782 	746.161088 	4.369841 	1.377600
194.100000 	5.000000 	5.000000 	276.320000 	1467.140180 	4.974192 	3.658832 	744.363359 	4.386032 	1.377600
194.600000 	5.000000 	5.000000 	277.340000 	1463.695555 	4.975236 	3.655965 	742.615705 	4.402222 	1.377600
195.100000 	5.000000 	5.000000 	278.380000 	1460.132490 	4.970464 	3.652998 	740.807960 	4.418730 	1.377600
195.600000 	5.000000 	5.000000 	279.480000 	1456.579295 	4.975236 	3.650040 	739.005223 	4.436190 	1.377600
196.100000 	5.000000 	5.000000 	280.540000 	1453.312330 	4.981573 	3.647321 	737.347707 	4.453016 	1.377600
196.600000 	5.000000 	5.000000 	281.540000 	1449.087976 	4.971732 	3.643804 	735.204453 	4.468889 	1.377600
197.100000 	5.000000 	5.000000 	282.540000 	1445.337382 	4.977771 	3.640682 	733.301564 	4.484762 	1.377600
197.600000 	5.000000 	5.000000 	283.600000 	1442.080287 	4.981275 	3.637970 	731.649055 	4.501587 	1.377600
198.100000 	5.000000 	5.000000 	284.600000 	1437.915153 	4.975087 	3.634503 	729.535846 	4.517460 	1.377600
198.600000 	5.000000 	5.000000 	285.620000 	1433.690799 	4.973372 	3.630986 	727.392592 	4.533651 	1.377600
199.100000 	5.000000 	5.000000 	286.660000 	1429.545405 	4.974043 	3.627535 	725.289399 	4.550159 	1.377600
199.600000 	5.000000 	5.000000 	287.660000 	1425.350661 	4.976652 	3.624043 	723.161167 	4.566032 	1.377600
200.100000 	5.000000 	5.000000 	288.640000 	1421.037477 	4.970017 	3.620453 	720.972845 	4.581587 	1.377600
200.600000 	5.000000 	5.000000 	289.700000 	1416.408454 	4.972030 	3.616599 	718.624279 	4.598413 	1.377600
201.100000 	5.000000 	5.000000 	290.740000 	1411.345151 	4.973521 	3.612384 	716.055378 	4.614921 	1.377600
201.600000 	5.000000 	5.000000 	291.720000 	1407.545206 	4.978591 	3.609220 	714.127451 	4.630476 	1.377600
202.100000 	5.000000 	5.000000 	292.660000 	1402.787873 	4.978889 	3.605260 	711.713786 	4.645397 	1.377600
202.600000 	5.000000 	5.000000 	293.640000 	1397.981190 	4.978218 	3.601259 	709.275084 	4.660952 	1.377600
203.100000 	5.000000 	5.000000 	294.660000 	1393.174506 	4.975907 	3.597257 	706.836381 	4.677143 	1.377600
203.600000 	5.000000 	5.000000 	295.660000 	1388.160553 	4.975385 	3.593083 	704.292518 	4.693016 	1.377600
204.100000 	5.000000 	5.000000 	296.660000 	1382.830761 	4.978815 	3.588646 	701.588412 	4.708889 	1.377600
204.600000 	5.000000 	5.000000 	297.720000 	1377.076559 	4.977174 	3.583856 	698.668979 	4.725714 	1.377600
205.100000 	5.000000 	5.000000 	298.760000 	1372.062605 	4.975683 	3.579682 	696.125117 	4.742222 	1.377600
205.600000 	5.000000 	5.000000 	299.800000 	1366.091263 	4.978516 	3.574711 	693.095517 	4.758730 	1.377600
206.100000 	5.000000 	5.000000 	300.820000 	1360.603551 	4.980828 	3.570142 	690.311289 	4.774921 	1.377600
206.600000 	5.000000 	5.000000 	301.880000 	1354.730909 	4.979113 	3.565254 	687.331765 	4.791746 	1.377600
207.100000 	5.000000 	5.000000 	302.940000 	1347.644258 	4.972626 	3.559354 	683.736305 	4.808571 	1.377600
207.600000 	5.000000 	5.000000 	303.940000 	1342.146675 	4.982169 	3.554778 	680.947070 	4.824444 	1.377600
208.100000 	5.000000 	5.000000 	305.000000 	1335.563394 	4.984332 	3.549297 	677.606998 	4.841270 	1.377600
208.600000 	5.000000 	5.000000 	306.060000 	1329.335432 	4.975907 	3.544112 	674.447200 	4.858095 	1.377600
209.100000 	5.000000 	5.000000 	307.080000 	1322.436311 	4.977696 	3.538369 	670.946885 	4.874286 	1.377600
209.600000 	5.000000 	5.000000 	308.120000 	1315.290440 	4.980902 	3.532420 	667.321380 	4.890794 	1.377600
210.100000 	5.000000 	5.000000 	309.220000 	1308.470278 	4.980455 	3.526743 	663.861125 	4.908254 	1.377600
210.600000 	5.000000 	5.000000 	310.280000 	1300.939478 	4.978516 	3.520473 	660.040324 	4.925079 	1.377600
211.100000 	5.000000 	5.000000 	311.340000 	1293.497507 	4.977696 	3.514278 	656.264590 	4.941905 	1.377600
211.600000 	5.000000 	5.000000 	312.420000 	1285.354767 	4.978218 	3.507499 	652.133317 	4.959048 	1.377600
212.100000 	5.000000 	5.000000 	313.480000 	1276.945537 	4.980902 	3.500499 	647.866838 	4.975873 	1.377600
212.600000 	5.000000 	5.000000 	314.560000 	1269.039677 	4.979635 	3.493917 	643.855747 	4.993016 	1.377600
213.100000 	5.000000 	5.000000 	315.600000 	1259.979027 	4.976652 	3.486375 	639.258766 	5.009524 	1.377600
213.600000 	5.000000 	5.000000 	316.640000 	1251.056558 	4.974565 	3.478947 	634.731891 	5.026032 	1.377600
214.100000 	5.000000 	5.000000 	317.680000 	1241.946558 	4.979187 	3.471363 	630.109872 	5.042540 	1.377600
214.600000 	5.000000 	5.000000 	318.740000 	1232.066700 	4.976205 	3.463138 	625.097260 	5.059365 	1.377600
215.100000 	5.000000 	5.000000 	319.800000 	1221.693341 	4.981275 	3.454503 	619.834268 	5.076190 	1.377600
215.600000 	5.000000 	5.000000 	320.940000 	1210.796874 	4.979113 	3.445431 	614.305872 	5.094286 	1.377600
216.100000 	5.000000 	5.000000 	322.040000 	1198.242247 	4.975832 	3.434980 	607.936199 	5.111746 	1.377600
216.600000 	5.000000 	5.000000 	312.000000 	1127.020370 	4.978218 	3.375689 	571.801304 	4.952381 	1.377600
217.100000 	5.000000 	5.000000 	317.080000 	-9.687407 	4.982542 	2.429403 	-4.914971 	5.033016 	1.377600
217.600000 	5.000000 	5.000000 	317.120000 	-10.230257 	4.977696 	2.428951 	-5.190389 	5.033651 	1.377600
218.100000 	5.000000 	5.000000 	317.740000 	-9.865067 	4.982169 	2.429255 	-5.005108 	5.043492 	1.377600
218.600000 	5.000000 	5.000000 	318.200000 	-9.904547 	1.599797 	2.429222 	-5.025138 	5.050794 	1.377600
219.100000 	5.000000 	5.000000 	318.220000 	-10.151297 	0.006393 	2.429017 	-5.150328 	5.051111 	1.377600
219.600000 	5.000000 	5.000000 	318.240000 	-9.736757 	0.007670 	2.429362 	-4.940009 	5.051429 	1.377600
220.100000 	5.000000 	5.000000 	318.240000 	-9.608447 	0.009300 	2.429468 	-4.874910 	5.051429 	1.377600
220.600000 	5.000000 	5.000000 	318.260000 	-10.200647 	0.009048 	2.428975 	-5.175367 	5.051746 	1.377600
221.100000 	5.000000 	5.000000 	318.260000 	-10.101947 	0.007194 	2.429058 	-5.125290 	5.051746 	1.377600
221.600000 	5.000000 	5.000000 	318.260000 	-9.983507 	0.007492 	2.429156 	-5.065199 	5.051746 	1.377600
222.100000 	5.000000 	5.000000 	318.260000 	-10.338828 	0.012189 	2.428860 	-5.245473 	5.051746 	1.377600
222.600000 	5.000000 	5.000000 	318.260000 	-10.338828 	0.007987 	2.428860 	-5.245473 	5.051746 	1.377600
223.000000 	5.000000 	5.000000 	318.260000 	-10.131557 	0.009346 	2.429033 	-5.140313 	5.051746 	1.377600