File: data/output/vidExt_M-35Zr39Ti25Nb_Glb_11/vidExt_M-35Zr39Ti25Nb_Glb_11_correlated.txt
Total length (mm) = 50
Gage length (mm) = 5.1
Width (mm) = 2.21
Thickness (mm) = 0.95
----------
Time (s)	Displacement (mm)	Force (N)	Eng. strain	Eng. stress (MPa)
0.00000000	0.00000000	0.00000000	0.00000000	0.00000000
0.20000000	0.03773923	61.83140200	0.00739985	29.45053679
0.40000000	0.03826538	65.30208500	0.00750301	31.10363658
0.60000000	0.03879152	69.42352100	0.00760618	33.06669255
0.80000000	0.03931766	72.96322300	0.00770934	34.75266635
1.00000000	0.03984380	76.62124400	0.00781251	36.49499595
1.20000000	0.04036994	80.78211900	0.00791567	38.47683687
1.40000000	0.04089608	85.23879200	0.00801884	40.59956752
1.60000000	0.04142222	89.40952700	0.00812200	42.58610479
1.80000000	0.04194837	93.19572700	0.00822517	44.38948654
2.00000000	0.04247451	97.32702300	0.00832833	46.35723887
2.20000000	0.04300065	101.48789800	0.00843150	48.33907978
2.40000000	0.04352679	105.40227600	0.00853466	50.20351322
2.60000000	0.04405293	109.48427200	0.00863783	52.14778376
2.80000000	0.04457907	114.07898300	0.00874099	54.33626244
3.00000000	0.04510522	118.12154000	0.00884416	56.26174804
3.20000000	0.04563136	121.95703900	0.00894732	58.08861110
3.40000000	0.04615750	126.51231000	0.00905049	60.25830436
3.60000000	0.04668364	131.01828200	0.00915366	62.40451631
3.80000000	0.04720978	135.43551400	0.00925682	64.50846106
4.00000000	0.04773592	139.52737000	0.00935999	66.45742796
4.20000000	0.04826207	143.60936700	0.00946315	68.40169898
4.40000000	0.04878821	147.82940100	0.00956632	70.41171755
4.60000000	0.04931435	152.35509300	0.00966948	72.56732222
4.80000000	0.04984049	156.75260500	0.00977265	74.66187426
5.00000000	0.05036663	160.99236000	0.00987581	76.68128602
5.20000000	0.05089277	165.33071300	0.00997898	78.74766040
5.40000000	0.05141891	169.08733300	0.01008214	80.53695308
5.60000000	0.05194506	173.54400500	0.01018531	82.65968326
5.80000000	0.05247120	178.14857500	0.01028847	84.85285782
6.00000000	0.05299734	182.18127200	0.01039164	86.77364706
6.20000000	0.05352348	186.68724300	0.01049480	88.91985854
6.40000000	0.05404962	191.75522900	0.01059797	91.33375994
6.60000000	0.05457576	196.15274100	0.01070113	93.42831198
6.80000000	0.05510191	200.08683900	0.01080430	95.30213813
7.00000000	0.05562805	204.12939500	0.01090746	97.22762324
7.20000000	0.05615419	208.67480600	0.01101063	99.39262015
7.40000000	0.05668033	213.38783500	0.01111379	101.63745416
7.60000000	0.05720647	217.62758900	0.01121696	103.65686544
7.80000000	0.05773261	222.13356100	0.01132012	105.80307740
8.00000000	0.05825875	226.50149300	0.01142329	107.88354037
8.20000000	0.05878490	230.83984700	0.01152645	109.94991522
8.40000000	0.05931104	235.51343600	0.01162962	112.17596380
8.60000000	0.05983718	239.73347000	0.01173278	114.18598238
8.80000000	0.06036332	244.07182300	0.01183595	116.25235675
9.00000000	0.06088946	248.58765400	0.01193911	118.40326459
9.20000000	0.06141560	252.78796900	0.01204228	120.40389093
9.40000000	0.06194175	257.40239900	0.01214544	122.60176185
9.60000000	0.06246789	261.88865000	0.01224861	124.73858061
9.80000000	0.06299403	265.73400900	0.01235177	126.57014003
10.00000000	0.06352017	270.05264200	0.01245494	128.62712170
10.20000000	0.06404631	274.47973400	0.01255810	130.73576280
10.40000000	0.06457245	278.66032800	0.01266127	132.72699595
10.60000000	0.06509860	283.29447800	0.01276443	134.93425959
10.80000000	0.06562474	287.55395200	0.01286760	136.96306359
11.00000000	0.06615088	291.61622700	0.01297076	138.89794094
11.20000000	0.06667702	295.97430000	0.01307393	140.97370803
11.40000000	0.06720316	300.41125200	0.01317709	143.08704549
11.60000000	0.06772930	304.57212700	0.01328026	145.06888640
11.80000000	0.06825544	309.09781700	0.01338342	147.22449012
12.00000000	0.06878159	313.76154600	0.01348659	149.44584234
12.20000000	0.06930773	318.09989900	0.01358975	151.51221672
12.40000000	0.06983387	322.71432900	0.01369292	153.71008764
12.60000000	0.07036001	327.22030000	0.01379608	155.85629912
12.80000000	0.07088615	331.49949300	0.01389925	157.89449536
13.00000000	0.07141229	335.58148900	0.01400241	159.83876590
13.20000000	0.07193844	339.79166300	0.01410558	161.84408812
13.40000000	0.07246458	344.08071600	0.01420874	163.88698071
13.60000000	0.07299072	348.35004900	0.01431191	165.92048059
13.80000000	0.07351686	353.01377800	0.01441507	168.14183282
14.00000000	0.07404300	357.17465300	0.01451824	170.12367373
14.20000000	0.07456914	361.01015100	0.01462140	171.95053632
14.40000000	0.07509528	365.67388000	0.01472457	174.17188854
14.60000000	0.07562143	369.83475400	0.01482773	176.15372898
14.80000000	0.07614757	373.54207400	0.01493090	177.91953989
15.00000000	0.07667371	378.38328100	0.01503406	180.22542558
15.20000000	0.07719985	383.45126500	0.01513723	182.63932603
15.40000000	0.07772599	387.57270000	0.01524039	184.60238152
15.60000000	0.07825213	391.64483500	0.01534356	186.54195523
15.80000000	0.07877828	396.46632200	0.01544672	188.83844820
16.00000000	0.07930442	400.85397400	0.01554989	190.92830388
16.20000000	0.07983056	404.83737000	0.01565305	192.82561086
16.40000000	0.08035670	409.45180000	0.01575622	195.02348178
16.60000000	0.08088284	413.83945100	0.01585938	197.11333698
16.80000000	0.08140898	417.67494900	0.01596255	198.94019957
17.00000000	0.08193513	421.87526300	0.01606571	200.94082543
17.20000000	0.08246127	426.43053300	0.01616888	203.11051822
17.40000000	0.08298741	430.31533000	0.01627204	204.96086211
17.60000000	0.08351355	434.46634400	0.01637521	206.93800619
17.80000000	0.08403969	439.20895200	0.01647837	209.19692879
18.00000000	0.08456583	443.36982600	0.01658154	211.17876923
18.20000000	0.08509197	447.58986000	0.01668470	213.18878781
18.40000000	0.08561812	451.39577800	0.01678787	215.00156132
18.60000000	0.08614426	455.31015500	0.01689103	216.86599428
18.80000000	0.08667040	460.17108100	0.01699420	219.18127221
19.00000000	0.08719654	464.43055400	0.01709736	221.21007573
19.20000000	0.08772268	468.18717300	0.01720053	222.99936794
19.40000000	0.08824882	472.35790600	0.01730369	224.98590426
19.60000000	0.08877497	476.75541800	0.01740686	227.08045630
19.80000000	0.08930111	481.01489100	0.01751002	229.10925982
20.00000000	0.08982725	485.09688600	0.01761319	231.05352989
20.20000000	0.09035339	489.44509700	0.01771635	233.12459967
20.40000000	0.09087953	493.55667200	0.01781952	235.08295880
20.60000000	0.09140567	497.54006800	0.01792268	236.98026578
20.80000000	0.09193181	501.85870000	0.01802585	239.03724696
21.00000000	0.09245796	505.91111500	0.01812901	240.96742796
21.20000000	0.09298410	510.11142800	0.01823218	242.96805335
21.40000000	0.09351024	514.14412400	0.01833534	244.88884211
21.60000000	0.09403638	518.21625800	0.01843851	246.82841534
21.80000000	0.09456252	522.62363000	0.01854167	248.92766373
22.00000000	0.09508866	526.50842600	0.01864484	250.77800714
22.20000000	0.09561481	530.47210200	0.01874800	252.66592141
22.40000000	0.09614095	534.77101500	0.01885117	254.71351036
22.60000000	0.09666709	538.94174800	0.01895433	256.70004668
22.80000000	0.09719323	542.72794600	0.01905750	258.50342748
23.00000000	0.09771937	546.57330300	0.01916066	260.33498595
23.20000000	0.09824551	551.08913300	0.01926383	262.48589331
23.40000000	0.09877166	555.21056700	0.01936699	264.44894832
23.60000000	0.09929780	558.76012700	0.01947016	266.13961753
23.80000000	0.09982394	562.66464400	0.01957332	267.99935413
24.00000000	0.10035008	566.82551800	0.01967649	269.98119457
24.20000000	0.10087622	570.73989400	0.01977965	271.84562705
24.40000000	0.10140236	574.79230900	0.01988282	273.77580805
24.60000000	0.10192850	579.08136100	0.01998598	275.81870017
24.80000000	0.10245465	583.62677000	0.02008915	277.98369612
25.00000000	0.10298079	587.40310800	0.02019231	279.78238057
25.20000000	0.10350693	591.18930500	0.02029548	281.58576090
25.40000000	0.10403307	595.62625600	0.02039864	283.69909788
25.60000000	0.10455921	599.77726900	0.02050181	285.67624149
25.80000000	0.10508535	603.62262600	0.02060497	287.50779995
26.00000000	0.10561150	607.74406000	0.02070814	289.47085497
26.20000000	0.10613764	612.02325200	0.02081130	291.50905073
26.40000000	0.10666378	615.61225200	0.02091447	293.21850536
26.60000000	0.10718992	619.51676800	0.02101763	295.07824149
26.80000000	0.10771606	623.70722100	0.02112080	297.07417052
27.00000000	0.10824220	627.77935600	0.02122396	299.01374422
27.20000000	0.10876834	631.66415200	0.02132713	300.86408764
27.40000000	0.10929449	635.62782700	0.02143029	302.75200143
27.60000000	0.10982063	639.95631900	0.02153346	304.81367897
27.80000000	0.11034677	643.86083500	0.02163662	306.67341510
28.00000000	0.11087291	647.75549100	0.02173979	308.52845487
28.20000000	0.11139905	651.76846600	0.02184295	310.43985044
28.40000000	0.11192519	655.49550400	0.02194612	312.21505311
28.60000000	0.11245134	659.80427500	0.02204928	314.26733746
28.80000000	0.11297748	663.65949200	0.02215245	316.10359228
29.00000000	0.11350362	667.50484900	0.02225561	317.93515075
29.20000000	0.11402976	671.70516100	0.02235878	319.93577566
29.40000000	0.11455590	675.69841600	0.02246194	321.83777852
29.60000000	0.11508204	679.46489400	0.02256511	323.63176661
29.80000000	0.11560819	683.23137100	0.02266827	325.42575423
30.00000000	0.11613433	687.22462600	0.02277144	327.32775709
30.20000000	0.11666047	691.07984300	0.02287460	329.16401191
30.40000000	0.11718661	694.95477900	0.02297777	331.00965897
30.60000000	0.11771275	698.34658100	0.02308093	332.62518743
30.80000000	0.11823889	702.15249800	0.02318410	334.43796047
31.00000000	0.11876503	706.28379100	0.02328726	336.40571136
31.20000000	0.11929118	710.03054800	0.02339043	338.19030626
31.40000000	0.11981732	713.82660500	0.02349359	339.99838295
31.60000000	0.12034346	717.90859900	0.02359676	341.94265254
31.80000000	0.12086960	721.37928000	0.02369992	343.59575137
32.00000000	0.12139574	724.87954000	0.02380309	345.26293879
32.20000000	0.12192188	729.03055300	0.02390625	347.24008240
32.40000000	0.12244803	732.96464900	0.02400942	349.11390760
32.60000000	0.12297417	736.59308700	0.02411258	350.84214670
32.80000000	0.12350031	740.27082600	0.02421575	352.59386806
33.00000000	0.12402645	744.37253900	0.02431891	354.54752989
33.20000000	0.12455259	748.27705500	0.02442208	356.40726602
33.40000000	0.12507873	751.60969700	0.02452524	357.99461634
33.60000000	0.12560487	755.33673400	0.02462841	359.76981853
33.80000000	0.12613102	759.43844800	0.02473157	361.72348083
34.00000000	0.12665716	762.98800700	0.02483474	363.41414956
34.20000000	0.12718330	766.67560500	0.02493790	365.17056680
34.40000000	0.12770944	770.76745900	0.02504107	367.11953275
34.60000000	0.12823558	774.62267500	0.02514423	368.95578709
34.80000000	0.12876172	778.14265500	0.02524740	370.63236723
35.00000000	0.12928787	781.47529700	0.02535056	372.21971755
35.20000000	0.12981401	784.83751800	0.02545373	373.82115647
35.40000000	0.13034015	788.91951200	0.02555689	375.76542605
35.60000000	0.13086629	792.64654900	0.02566006	377.54062824
35.80000000	0.13139243	795.77213400	0.02576322	379.02935651
36.00000000	0.13191857	799.32169300	0.02586639	380.72002524
36.20000000	0.13244472	803.47270500	0.02596955	382.69716837
36.40000000	0.13297086	807.49553900	0.02607272	384.61325982
36.60000000	0.13349700	810.67042300	0.02617588	386.12546940
36.80000000	0.13402314	814.18054300	0.02627905	387.79735318
37.00000000	0.13454928	817.86814100	0.02638221	389.55377042
37.20000000	0.13507542	821.25008200	0.02648538	391.16460205
37.40000000	0.13560156	825.14473700	0.02658854	393.01964134
37.60000000	0.13612771	828.96051400	0.02669171	394.83711074
37.80000000	0.13665385	832.15511700	0.02679487	396.35871255
38.00000000	0.13717999	835.66523700	0.02689804	398.03059633
38.20000000	0.13770613	839.71765000	0.02700120	399.96077638
38.40000000	0.13823227	843.36580800	0.02710437	401.69840819
38.60000000	0.13875841	846.98438700	0.02720753	403.42195142
38.80000000	0.13928456	850.72128400	0.02731070	405.20184996
39.00000000	0.13981070	854.37930200	0.02741386	406.94417814
39.20000000	0.14033684	857.93872100	0.02751703	408.63954322
39.40000000	0.14086298	861.20234300	0.02762019	410.19401905
39.60000000	0.14138912	864.58428400	0.02772336	411.80485068
39.80000000	0.14191526	868.20286300	0.02782652	413.52839390
40.00000000	0.14244140	871.78200200	0.02792969	415.23315170
40.20000000	0.14296755	875.32170100	0.02803285	416.91912408
40.40000000	0.14349369	878.71350200	0.02813602	418.53465206
40.60000000	0.14401983	881.93768500	0.02823918	420.07034294
40.80000000	0.14454597	885.45766400	0.02834235	421.74692260
41.00000000	0.14507211	888.94806400	0.02844551	423.40941367
41.20000000	0.14559825	892.40888400	0.02854868	425.05781567
41.40000000	0.14612440	895.67250600	0.02865184	426.61229150
41.60000000	0.14665054	898.63047200	0.02875501	428.02118219
41.80000000	0.14717668	901.94339400	0.02885817	429.59913980
42.00000000	0.14770282	905.15771600	0.02896134	431.13013384
42.20000000	0.14822896	908.26358000	0.02906450	432.60946892
42.40000000	0.14875510	911.59622200	0.02916767	434.19681924
42.60000000	0.14928125	914.94858300	0.02927083	435.79356180
42.80000000	0.14980739	918.62632100	0.02937400	437.54528269
43.00000000	0.15033353	922.04770100	0.02947716	439.17489926
43.20000000	0.15085967	925.40006200	0.02958033	440.77164182
43.40000000	0.15138581	928.96934100	0.02968349	442.47170326
43.60000000	0.15191195	932.10478400	0.02978666	443.96512693
43.80000000	0.15243809	935.32896700	0.02988982	445.50081781
44.00000000	0.15296424	938.59258900	0.02999299	447.05529364
44.20000000	0.15349038	941.64915400	0.03009615	448.51114742
44.40000000	0.15401652	945.23815200	0.03019932	450.22060110
44.60000000	0.15454266	949.11308700	0.03030248	452.06624768
44.80000000	0.15506880	952.62320600	0.03040565	453.73813098
45.00000000	0.15559494	956.15304500	0.03050881	455.41940700
45.20000000	0.15612109	959.38708700	0.03061198	456.95979376
45.40000000	0.15664723	962.44365200	0.03071514	458.41564754
45.60000000	0.15717337	965.64811500	0.03081831	459.94194570
45.80000000	0.15769951	969.59206900	0.03092147	461.82046630
46.00000000	0.15822565	972.93457000	0.03102464	463.41251250
46.20000000	0.15875179	975.71505700	0.03112780	464.73686925
46.40000000	0.15927793	979.27447600	0.03123097	466.43223434
46.60000000	0.15980408	982.42963900	0.03133413	467.93505073
46.80000000	0.16033022	985.57494200	0.03143730	469.43317075
47.00000000	0.16085636	989.35127800	0.03154046	471.23185425
47.20000000	0.16138250	992.76279800	0.03164363	472.85677447
47.40000000	0.16190864	996.17431900	0.03174679	474.48169517
47.60000000	0.16243478	999.84219600	0.03184996	476.22871922
47.80000000	0.16296093	1002.91848000	0.03195312	477.69396523
48.00000000	0.16348707	1006.20182100	0.03205629	479.25783329
48.20000000	0.16401321	1009.42600400	0.03215945	480.79352417
48.40000000	0.16453935	1012.40368900	0.03226262	482.21180710
48.60000000	0.16506549	1015.73633000	0.03236578	483.79915694
48.80000000	0.16559163	1019.16757000	0.03246895	485.43346987
49.00000000	0.16611778	1022.25371300	0.03257211	486.90341176
49.20000000	0.16664392	1024.82714300	0.03267528	488.12914646
49.40000000	0.16717006	1027.57805100	0.03277844	489.43941462
49.60000000	0.16769620	1031.21634800	0.03288161	491.17234961
49.80000000	0.16822234	1034.73632700	0.03298477	492.84892927
50.00000000	0.16874848	1037.21115800	0.03308794	494.02770088
50.20000000	0.16927462	1040.13954400	0.03319110	495.42250250
50.40000000	0.16980077	1043.60036300	0.03329427	497.07090402
50.60000000	0.17032691	1046.85412500	0.03339743	498.62068350
50.80000000	0.17085305	1049.82195000	0.03350060	500.03427006
51.00000000	0.17137919	1052.74047500	0.03360376	501.42437485
51.20000000	0.17190533	1055.63928100	0.03370693	502.80508740
51.40000000	0.17243147	1058.60710600	0.03381009	504.21867397
51.60000000	0.17295762	1061.24955500	0.03391326	505.47728269
51.80000000	0.17348376	1063.46802900	0.03401642	506.53395046
52.00000000	0.17400990	1065.88370100	0.03411959	507.68454442
52.20000000	0.17453604	1068.49657000	0.03422275	508.92906406
52.40000000	0.17506218	1071.17845800	0.03432592	510.20645773
52.60000000	0.17558832	1073.82090700	0.03442908	511.46506644
52.80000000	0.17611446	1076.38447700	0.03453225	512.68610479
53.00000000	0.17664061	1078.62267100	0.03463541	513.75216528
53.20000000	0.17690368	1080.98904300	0.03468700	514.87927745
53.40000000	0.17818487	1083.39485400	0.03493821	516.02517457
53.60000000	0.17946606	1085.55416900	0.03518942	517.05366468
53.80000000	0.18074725	1087.43740700	0.03544064	517.95065825
54.00000000	0.18202843	1089.57700100	0.03569185	518.96975518
54.20000000	0.18330962	1091.63771700	0.03594306	519.95128221
54.40000000	0.18459081	1093.59983400	0.03619428	520.88584615
54.60000000	0.18587200	1095.24643400	0.03644549	521.67012813
54.80000000	0.18715319	1096.90289500	0.03669670	522.45910693
55.00000000	0.18843438	1098.68753400	0.03694792	523.30913741
55.20000000	0.18971557	1100.19609600	0.03719913	524.02767135
55.40000000	0.19099676	1101.57647900	0.03745035	524.68515313
55.60000000	0.19227795	1102.78924500	0.03770156	525.26279829
55.80000000	0.19355914	1103.97243100	0.03795277	525.82635437
56.00000000	0.19484033	1105.11617800	0.03820399	526.37112551
56.20000000	0.19612152	1106.37824300	0.03845520	526.97225196
56.40000000	0.19740271	1107.07829400	0.03870641	527.30568897
56.60000000	0.19868390	1107.88680500	0.03895763	527.69078590
56.80000000	0.19996509	1109.46438600	0.03920884	528.44219386
57.00000000	0.20124628	1110.61799200	0.03946005	528.99166087
57.20000000	0.20252747	1111.30818400	0.03971127	529.32040200
57.40000000	0.20380866	1112.05753500	0.03996248	529.67732079
57.60000000	0.20508984	1112.68856800	0.04021370	529.97788426
57.80000000	0.20637103	1113.11254300	0.04046491	530.17982520
58.00000000	0.20765222	1113.64497700	0.04071612	530.43342558
58.20000000	0.20893341	1113.93091300	0.04096734	530.56961800
58.40000000	0.21021460	1114.00979200	0.04121855	530.60718838
58.60000000	0.21149579	1115.00564000	0.04146976	531.08151465
58.80000000	0.21277698	1115.43947500	0.04172098	531.28815194
59.00000000	0.21405817	1115.40989600	0.04197219	531.27406335
59.20000000	0.21533936	1116.14938700	0.04222340	531.62628578
59.40000000	0.21662055	1116.62266100	0.04247462	531.85170803
59.60000000	0.21790174	1116.72126000	0.04272583	531.89867111
59.80000000	0.21918293	1116.72126000	0.04297704	531.89867111
60.00000000	0.22046412	1116.92831800	0.04322826	531.99729364
60.20000000	0.22174531	1117.09593600	0.04347947	532.07713075
60.40000000	0.22302650	1117.03677600	0.04373069	532.04895261
60.60000000	0.22430769	1117.74668800	0.04398190	532.38708645
60.80000000	0.22558888	1118.62421800	0.04423311	532.80505739
61.00000000	0.22687007	1118.76225600	0.04448433	532.87080543
61.20000000	0.22815125	1119.02847300	0.04473554	532.99760562
61.40000000	0.22943244	1119.40314800	0.04498675	533.17606478
61.60000000	0.23071363	1119.38342900	0.04523797	533.16667254
61.80000000	0.23199482	1119.50174700	0.04548918	533.22302786
62.00000000	0.23327601	1119.95530200	0.04574039	533.43905787
62.20000000	0.23455720	1119.79754400	0.04599161	533.36391712
62.40000000	0.23583839	1119.79754400	0.04624282	533.36391712
62.60000000	0.23711958	1119.97502200	0.04649404	533.44845058
62.80000000	0.23840077	1119.87642300	0.04674525	533.40148750
63.00000000	0.23968196	1120.23137900	0.04699646	533.57055442
63.20000000	0.24096315	1120.28067800	0.04724768	533.59403572
63.40000000	0.24224434	1120.45815600	0.04749889	533.67856918
63.60000000	0.24352553	1120.72437300	0.04775010	533.80536937
63.80000000	0.24480672	1120.91171000	0.04800132	533.89459871
64.00000000	0.24608791	1121.33568500	0.04825253	534.09653965
64.20000000	0.24736910	1121.49344400	0.04850374	534.17168088
64.40000000	0.24865029	1121.51316300	0.04875496	534.18107311
64.60000000	0.24993148	1121.43428400	0.04900617	534.14350274
64.80000000	0.25121266	1121.49344400	0.04925739	534.17168088
65.00000000	0.25249385	1121.87797900	0.04950860	534.35483639
65.20000000	0.25377504	1122.04559700	0.04975981	534.43467349
65.40000000	0.25505623	1121.86811900	0.05001103	534.35014003
65.60000000	0.25633742	1121.45400400	0.05026224	534.15289545
65.80000000	0.25761861	1121.54274300	0.05051345	534.19516218
66.00000000	0.25889980	1122.01601700	0.05076467	534.42058442
66.20000000	0.26018099	1121.79910000	0.05101588	534.31726602
66.40000000	0.26146218	1121.77938000	0.05126709	534.30787330
66.60000000	0.26274337	1122.32167400	0.05151831	534.56617004
66.80000000	0.26402456	1122.53859100	0.05176952	534.66948845
67.00000000	0.26530575	1122.38083300	0.05202073	534.59434770
67.20000000	0.26658694	1122.14419600	0.05227195	534.48163658
67.40000000	0.26786813	1122.35125300	0.05252316	534.58025863
67.60000000	0.26914932	1122.67663000	0.05277438	534.73523696
67.80000000	0.27043051	1122.61747000	0.05302559	534.70705882
68.00000000	0.27171170	1122.81466800	0.05327680	534.80098500
68.20000000	0.27299289	1122.92312700	0.05352802	534.85264444
68.40000000	0.27427407	1122.93298600	0.05377923	534.85734032
68.60000000	0.27555526	1122.92312700	0.05403044	534.85264444
68.80000000	0.27683645	1122.82452800	0.05428166	534.80568135
69.00000000	0.27811764	1122.50901200	0.05453287	534.65539986
69.20000000	0.27939883	1122.57803100	0.05478408	534.68827387
69.40000000	0.28068002	1122.70620900	0.05503530	534.74932555
69.60000000	0.28196121	1122.64705000	0.05528651	534.72114789
69.80000000	0.28324240	1122.52873100	0.05553773	534.66479209
70.00000000	0.28452359	1122.13433600	0.05578894	534.47694022
70.20000000	0.28580478	1122.25265500	0.05604015	534.53329602
70.40000000	0.28708597	1122.51887100	0.05629137	534.66009574
70.60000000	0.28836716	1122.28223400	0.05654258	534.54738462
70.80000000	0.28964835	1122.27237400	0.05679379	534.54268826
71.00000000	0.29092954	1122.41041300	0.05704501	534.60843677
71.20000000	0.29221073	1122.37097300	0.05729622	534.58965135
71.40000000	0.29349192	1122.62733000	0.05754743	534.71175518
71.60000000	0.29477311	1122.44985200	0.05779865	534.62722172
71.80000000	0.29605429	1122.32167400	0.05804986	534.56617004
72.00000000	0.29733548	1122.47943200	0.05830108	534.64131079
72.20000000	0.29861667	1122.30195400	0.05855229	534.55677733
72.40000000	0.29989786	1122.25265500	0.05880350	534.53329602
72.60000000	0.30117905	1121.93713800	0.05905472	534.38301405
72.80000000	0.30246024	1121.86811900	0.05930593	534.35014003
73.00000000	0.30374143	1122.04559700	0.05955714	534.43467349
73.20000000	0.30502262	1121.81882000	0.05980836	534.32665873
73.40000000	0.30630381	1121.86811900	0.06005957	534.35014003
73.60000000	0.30758500	1121.83853900	0.06031078	534.33605096
73.80000000	0.30886619	1121.96671800	0.06056200	534.39710312
74.00000000	0.31014738	1122.12447600	0.06081321	534.47224387
74.20000000	0.31142857	1121.72022100	0.06106443	534.27969564
74.40000000	0.31270976	1121.72022100	0.06131564	534.27969564
74.60000000	0.31399095	1122.12447600	0.06156685	534.47224387
74.80000000	0.31527214	1122.24279500	0.06181807	534.52859967
75.00000000	0.31655333	1122.42027300	0.06206928	534.61313313
75.20000000	0.31783452	1122.24279500	0.06232049	534.52859967
75.40000000	0.31911570	1122.16391600	0.06257171	534.49102929
75.60000000	0.32039689	1121.95685800	0.06282292	534.39240676
75.80000000	0.32167808	1121.58218300	0.06307413	534.21394761
76.00000000	0.32295927	1121.64134200	0.06332535	534.24212527
76.20000000	0.32424046	1121.30610600	0.06357656	534.08245106
76.40000000	0.32552165	1121.22722700	0.06382777	534.04488069
76.60000000	0.32680284	1121.44414400	0.06407899	534.14819910
76.80000000	0.32808403	1121.21736700	0.06433020	534.04018433
77.00000000	0.32936522	1120.72437300	0.06458142	533.80536937
77.20000000	0.33064641	1120.24123800	0.06483263	533.57525030
77.40000000	0.33192760	1120.32997700	0.06508384	533.61751703
77.60000000	0.33320879	1120.78353200	0.06533506	533.83354704
77.80000000	0.33448998	1120.83283100	0.06558627	533.85702834
78.00000000	0.33577117	1120.55675500	0.06583748	533.72553227
78.20000000	0.33705236	1120.36941700	0.06608870	533.63630245
78.40000000	0.33833355	1120.29053800	0.06633991	533.59873208
78.60000000	0.33961474	1120.43843600	0.06659112	533.66917647
78.80000000	0.34089593	1120.58633400	0.06684234	533.73962086
79.00000000	0.34217711	1120.04404100	0.06709355	533.48132460
79.20000000	0.34345830	1119.85670300	0.06734477	533.39209478
79.40000000	0.34473949	1119.78768400	0.06759598	533.35922077
79.60000000	0.34602068	1119.27497000	0.06784719	533.11501310
79.80000000	0.34730187	1119.37356900	0.06809841	533.16197618
80.00000000	0.34858306	1119.36370900	0.06834962	533.15727983
80.20000000	0.34986425	1119.36370900	0.06860083	533.15727983
80.40000000	0.35114544	1119.40314800	0.06885205	533.17606478
80.60000000	0.35242663	1119.00875300	0.06910326	532.98821291
80.80000000	0.35370782	1119.05805200	0.06935447	533.01169421
81.00000000	0.35498901	1118.80169500	0.06960569	532.88959038
81.20000000	0.35627020	1118.14108300	0.06985690	532.57493832
81.40000000	0.35755139	1117.69738900	0.07010812	532.36360514
81.60000000	0.35883258	1117.24383400	0.07035933	532.14757514
81.80000000	0.36011377	1117.17481500	0.07061054	532.11470112
82.00000000	0.36139496	1117.21425400	0.07086176	532.13348607
82.20000000	0.36267615	1117.11565500	0.07111297	532.08652298
82.40000000	0.36395734	1117.02691700	0.07136418	532.04425673
82.60000000	0.36523852	1117.02691700	0.07161540	532.04425673
82.80000000	0.36651971	1116.64238100	0.07186661	531.86110074
83.00000000	0.36780090	1116.21840600	0.07211782	531.65915980
83.20000000	0.36908209	1116.30714500	0.07236904	531.70142653
83.40000000	0.37036328	1115.78457100	0.07262025	531.45252251
83.60000000	0.37164447	1115.24227800	0.07287147	531.19422624
83.80000000	0.37292566	1115.13381900	0.07312268	531.14256680
84.00000000	0.37420685	1114.90704200	0.07337389	531.03455204
84.20000000	0.37548804	1114.88732200	0.07362511	531.02515932
84.40000000	0.37676923	1114.56194600	0.07387632	530.87018147
84.60000000	0.37805042	1113.98021300	0.07412753	530.59309979
84.80000000	0.37933161	1114.02951200	0.07437875	530.61658109
85.00000000	0.38061280	1114.22671000	0.07462996	530.71050726
85.20000000	0.38189399	1114.21685000	0.07488117	530.70581091
85.40000000	0.38317518	1114.25628900	0.07513239	530.72459586
85.60000000	0.38445637	1114.17741000	0.07538360	530.68702548
85.80000000	0.38573756	1114.05909200	0.07563481	530.63067016
86.00000000	0.38701875	1114.01965200	0.07588603	530.61188473
86.20000000	0.38829993	1113.69427600	0.07613724	530.45690688
86.40000000	0.38958112	1113.17170200	0.07638846	530.20800286
86.60000000	0.39086231	1113.06324300	0.07663967	530.15634342
86.80000000	0.39214350	1113.02380400	0.07689088	530.13755847
87.00000000	0.39342469	1113.01394400	0.07714210	530.13286211
87.20000000	0.39470588	1113.03366400	0.07739331	530.14225482
87.40000000	0.39598707	1112.52095000	0.07764452	529.89804715
87.60000000	0.39726826	1111.88991700	0.07789574	529.59748369
87.80000000	0.39854945	1111.29832400	0.07814695	529.31570564
88.00000000	0.39983064	1111.27860500	0.07839816	529.30631341
88.20000000	0.40111183	1112.03781600	0.07864938	529.66792855
88.40000000	0.40239302	1111.67300000	0.07890059	529.49416528
88.60000000	0.40367421	1111.10112700	0.07915181	529.22177995
88.80000000	0.40495540	1111.41664300	0.07940302	529.37206144
89.00000000	0.40623659	1111.27860500	0.07965423	529.30631341
89.20000000	0.40751778	1111.07154700	0.07990545	529.20769088
89.40000000	0.40879897	1111.17014600	0.08015666	529.25465397
89.60000000	0.41008015	1110.84477000	0.08040787	529.09967611
89.80000000	0.41136134	1110.66729200	0.08065909	529.01514265
90.00000000	0.41264253	1110.88420900	0.08091030	529.11846106
90.20000000	0.41392372	1110.43065500	0.08116151	528.90243153
90.40000000	0.41520491	1110.19401700	0.08141273	528.78971993
90.60000000	0.41648610	1110.12499800	0.08166394	528.75684592
90.80000000	0.41776729	1109.42494700	0.08191516	528.42340891
91.00000000	0.41904848	1108.93195200	0.08216637	528.18859347
91.20000000	0.42032967	1108.74461500	0.08241758	528.09936413
91.40000000	0.42161086	1108.81363400	0.08266880	528.13223815
91.60000000	0.42289205	1108.45867800	0.08292001	527.96317123
91.80000000	0.42417324	1108.16288200	0.08317122	527.82228245
92.00000000	0.42545443	1107.99526300	0.08342244	527.74244487
92.20000000	0.42673562	1107.76848600	0.08367365	527.63443010
92.40000000	0.42801681	1107.53184900	0.08392486	527.52171898
92.60000000	0.42929800	1107.09801400	0.08417608	527.31508169
92.80000000	0.43057919	1107.16703300	0.08442729	527.34795570
93.00000000	0.43186038	1106.87123700	0.08467850	527.20706692
93.20000000	0.43314156	1106.13174600	0.08492972	526.85484449
93.40000000	0.43442275	1106.02328700	0.08518093	526.80318504
93.60000000	0.43570394	1105.61903200	0.08543215	526.61063682
93.80000000	0.43698513	1105.42183400	0.08568336	526.51671065
94.00000000	0.43826632	1105.61903200	0.08593457	526.61063682
94.20000000	0.43954751	1105.19505700	0.08618579	526.40869588
94.40000000	0.44082870	1104.44570600	0.08643700	526.05177709
94.60000000	0.44210989	1104.20906800	0.08668821	525.93906549
94.80000000	0.44339108	1104.03159000	0.08693943	525.85453203
95.00000000	0.44467227	1103.38083800	0.08719064	525.54457633
95.20000000	0.44595346	1102.70050600	0.08744185	525.22053156
95.40000000	0.44723465	1101.88213600	0.08769307	524.83073875
95.60000000	0.44851584	1101.47788100	0.08794428	524.63819052
95.80000000	0.44979703	1100.98488600	0.08819550	524.40337509
96.00000000	0.45107822	1100.47217300	0.08844671	524.15916790
96.20000000	0.45235941	1099.72282100	0.08869792	523.80224863
96.40000000	0.45364060	1098.93403100	0.08894914	523.42654489
96.60000000	0.45492179	1098.23397900	0.08920035	523.09310741
96.80000000	0.45620297	1096.71555700	0.08945156	522.36987711
97.00000000	0.45748416	1095.14783500	0.08970278	521.62316504
97.20000000	0.45876535	1093.72801200	0.08995399	520.94689783
97.40000000	0.46004654	1091.79547500	0.09020520	520.02642296
97.60000000	0.46132773	1089.42910300	0.09045642	518.89931079
97.80000000	0.46260892	1086.03730300	0.09070763	517.28378328
98.00000000	0.46389011	1080.54534800	0.09095885	514.66794380
98.20000000	0.46517130	1073.28847400	0.09121006	511.21146654
98.40000000	0.46645249	1063.77368600	0.09146127	506.67953608
98.60000000	0.46773368	1046.69636600	0.09171249	498.54554227