File: data/output/vidExt_M-35Zr39Ti25Nb_Glb_11/vidExt_M-35Zr39Ti25Nb_Glb_11_correlated.txt
Total length (mm) = 50
Gage length (mm) = 5.1
Width (mm) = 2.21
Thickness (mm) = 0.95
----------
Time (s)	Displacement (mm)	Force (N)	Eng. strain	Eng. stress (MPa)
0.00000000	0.00000000	0.00000000	0.00000000	0.00000000
0.20000000	0.04058481	61.83140200	0.00795781	29.45053679
0.40000000	0.04111084	65.30208500	0.00806095	31.10363658
0.60000000	0.04163687	69.42352100	0.00816409	33.06669255
0.80000000	0.04216290	72.96322300	0.00826724	34.75266635
1.00000000	0.04268894	76.62124400	0.00837038	36.49499595
1.20000000	0.04321497	80.78211900	0.00847352	38.47683687
1.40000000	0.04374100	85.23879200	0.00857667	40.59956752
1.60000000	0.04426703	89.40952700	0.00867981	42.58610479
1.80000000	0.04479306	93.19572700	0.00878295	44.38948654
2.00000000	0.04531909	97.32702300	0.00888610	46.35723887
2.20000000	0.04584512	101.48789800	0.00898924	48.33907978
2.40000000	0.04637116	105.40227600	0.00909238	50.20351322
2.60000000	0.04689719	109.48427200	0.00919553	52.14778376
2.80000000	0.04742322	114.07898300	0.00929867	54.33626244
3.00000000	0.04794925	118.12154000	0.00940181	56.26174804
3.20000000	0.04847528	121.95703900	0.00950496	58.08861110
3.40000000	0.04900131	126.51231000	0.00960810	60.25830436
3.60000000	0.04952734	131.01828200	0.00971124	62.40451631
3.80000000	0.05005338	135.43551400	0.00981439	64.50846106
4.00000000	0.05057941	139.52737000	0.00991753	66.45742796
4.20000000	0.05110544	143.60936700	0.01002067	68.40169898
4.40000000	0.05163147	147.82940100	0.01012382	70.41171755
4.60000000	0.05215750	152.35509300	0.01022696	72.56732222
4.80000000	0.05268353	156.75260500	0.01033010	74.66187426
5.00000000	0.05320956	160.99236000	0.01043325	76.68128602
5.20000000	0.05373560	165.33071300	0.01053639	78.74766040
5.40000000	0.05426163	169.08733300	0.01063953	80.53695308
5.60000000	0.05478766	173.54400500	0.01074268	82.65968326
5.80000000	0.05531369	178.14857500	0.01084582	84.85285782
6.00000000	0.05583972	182.18127200	0.01094896	86.77364706
6.20000000	0.05636575	186.68724300	0.01105211	88.91985854
6.40000000	0.05689178	191.75522900	0.01115525	91.33375994
6.60000000	0.05741782	196.15274100	0.01125840	93.42831198
6.80000000	0.05794385	200.08683900	0.01136154	95.30213813
7.00000000	0.05846988	204.12939500	0.01146468	97.22762324
7.20000000	0.05899591	208.67480600	0.01156783	99.39262015
7.40000000	0.05952194	213.38783500	0.01167097	101.63745416
7.60000000	0.06004797	217.62758900	0.01177411	103.65686544
7.80000000	0.06057400	222.13356100	0.01187726	105.80307740
8.00000000	0.06110004	226.50149300	0.01198040	107.88354037
8.20000000	0.06162607	230.83984700	0.01208354	109.94991522
8.40000000	0.06215210	235.51343600	0.01218669	112.17596380
8.60000000	0.06267813	239.73347000	0.01228983	114.18598238
8.80000000	0.06320416	244.07182300	0.01239297	116.25235675
9.00000000	0.06373019	248.58765400	0.01249612	118.40326459
9.20000000	0.06425622	252.78796900	0.01259926	120.40389093
9.40000000	0.06478226	257.40239900	0.01270240	122.60176185
9.60000000	0.06530829	261.88865000	0.01280555	124.73858061
9.80000000	0.06583432	265.73400900	0.01290869	126.57014003
10.00000000	0.06636035	270.05264200	0.01301183	128.62712170
10.20000000	0.06688638	274.47973400	0.01311498	130.73576280
10.40000000	0.06741241	278.66032800	0.01321812	132.72699595
10.60000000	0.06793844	283.29447800	0.01332126	134.93425959
10.80000000	0.06846448	287.55395200	0.01342441	136.96306359
11.00000000	0.06899051	291.61622700	0.01352755	138.89794094
11.20000000	0.06951654	295.97430000	0.01363069	140.97370803
11.40000000	0.07004257	300.41125200	0.01373384	143.08704549
11.60000000	0.07056860	304.57212700	0.01383698	145.06888640
11.80000000	0.07109463	309.09781700	0.01394012	147.22449012
12.00000000	0.07162066	313.76154600	0.01404327	149.44584234
12.20000000	0.07214670	318.09989900	0.01414641	151.51221672
12.40000000	0.07267273	322.71432900	0.01424955	153.71008764
12.60000000	0.07319876	327.22030000	0.01435270	155.85629912
12.80000000	0.07372479	331.49949300	0.01445584	157.89449536
13.00000000	0.07425082	335.58148900	0.01455898	159.83876590
13.20000000	0.07477685	339.79166300	0.01466213	161.84408812
13.40000000	0.07530288	344.08071600	0.01476527	163.88698071
13.60000000	0.07582892	348.35004900	0.01486841	165.92048059
13.80000000	0.07635495	353.01377800	0.01497156	168.14183282
14.00000000	0.07688098	357.17465300	0.01507470	170.12367373
14.20000000	0.07740701	361.01015100	0.01517784	171.95053632
14.40000000	0.07793304	365.67388000	0.01528099	174.17188854
14.60000000	0.07845907	369.83475400	0.01538413	176.15372898
14.80000000	0.07898510	373.54207400	0.01548728	177.91953989
15.00000000	0.07951114	378.38328100	0.01559042	180.22542558
15.20000000	0.08003717	383.45126500	0.01569356	182.63932603
15.40000000	0.08056320	387.57270000	0.01579671	184.60238152
15.60000000	0.08108923	391.64483500	0.01589985	186.54195523
15.80000000	0.08161526	396.46632200	0.01600299	188.83844820
16.00000000	0.08214129	400.85397400	0.01610614	190.92830388
16.20000000	0.08266732	404.83737000	0.01620928	192.82561086
16.40000000	0.08319336	409.45180000	0.01631242	195.02348178
16.60000000	0.08371939	413.83945100	0.01641557	197.11333698
16.80000000	0.08424542	417.67494900	0.01651871	198.94019957
17.00000000	0.08477145	421.87526300	0.01662185	200.94082543
17.20000000	0.08529748	426.43053300	0.01672500	203.11051822
17.40000000	0.08582351	430.31533000	0.01682814	204.96086211
17.60000000	0.08634954	434.46634400	0.01693128	206.93800619
17.80000000	0.08687558	439.20895200	0.01703443	209.19692879
18.00000000	0.08740161	443.36982600	0.01713757	211.17876923
18.20000000	0.08792764	447.58986000	0.01724071	213.18878781
18.40000000	0.08845367	451.39577800	0.01734386	215.00156132
18.60000000	0.08897970	455.31015500	0.01744700	216.86599428
18.80000000	0.08950573	460.17108100	0.01755014	219.18127221
19.00000000	0.09003176	464.43055400	0.01765329	221.21007573
19.20000000	0.09055780	468.18717300	0.01775643	222.99936794
19.40000000	0.09108383	472.35790600	0.01785957	224.98590426
19.60000000	0.09160986	476.75541800	0.01796272	227.08045630
19.80000000	0.09213589	481.01489100	0.01806586	229.10925982
20.00000000	0.09266192	485.09688600	0.01816900	231.05352989
20.20000000	0.09318795	489.44509700	0.01827215	233.12459967
20.40000000	0.09371398	493.55667200	0.01837529	235.08295880
20.60000000	0.09424001	497.54006800	0.01847843	236.98026578
20.80000000	0.09476605	501.85870000	0.01858158	239.03724696
21.00000000	0.09529208	505.91111500	0.01868472	240.96742796
21.20000000	0.09581811	510.11142800	0.01878786	242.96805335
21.40000000	0.09634414	514.14412400	0.01889101	244.88884211
21.60000000	0.09687017	518.21625800	0.01899415	246.82841534
21.80000000	0.09739620	522.62363000	0.01909729	248.92766373
22.00000000	0.09792223	526.50842600	0.01920044	250.77800714
22.20000000	0.09844827	530.47210200	0.01930358	252.66592141
22.40000000	0.09897430	534.77101500	0.01940673	254.71351036
22.60000000	0.09950033	538.94174800	0.01950987	256.70004668
22.80000000	0.10002636	542.72794600	0.01961301	258.50342748
23.00000000	0.10055239	546.57330300	0.01971616	260.33498595
23.20000000	0.10107842	551.08913300	0.01981930	262.48589331
23.40000000	0.10160445	555.21056700	0.01992244	264.44894832
23.60000000	0.10213049	558.76012700	0.02002559	266.13961753
23.80000000	0.10265652	562.66464400	0.02012873	267.99935413
24.00000000	0.10318255	566.82551800	0.02023187	269.98119457
24.20000000	0.10370858	570.73989400	0.02033502	271.84562705
24.40000000	0.10423461	574.79230900	0.02043816	273.77580805
24.60000000	0.10476064	579.08136100	0.02054130	275.81870017
24.80000000	0.10528667	583.62677000	0.02064445	277.98369612
25.00000000	0.10581271	587.40310800	0.02074759	279.78238057
25.20000000	0.10633874	591.18930500	0.02085073	281.58576090
25.40000000	0.10686477	595.62625600	0.02095388	283.69909788
25.60000000	0.10739080	599.77726900	0.02105702	285.67624149
25.80000000	0.10791683	603.62262600	0.02116016	287.50779995
26.00000000	0.10844286	607.74406000	0.02126331	289.47085497
26.20000000	0.10896889	612.02325200	0.02136645	291.50905073
26.40000000	0.10949493	615.61225200	0.02146959	293.21850536
26.60000000	0.11002096	619.51676800	0.02157274	295.07824149
26.80000000	0.11054699	623.70722100	0.02167588	297.07417052
27.00000000	0.11107302	627.77935600	0.02177902	299.01374422
27.20000000	0.11159905	631.66415200	0.02188217	300.86408764
27.40000000	0.11212508	635.62782700	0.02198531	302.75200143
27.60000000	0.11265111	639.95631900	0.02208845	304.81367897
27.80000000	0.11317715	643.86083500	0.02219160	306.67341510
28.00000000	0.11370318	647.75549100	0.02229474	308.52845487
28.20000000	0.11422921	651.76846600	0.02239788	310.43985044
28.40000000	0.11475524	655.49550400	0.02250103	312.21505311
28.60000000	0.11528127	659.80427500	0.02260417	314.26733746
28.80000000	0.11580730	663.65949200	0.02270731	316.10359228
29.00000000	0.11633333	667.50484900	0.02281046	317.93515075
29.20000000	0.11685937	671.70516100	0.02291360	319.93577566
29.40000000	0.11738540	675.69841600	0.02301674	321.83777852
29.60000000	0.11791143	679.46489400	0.02311989	323.63176661
29.80000000	0.11843746	683.23137100	0.02322303	325.42575423
30.00000000	0.11896349	687.22462600	0.02332617	327.32775709
30.20000000	0.11948952	691.07984300	0.02342932	329.16401191
30.40000000	0.12001555	694.95477900	0.02353246	331.00965897
30.60000000	0.12054159	698.34658100	0.02363561	332.62518743
30.80000000	0.12106762	702.15249800	0.02373875	334.43796047
31.00000000	0.12159365	706.28379100	0.02384189	336.40571136
31.20000000	0.12211968	710.03054800	0.02394504	338.19030626
31.40000000	0.12264571	713.82660500	0.02404818	339.99838295
31.60000000	0.12317174	717.90859900	0.02415132	341.94265254
31.80000000	0.12369777	721.37928000	0.02425447	343.59575137
32.00000000	0.12422381	724.87954000	0.02435761	345.26293879
32.20000000	0.12474984	729.03055300	0.02446075	347.24008240
32.40000000	0.12527587	732.96464900	0.02456390	349.11390760
32.60000000	0.12580190	736.59308700	0.02466704	350.84214670
32.80000000	0.12632793	740.27082600	0.02477018	352.59386806
33.00000000	0.12685396	744.37253900	0.02487333	354.54752989
33.20000000	0.12737999	748.27705500	0.02497647	356.40726602
33.40000000	0.12790603	751.60969700	0.02507961	357.99461634
33.60000000	0.12843206	755.33673400	0.02518276	359.76981853
33.80000000	0.12895809	759.43844800	0.02528590	361.72348083
34.00000000	0.12948412	762.98800700	0.02538904	363.41414956
34.20000000	0.13001015	766.67560500	0.02549219	365.17056680
34.40000000	0.13053618	770.76745900	0.02559533	367.11953275
34.60000000	0.13106221	774.62267500	0.02569847	368.95578709
34.80000000	0.13158825	778.14265500	0.02580162	370.63236723
35.00000000	0.13211428	781.47529700	0.02590476	372.21971755
35.20000000	0.13264031	784.83751800	0.02600790	373.82115647
35.40000000	0.13316634	788.91951200	0.02611105	375.76542605
35.60000000	0.13369237	792.64654900	0.02621419	377.54062824
35.80000000	0.13421840	795.77213400	0.02631733	379.02935651
36.00000000	0.13474443	799.32169300	0.02642048	380.72002524
36.20000000	0.13527047	803.47270500	0.02652362	382.69716837
36.40000000	0.13579650	807.49553900	0.02662676	384.61325982
36.60000000	0.13632253	810.67042300	0.02672991	386.12546940
36.80000000	0.13684856	814.18054300	0.02683305	387.79735318
37.00000000	0.13737459	817.86814100	0.02693619	389.55377042
37.20000000	0.13790062	821.25008200	0.02703934	391.16460205
37.40000000	0.13842665	825.14473700	0.02714248	393.01964134
37.60000000	0.13895269	828.96051400	0.02724562	394.83711074
37.80000000	0.13947872	832.15511700	0.02734877	396.35871255
38.00000000	0.14000475	835.66523700	0.02745191	398.03059633
38.20000000	0.14053078	839.71765000	0.02755505	399.96077638
38.40000000	0.14105681	843.36580800	0.02765820	401.69840819
38.60000000	0.14158284	846.98438700	0.02776134	403.42195142
38.80000000	0.14210887	850.72128400	0.02786449	405.20184996
39.00000000	0.14263491	854.37930200	0.02796763	406.94417814
39.20000000	0.14316094	857.93872100	0.02807077	408.63954322
39.40000000	0.14368697	861.20234300	0.02817392	410.19401905
39.60000000	0.14421300	864.58428400	0.02827706	411.80485068
39.80000000	0.14473903	868.20286300	0.02838020	413.52839390
40.00000000	0.14526506	871.78200200	0.02848335	415.23315170
40.20000000	0.14579109	875.32170100	0.02858649	416.91912408
40.40000000	0.14631713	878.71350200	0.02868963	418.53465206
40.60000000	0.14684316	881.93768500	0.02879278	420.07034294
40.80000000	0.14736919	885.45766400	0.02889592	421.74692260
41.00000000	0.14789522	888.94806400	0.02899906	423.40941367
41.20000000	0.14842125	892.40888400	0.02910221	425.05781567
41.40000000	0.14894728	895.67250600	0.02920535	426.61229150
41.60000000	0.14947331	898.63047200	0.02930849	428.02118219
41.80000000	0.14999935	901.94339400	0.02941164	429.59913980
42.00000000	0.15052538	905.15771600	0.02951478	431.13013384
42.20000000	0.15105141	908.26358000	0.02961792	432.60946892
42.40000000	0.15157744	911.59622200	0.02972107	434.19681924
42.60000000	0.15210347	914.94858300	0.02982421	435.79356180
42.80000000	0.15262950	918.62632100	0.02992735	437.54528269
43.00000000	0.15315553	922.04770100	0.03003050	439.17489926
43.20000000	0.15368157	925.40006200	0.03013364	440.77164182
43.40000000	0.15420760	928.96934100	0.03023678	442.47170326
43.60000000	0.15473363	932.10478400	0.03033993	443.96512693
43.80000000	0.15525966	935.32896700	0.03044307	445.50081781
44.00000000	0.15578569	938.59258900	0.03054621	447.05529364
44.20000000	0.15631172	941.64915400	0.03064936	448.51114742
44.40000000	0.15683775	945.23815200	0.03075250	450.22060110
44.60000000	0.15736379	949.11308700	0.03085564	452.06624768
44.80000000	0.15788982	952.62320600	0.03095879	453.73813098
45.00000000	0.15841585	956.15304500	0.03106193	455.41940700
45.20000000	0.15894188	959.38708700	0.03116507	456.95979376
45.40000000	0.15946791	962.44365200	0.03126822	458.41564754
45.60000000	0.15999394	965.64811500	0.03137136	459.94194570
45.80000000	0.16051997	969.59206900	0.03147450	461.82046630
46.00000000	0.16104601	972.93457000	0.03157765	463.41251250
46.20000000	0.16157204	975.71505700	0.03168079	464.73686925
46.40000000	0.16209807	979.27447600	0.03178394	466.43223434
46.60000000	0.16262410	982.42963900	0.03188708	467.93505073
46.80000000	0.16315013	985.57494200	0.03199022	469.43317075
47.00000000	0.16367616	989.35127800	0.03209337	471.23185425
47.20000000	0.16420219	992.76279800	0.03219651	472.85677447
47.40000000	0.16472823	996.17431900	0.03229965	474.48169517
47.60000000	0.16525426	999.84219600	0.03240280	476.22871922
47.80000000	0.16578029	1002.91848000	0.03250594	477.69396523
48.00000000	0.16630632	1006.20182100	0.03260908	479.25783329
48.20000000	0.16683235	1009.42600400	0.03271223	480.79352417
48.40000000	0.16735838	1012.40368900	0.03281537	482.21180710
48.60000000	0.16788441	1015.73633000	0.03291851	483.79915694
48.80000000	0.16841045	1019.16757000	0.03302166	485.43346987
49.00000000	0.16893648	1022.25371300	0.03312480	486.90341176
49.20000000	0.16946251	1024.82714300	0.03322794	488.12914646
49.40000000	0.16998854	1027.57805100	0.03333109	489.43941462
49.60000000	0.17051457	1031.21634800	0.03343423	491.17234961
49.80000000	0.17104060	1034.73632700	0.03353737	492.84892927
50.00000000	0.17156663	1037.21115800	0.03364052	494.02770088
50.20000000	0.17209267	1040.13954400	0.03374366	495.42250250
50.40000000	0.17261870	1043.60036300	0.03384680	497.07090402
50.60000000	0.17314473	1046.85412500	0.03394995	498.62068350
50.80000000	0.17367076	1049.82195000	0.03405309	500.03427006
51.00000000	0.17419679	1052.74047500	0.03415623	501.42437485
51.20000000	0.17472282	1055.63928100	0.03425938	502.80508740
51.40000000	0.17524885	1058.60710600	0.03436252	504.21867397
51.60000000	0.17577489	1061.24955500	0.03446566	505.47728269
51.80000000	0.17630092	1063.46802900	0.03456881	506.53395046
52.00000000	0.17682695	1065.88370100	0.03467195	507.68454442
52.20000000	0.17735298	1068.49657000	0.03477509	508.92906406
52.40000000	0.17787901	1071.17845800	0.03487824	510.20645773
52.60000000	0.17840504	1073.82090700	0.03498138	511.46506644
52.80000000	0.17893107	1076.38447700	0.03508452	512.68610479
53.00000000	0.17945711	1078.62267100	0.03518767	513.75216528
53.20000000	0.17885512	1080.98904300	0.03506963	514.87927745
53.40000000	0.18014044	1083.39485400	0.03532166	516.02517457
53.60000000	0.18142576	1085.55416900	0.03557368	517.05366468
53.80000000	0.18271109	1087.43740700	0.03582570	517.95065825
54.00000000	0.18399641	1089.57700100	0.03607773	518.96975518
54.20000000	0.18528174	1091.63771700	0.03632975	519.95128221
54.40000000	0.18656706	1093.59983400	0.03658178	520.88584615
54.60000000	0.18785238	1095.24643400	0.03683380	521.67012813
54.80000000	0.18913771	1096.90289500	0.03708583	522.45910693
55.00000000	0.19042303	1098.68753400	0.03733785	523.30913741
55.20000000	0.19170836	1100.19609600	0.03758987	524.02767135
55.40000000	0.19299368	1101.57647900	0.03784190	524.68515313
55.60000000	0.19427901	1102.78924500	0.03809392	525.26279829
55.80000000	0.19556433	1103.97243100	0.03834595	525.82635437
56.00000000	0.19684965	1105.11617800	0.03859797	526.37112551
56.20000000	0.19813498	1106.37824300	0.03885000	526.97225196
56.40000000	0.19942030	1107.07829400	0.03910202	527.30568897
56.60000000	0.20070563	1107.88680500	0.03935404	527.69078590
56.80000000	0.20199095	1109.46438600	0.03960607	528.44219386
57.00000000	0.20327627	1110.61799200	0.03985809	528.99166087
57.20000000	0.20456160	1111.30818400	0.04011012	529.32040200
57.40000000	0.20584692	1112.05753500	0.04036214	529.67732079
57.60000000	0.20713225	1112.68856800	0.04061417	529.97788426
57.80000000	0.20841757	1113.11254300	0.04086619	530.17982520
58.00000000	0.20970289	1113.64497700	0.04111821	530.43342558
58.20000000	0.21098822	1113.93091300	0.04137024	530.56961800
58.40000000	0.21227354	1114.00979200	0.04162226	530.60718838
58.60000000	0.21355887	1115.00564000	0.04187429	531.08151465
58.80000000	0.21484419	1115.43947500	0.04212631	531.28815194
59.00000000	0.21612951	1115.40989600	0.04237834	531.27406335
59.20000000	0.21741484	1116.14938700	0.04263036	531.62628578
59.40000000	0.21870016	1116.62266100	0.04288238	531.85170803
59.60000000	0.21998549	1116.72126000	0.04313441	531.89867111
59.80000000	0.22127081	1116.72126000	0.04338643	531.89867111
60.00000000	0.22255614	1116.92831800	0.04363846	531.99729364
60.20000000	0.22384146	1117.09593600	0.04389048	532.07713075
60.40000000	0.22512678	1117.03677600	0.04414251	532.04895261
60.60000000	0.22641211	1117.74668800	0.04439453	532.38708645
60.80000000	0.22769743	1118.62421800	0.04464656	532.80505739
61.00000000	0.22898276	1118.76225600	0.04489858	532.87080543
61.20000000	0.23026808	1119.02847300	0.04515060	532.99760562
61.40000000	0.23155340	1119.40314800	0.04540263	533.17606478
61.60000000	0.23283873	1119.38342900	0.04565465	533.16667254
61.80000000	0.23412405	1119.50174700	0.04590668	533.22302786
62.00000000	0.23540938	1119.95530200	0.04615870	533.43905787
62.20000000	0.23669470	1119.79754400	0.04641073	533.36391712
62.40000000	0.23798002	1119.79754400	0.04666275	533.36391712
62.60000000	0.23926535	1119.97502200	0.04691477	533.44845058
62.80000000	0.24055067	1119.87642300	0.04716680	533.40148750
63.00000000	0.24183600	1120.23137900	0.04741882	533.57055442
63.20000000	0.24312132	1120.28067800	0.04767085	533.59403572
63.40000000	0.24440664	1120.45815600	0.04792287	533.67856918
63.60000000	0.24569197	1120.72437300	0.04817490	533.80536937
63.80000000	0.24697729	1120.91171000	0.04842692	533.89459871
64.00000000	0.24826262	1121.33568500	0.04867894	534.09653965
64.20000000	0.24954794	1121.49344400	0.04893097	534.17168088
64.40000000	0.25083326	1121.51316300	0.04918299	534.18107311
64.60000000	0.25211859	1121.43428400	0.04943502	534.14350274
64.80000000	0.25340391	1121.49344400	0.04968704	534.17168088
65.00000000	0.25468924	1121.87797900	0.04993907	534.35483639
65.20000000	0.25597456	1122.04559700	0.05019109	534.43467349
65.40000000	0.25725989	1121.86811900	0.05044311	534.35014003
65.60000000	0.25854521	1121.45400400	0.05069514	534.15289545
65.80000000	0.25983053	1121.54274300	0.05094716	534.19516218
66.00000000	0.26111586	1122.01601700	0.05119919	534.42058442
66.20000000	0.26240118	1121.79910000	0.05145121	534.31726602
66.40000000	0.26368651	1121.77938000	0.05170324	534.30787330
66.60000000	0.26497183	1122.32167400	0.05195526	534.56617004
66.80000000	0.26625715	1122.53859100	0.05220729	534.66948845
67.00000000	0.26754248	1122.38083300	0.05245931	534.59434770
67.20000000	0.26882780	1122.14419600	0.05271133	534.48163658
67.40000000	0.27011313	1122.35125300	0.05296336	534.58025863
67.60000000	0.27139845	1122.67663000	0.05321538	534.73523696
67.80000000	0.27268377	1122.61747000	0.05346741	534.70705882
68.00000000	0.27396910	1122.81466800	0.05371943	534.80098500
68.20000000	0.27525442	1122.92312700	0.05397146	534.85264444
68.40000000	0.27653975	1122.93298600	0.05422348	534.85734032
68.60000000	0.27782507	1122.92312700	0.05447550	534.85264444
68.80000000	0.27911039	1122.82452800	0.05472753	534.80568135
69.00000000	0.28039572	1122.50901200	0.05497955	534.65539986
69.20000000	0.28168104	1122.57803100	0.05523158	534.68827387
69.40000000	0.28296637	1122.70620900	0.05548360	534.74932555
69.60000000	0.28425169	1122.64705000	0.05573563	534.72114789
69.80000000	0.28553701	1122.52873100	0.05598765	534.66479209
70.00000000	0.28682234	1122.13433600	0.05623967	534.47694022
70.20000000	0.28810766	1122.25265500	0.05649170	534.53329602
70.40000000	0.28939299	1122.51887100	0.05674372	534.66009574
70.60000000	0.29067831	1122.28223400	0.05699575	534.54738462
70.80000000	0.29196364	1122.27237400	0.05724777	534.54268826
71.00000000	0.29324896	1122.41041300	0.05749980	534.60843677
71.20000000	0.29453428	1122.37097300	0.05775182	534.58965135
71.40000000	0.29581961	1122.62733000	0.05800384	534.71175518
71.60000000	0.29710493	1122.44985200	0.05825587	534.62722172
71.80000000	0.29839026	1122.32167400	0.05850789	534.56617004
72.00000000	0.29967558	1122.47943200	0.05875992	534.64131079
72.20000000	0.30096090	1122.30195400	0.05901194	534.55677733
72.40000000	0.30224623	1122.25265500	0.05926397	534.53329602
72.60000000	0.30353155	1121.93713800	0.05951599	534.38301405
72.80000000	0.30481688	1121.86811900	0.05976801	534.35014003
73.00000000	0.30610220	1122.04559700	0.06002004	534.43467349
73.20000000	0.30738752	1121.81882000	0.06027206	534.32665873
73.40000000	0.30867285	1121.86811900	0.06052409	534.35014003
73.60000000	0.30995817	1121.83853900	0.06077611	534.33605096
73.80000000	0.31124350	1121.96671800	0.06102814	534.39710312
74.00000000	0.31252882	1122.12447600	0.06128016	534.47224387
74.20000000	0.31381414	1121.72022100	0.06153219	534.27969564
74.40000000	0.31509947	1121.72022100	0.06178421	534.27969564
74.60000000	0.31638479	1122.12447600	0.06203623	534.47224387
74.80000000	0.31767012	1122.24279500	0.06228826	534.52859967
75.00000000	0.31895544	1122.42027300	0.06254028	534.61313313
75.20000000	0.32024076	1122.24279500	0.06279231	534.52859967
75.40000000	0.32152609	1122.16391600	0.06304433	534.49102929
75.60000000	0.32281141	1121.95685800	0.06329636	534.39240676
75.80000000	0.32409674	1121.58218300	0.06354838	534.21394761
76.00000000	0.32538206	1121.64134200	0.06380040	534.24212527
76.20000000	0.32666739	1121.30610600	0.06405243	534.08245106
76.40000000	0.32795271	1121.22722700	0.06430445	534.04488069
76.60000000	0.32923803	1121.44414400	0.06455648	534.14819910
76.80000000	0.33052336	1121.21736700	0.06480850	534.04018433
77.00000000	0.33180868	1120.72437300	0.06506053	533.80536937
77.20000000	0.33309401	1120.24123800	0.06531255	533.57525030
77.40000000	0.33437933	1120.32997700	0.06556457	533.61751703
77.60000000	0.33566465	1120.78353200	0.06581660	533.83354704
77.80000000	0.33694998	1120.83283100	0.06606862	533.85702834
78.00000000	0.33823530	1120.55675500	0.06632065	533.72553227
78.20000000	0.33952063	1120.36941700	0.06657267	533.63630245
78.40000000	0.34080595	1120.29053800	0.06682470	533.59873208
78.60000000	0.34209127	1120.43843600	0.06707672	533.66917647
78.80000000	0.34337660	1120.58633400	0.06732874	533.73962086
79.00000000	0.34466192	1120.04404100	0.06758077	533.48132460
79.20000000	0.34594725	1119.85670300	0.06783279	533.39209478
79.40000000	0.34723257	1119.78768400	0.06808482	533.35922077
79.60000000	0.34851789	1119.27497000	0.06833684	533.11501310
79.80000000	0.34980322	1119.37356900	0.06858887	533.16197618
80.00000000	0.35108854	1119.36370900	0.06884089	533.15727983
80.20000000	0.35237387	1119.36370900	0.06909292	533.15727983
80.40000000	0.35365919	1119.40314800	0.06934494	533.17606478
80.60000000	0.35494451	1119.00875300	0.06959696	532.98821291
80.80000000	0.35622984	1119.05805200	0.06984899	533.01169421
81.00000000	0.35751516	1118.80169500	0.07010101	532.88959038
81.20000000	0.35880049	1118.14108300	0.07035304	532.57493832
81.40000000	0.36008581	1117.69738900	0.07060506	532.36360514
81.60000000	0.36137114	1117.24383400	0.07085709	532.14757514
81.80000000	0.36265646	1117.17481500	0.07110911	532.11470112
82.00000000	0.36394178	1117.21425400	0.07136113	532.13348607
82.20000000	0.36522711	1117.11565500	0.07161316	532.08652298
82.40000000	0.36651243	1117.02691700	0.07186518	532.04425673
82.60000000	0.36779776	1117.02691700	0.07211721	532.04425673
82.80000000	0.36908308	1116.64238100	0.07236923	531.86110074
83.00000000	0.37036840	1116.21840600	0.07262126	531.65915980
83.20000000	0.37165373	1116.30714500	0.07287328	531.70142653
83.40000000	0.37293905	1115.78457100	0.07312530	531.45252251
83.60000000	0.37422438	1115.24227800	0.07337733	531.19422624
83.80000000	0.37550970	1115.13381900	0.07362935	531.14256680
84.00000000	0.37679502	1114.90704200	0.07388138	531.03455204
84.20000000	0.37808035	1114.88732200	0.07413340	531.02515932
84.40000000	0.37936567	1114.56194600	0.07438543	530.87018147
84.60000000	0.38065100	1113.98021300	0.07463745	530.59309979
84.80000000	0.38193632	1114.02951200	0.07488947	530.61658109
85.00000000	0.38322164	1114.22671000	0.07514150	530.71050726
85.20000000	0.38450697	1114.21685000	0.07539352	530.70581091
85.40000000	0.38579229	1114.25628900	0.07564555	530.72459586
85.60000000	0.38707762	1114.17741000	0.07589757	530.68702548
85.80000000	0.38836294	1114.05909200	0.07614960	530.63067016
86.00000000	0.38964826	1114.01965200	0.07640162	530.61188473
86.20000000	0.39093359	1113.69427600	0.07665364	530.45690688
86.40000000	0.39221891	1113.17170200	0.07690567	530.20800286
86.60000000	0.39350424	1113.06324300	0.07715769	530.15634342
86.80000000	0.39478956	1113.02380400	0.07740972	530.13755847
87.00000000	0.39607489	1113.01394400	0.07766174	530.13286211
87.20000000	0.39736021	1113.03366400	0.07791377	530.14225482
87.40000000	0.39864553	1112.52095000	0.07816579	529.89804715
87.60000000	0.39993086	1111.88991700	0.07841782	529.59748369
87.80000000	0.40121618	1111.29832400	0.07866984	529.31570564
88.00000000	0.40250151	1111.27860500	0.07892186	529.30631341
88.20000000	0.40378683	1112.03781600	0.07917389	529.66792855
88.40000000	0.40507215	1111.67300000	0.07942591	529.49416528
88.60000000	0.40635748	1111.10112700	0.07967794	529.22177995
88.80000000	0.40764280	1111.41664300	0.07992996	529.37206144
89.00000000	0.40892813	1111.27860500	0.08018199	529.30631341
89.20000000	0.41021345	1111.07154700	0.08043401	529.20769088
89.40000000	0.41149877	1111.17014600	0.08068603	529.25465397
89.60000000	0.41278410	1110.84477000	0.08093806	529.09967611
89.80000000	0.41406942	1110.66729200	0.08119008	529.01514265
90.00000000	0.41535475	1110.88420900	0.08144211	529.11846106
90.20000000	0.41664007	1110.43065500	0.08169413	528.90243153
90.40000000	0.41792539	1110.19401700	0.08194616	528.78971993
90.60000000	0.41921072	1110.12499800	0.08219818	528.75684592
90.80000000	0.42049604	1109.42494700	0.08245020	528.42340891
91.00000000	0.42178137	1108.93195200	0.08270223	528.18859347
91.20000000	0.42306669	1108.74461500	0.08295425	528.09936413
91.40000000	0.42435201	1108.81363400	0.08320628	528.13223815
91.60000000	0.42563734	1108.45867800	0.08345830	527.96317123
91.80000000	0.42692266	1108.16288200	0.08371033	527.82228245
92.00000000	0.42820799	1107.99526300	0.08396235	527.74244487
92.20000000	0.42949331	1107.76848600	0.08421437	527.63443010
92.40000000	0.43077864	1107.53184900	0.08446640	527.52171898
92.60000000	0.43206396	1107.09801400	0.08471842	527.31508169
92.80000000	0.43334928	1107.16703300	0.08497045	527.34795570
93.00000000	0.43463461	1106.87123700	0.08522247	527.20706692
93.20000000	0.43591993	1106.13174600	0.08547450	526.85484449
93.40000000	0.43720526	1106.02328700	0.08572652	526.80318504
93.60000000	0.43849058	1105.61903200	0.08597855	526.61063682
93.80000000	0.43977590	1105.42183400	0.08623057	526.51671065
94.00000000	0.44106123	1105.61903200	0.08648259	526.61063682
94.20000000	0.44234655	1105.19505700	0.08673462	526.40869588
94.40000000	0.44363188	1104.44570600	0.08698664	526.05177709
94.60000000	0.44491720	1104.20906800	0.08723867	525.93906549
94.80000000	0.44620252	1104.03159000	0.08749069	525.85453203
95.00000000	0.44748785	1103.38083800	0.08774272	525.54457633
95.20000000	0.44877317	1102.70050600	0.08799474	525.22053156
95.40000000	0.45005850	1101.88213600	0.08824676	524.83073875
95.60000000	0.45134382	1101.47788100	0.08849879	524.63819052
95.80000000	0.45262914	1100.98488600	0.08875081	524.40337509
96.00000000	0.45391447	1100.47217300	0.08900284	524.15916790
96.20000000	0.45519979	1099.72282100	0.08925486	523.80224863
96.40000000	0.45648512	1098.93403100	0.08950689	523.42654489
96.60000000	0.45777044	1098.23397900	0.08975891	523.09310741
96.80000000	0.45905576	1096.71555700	0.09001093	522.36987711
97.00000000	0.46034109	1095.14783500	0.09026296	521.62316504
97.20000000	0.46162641	1093.72801200	0.09051498	520.94689783
97.40000000	0.46291174	1091.79547500	0.09076701	520.02642296
97.60000000	0.46419706	1089.42910300	0.09101903	518.89931079
97.80000000	0.46548239	1086.03730300	0.09127106	517.28378328
98.00000000	0.46676771	1080.54534800	0.09152308	514.66794380
98.20000000	0.46805303	1073.28847400	0.09177510	511.21146654
98.40000000	0.46933836	1063.77368600	0.09202713	506.67953608
98.60000000	0.47062368	1046.69636600	0.09227915	498.54554227